(0.007) SELECT @@SQL_AUTO_IS_NULL; args=None
(0.001) SET SESSION TRANSACTION ISOLATION LEVEL READ COMMITTED; args=None
(0.002) SELECT VERSION(); args=None
(0.000) SET SESSION TRANSACTION ISOLATION LEVEL READ COMMITTED; args=None
(0.078) SHOW FULL TABLES; args=None
(0.029) SELECT `django_migrations`.`app`, `django_migrations`.`name` FROM `django_migrations`; args=()
"GET / HTTP/1.1" 200 5224
Exception while resolving variable 'hide_label' in template 'rest_framework/horizontal/input.html'.
Traceback (most recent call last):
  File "/Users/cribbee/Virtualenv/V-ZoomIn/lib/python3.6/site-packages/django/template/base.py", line 835, in _resolve_lookup
    current = current[bit]
KeyError: 'hide_label'

During handling of the above exception, another exception occurred:

Traceback (most recent call last):
  File "/Users/cribbee/Virtualenv/V-ZoomIn/lib/python3.6/site-packages/django/template/base.py", line 843, in _resolve_lookup
    current = getattr(current, bit)
AttributeError: 'dict' object has no attribute 'hide_label'

During handling of the above exception, another exception occurred:

Traceback (most recent call last):
  File "/Users/cribbee/Virtualenv/V-ZoomIn/lib/python3.6/site-packages/django/template/base.py", line 849, in _resolve_lookup
    current = current[int(bit)]
ValueError: invalid literal for int() with base 10: 'hide_label'

During handling of the above exception, another exception occurred:

Traceback (most recent call last):
  File "/Users/cribbee/Virtualenv/V-ZoomIn/lib/python3.6/site-packages/django/template/base.py", line 856, in _resolve_lookup
    (bit, current))  # missing attribute
django.template.base.VariableDoesNotExist: Failed lookup for key [hide_label] in {'base_template': 'input.html', 'input_type': 'text', 'template_pack': 'rest_framework/horizontal', 'renderer': <rest_framework.renderers.HTMLFormRenderer object at 0x10fa0fb00>}
Exception while resolving variable 'placeholder' in template 'rest_framework/horizontal/input.html'.
Traceback (most recent call last):
  File "/Users/cribbee/Virtualenv/V-ZoomIn/lib/python3.6/site-packages/django/template/base.py", line 835, in _resolve_lookup
    current = current[bit]
KeyError: 'placeholder'

During handling of the above exception, another exception occurred:

Traceback (most recent call last):
  File "/Users/cribbee/Virtualenv/V-ZoomIn/lib/python3.6/site-packages/django/template/base.py", line 843, in _resolve_lookup
    current = getattr(current, bit)
AttributeError: 'dict' object has no attribute 'placeholder'

During handling of the above exception, another exception occurred:

Traceback (most recent call last):
  File "/Users/cribbee/Virtualenv/V-ZoomIn/lib/python3.6/site-packages/django/template/base.py", line 849, in _resolve_lookup
    current = current[int(bit)]
ValueError: invalid literal for int() with base 10: 'placeholder'

During handling of the above exception, another exception occurred:

Traceback (most recent call last):
  File "/Users/cribbee/Virtualenv/V-ZoomIn/lib/python3.6/site-packages/django/template/base.py", line 856, in _resolve_lookup
    (bit, current))  # missing attribute
django.template.base.VariableDoesNotExist: Failed lookup for key [placeholder] in {'base_template': 'input.html', 'input_type': 'text', 'template_pack': 'rest_framework/horizontal', 'renderer': <rest_framework.renderers.HTMLFormRenderer object at 0x10fa0fb00>}
Exception while resolving variable 'autofocus' in template 'rest_framework/horizontal/input.html'.
Traceback (most recent call last):
  File "/Users/cribbee/Virtualenv/V-ZoomIn/lib/python3.6/site-packages/django/template/base.py", line 835, in _resolve_lookup
    current = current[bit]
KeyError: 'autofocus'

During handling of the above exception, another exception occurred:

Traceback (most recent call last):
  File "/Users/cribbee/Virtualenv/V-ZoomIn/lib/python3.6/site-packages/django/template/base.py", line 843, in _resolve_lookup
    current = getattr(current, bit)
AttributeError: 'dict' object has no attribute 'autofocus'

During handling of the above exception, another exception occurred:

Traceback (most recent call last):
  File "/Users/cribbee/Virtualenv/V-ZoomIn/lib/python3.6/site-packages/django/template/base.py", line 849, in _resolve_lookup
    current = current[int(bit)]
ValueError: invalid literal for int() with base 10: 'autofocus'

During handling of the above exception, another exception occurred:

Traceback (most recent call last):
  File "/Users/cribbee/Virtualenv/V-ZoomIn/lib/python3.6/site-packages/django/template/base.py", line 856, in _resolve_lookup
    (bit, current))  # missing attribute
django.template.base.VariableDoesNotExist: Failed lookup for key [autofocus] in {'base_template': 'input.html', 'input_type': 'text', 'template_pack': 'rest_framework/horizontal', 'renderer': <rest_framework.renderers.HTMLFormRenderer object at 0x10fa0fb00>}
Exception while resolving variable 'hide_label' in template 'rest_framework/horizontal/input.html'.
Traceback (most recent call last):
  File "/Users/cribbee/Virtualenv/V-ZoomIn/lib/python3.6/site-packages/django/template/base.py", line 835, in _resolve_lookup
    current = current[bit]
KeyError: 'hide_label'

During handling of the above exception, another exception occurred:

Traceback (most recent call last):
  File "/Users/cribbee/Virtualenv/V-ZoomIn/lib/python3.6/site-packages/django/template/base.py", line 843, in _resolve_lookup
    current = getattr(current, bit)
AttributeError: 'dict' object has no attribute 'hide_label'

During handling of the above exception, another exception occurred:

Traceback (most recent call last):
  File "/Users/cribbee/Virtualenv/V-ZoomIn/lib/python3.6/site-packages/django/template/base.py", line 849, in _resolve_lookup
    current = current[int(bit)]
ValueError: invalid literal for int() with base 10: 'hide_label'

During handling of the above exception, another exception occurred:

Traceback (most recent call last):
  File "/Users/cribbee/Virtualenv/V-ZoomIn/lib/python3.6/site-packages/django/template/base.py", line 856, in _resolve_lookup
    (bit, current))  # missing attribute
django.template.base.VariableDoesNotExist: Failed lookup for key [hide_label] in {'base_template': 'input.html', 'input_type': 'password', 'template_pack': 'rest_framework/horizontal', 'renderer': <rest_framework.renderers.HTMLFormRenderer object at 0x10fa0fb00>}
Exception while resolving variable 'placeholder' in template 'rest_framework/horizontal/input.html'.
Traceback (most recent call last):
  File "/Users/cribbee/Virtualenv/V-ZoomIn/lib/python3.6/site-packages/django/template/base.py", line 835, in _resolve_lookup
    current = current[bit]
KeyError: 'placeholder'

During handling of the above exception, another exception occurred:

Traceback (most recent call last):
  File "/Users/cribbee/Virtualenv/V-ZoomIn/lib/python3.6/site-packages/django/template/base.py", line 843, in _resolve_lookup
    current = getattr(current, bit)
AttributeError: 'dict' object has no attribute 'placeholder'

During handling of the above exception, another exception occurred:

Traceback (most recent call last):
  File "/Users/cribbee/Virtualenv/V-ZoomIn/lib/python3.6/site-packages/django/template/base.py", line 849, in _resolve_lookup
    current = current[int(bit)]
ValueError: invalid literal for int() with base 10: 'placeholder'

During handling of the above exception, another exception occurred:

Traceback (most recent call last):
  File "/Users/cribbee/Virtualenv/V-ZoomIn/lib/python3.6/site-packages/django/template/base.py", line 856, in _resolve_lookup
    (bit, current))  # missing attribute
django.template.base.VariableDoesNotExist: Failed lookup for key [placeholder] in {'base_template': 'input.html', 'input_type': 'password', 'template_pack': 'rest_framework/horizontal', 'renderer': <rest_framework.renderers.HTMLFormRenderer object at 0x10fa0fb00>}
Exception while resolving variable 'autofocus' in template 'rest_framework/horizontal/input.html'.
Traceback (most recent call last):
  File "/Users/cribbee/Virtualenv/V-ZoomIn/lib/python3.6/site-packages/django/template/base.py", line 835, in _resolve_lookup
    current = current[bit]
KeyError: 'autofocus'

During handling of the above exception, another exception occurred:

Traceback (most recent call last):
  File "/Users/cribbee/Virtualenv/V-ZoomIn/lib/python3.6/site-packages/django/template/base.py", line 843, in _resolve_lookup
    current = getattr(current, bit)
AttributeError: 'dict' object has no attribute 'autofocus'

During handling of the above exception, another exception occurred:

Traceback (most recent call last):
  File "/Users/cribbee/Virtualenv/V-ZoomIn/lib/python3.6/site-packages/django/template/base.py", line 849, in _resolve_lookup
    current = current[int(bit)]
ValueError: invalid literal for int() with base 10: 'autofocus'

During handling of the above exception, another exception occurred:

Traceback (most recent call last):
  File "/Users/cribbee/Virtualenv/V-ZoomIn/lib/python3.6/site-packages/django/template/base.py", line 856, in _resolve_lookup
    (bit, current))  # missing attribute
django.template.base.VariableDoesNotExist: Failed lookup for key [autofocus] in {'base_template': 'input.html', 'input_type': 'password', 'template_pack': 'rest_framework/horizontal', 'renderer': <rest_framework.renderers.HTMLFormRenderer object at 0x10fa0fb00>}
"GET /login/ HTTP/1.1" 405 7693
(0.000) SELECT @@SQL_AUTO_IS_NULL; args=None
(0.000) SET SESSION TRANSACTION ISOLATION LEVEL READ COMMITTED; args=None
(0.000) SELECT VERSION(); args=None
(0.000) SET SESSION TRANSACTION ISOLATION LEVEL READ COMMITTED; args=None
(0.044) SELECT `users_userprofile`.`id`, `users_userprofile`.`password`, `users_userprofile`.`last_login`, `users_userprofile`.`is_superuser`, `users_userprofile`.`username`, `users_userprofile`.`first_name`, `users_userprofile`.`last_name`, `users_userprofile`.`is_staff`, `users_userprofile`.`is_active`, `users_userprofile`.`date_joined`, `users_userprofile`.`name`, `users_userprofile`.`birthday`, `users_userprofile`.`mobile`, `users_userprofile`.`gender`, `users_userprofile`.`email`, `users_userprofile`.`task_num` FROM `users_userprofile` WHERE (`users_userprofile`.`username` = 'lxy' OR `users_userprofile`.`mobile` = 'lxy'); args=('lxy', 'lxy')
Exception while resolving variable 'hide_label' in template 'rest_framework/horizontal/input.html'.
Traceback (most recent call last):
  File "/Users/cribbee/Virtualenv/V-ZoomIn/lib/python3.6/site-packages/django/template/base.py", line 835, in _resolve_lookup
    current = current[bit]
KeyError: 'hide_label'

During handling of the above exception, another exception occurred:

Traceback (most recent call last):
  File "/Users/cribbee/Virtualenv/V-ZoomIn/lib/python3.6/site-packages/django/template/base.py", line 843, in _resolve_lookup
    current = getattr(current, bit)
AttributeError: 'dict' object has no attribute 'hide_label'

During handling of the above exception, another exception occurred:

Traceback (most recent call last):
  File "/Users/cribbee/Virtualenv/V-ZoomIn/lib/python3.6/site-packages/django/template/base.py", line 849, in _resolve_lookup
    current = current[int(bit)]
ValueError: invalid literal for int() with base 10: 'hide_label'

During handling of the above exception, another exception occurred:

Traceback (most recent call last):
  File "/Users/cribbee/Virtualenv/V-ZoomIn/lib/python3.6/site-packages/django/template/base.py", line 856, in _resolve_lookup
    (bit, current))  # missing attribute
django.template.base.VariableDoesNotExist: Failed lookup for key [hide_label] in {'base_template': 'input.html', 'input_type': 'text', 'template_pack': 'rest_framework/horizontal', 'renderer': <rest_framework.renderers.HTMLFormRenderer object at 0x10fa554e0>}
Exception while resolving variable 'placeholder' in template 'rest_framework/horizontal/input.html'.
Traceback (most recent call last):
  File "/Users/cribbee/Virtualenv/V-ZoomIn/lib/python3.6/site-packages/django/template/base.py", line 835, in _resolve_lookup
    current = current[bit]
KeyError: 'placeholder'

During handling of the above exception, another exception occurred:

Traceback (most recent call last):
  File "/Users/cribbee/Virtualenv/V-ZoomIn/lib/python3.6/site-packages/django/template/base.py", line 843, in _resolve_lookup
    current = getattr(current, bit)
AttributeError: 'dict' object has no attribute 'placeholder'

During handling of the above exception, another exception occurred:

Traceback (most recent call last):
  File "/Users/cribbee/Virtualenv/V-ZoomIn/lib/python3.6/site-packages/django/template/base.py", line 849, in _resolve_lookup
    current = current[int(bit)]
ValueError: invalid literal for int() with base 10: 'placeholder'

During handling of the above exception, another exception occurred:

Traceback (most recent call last):
  File "/Users/cribbee/Virtualenv/V-ZoomIn/lib/python3.6/site-packages/django/template/base.py", line 856, in _resolve_lookup
    (bit, current))  # missing attribute
django.template.base.VariableDoesNotExist: Failed lookup for key [placeholder] in {'base_template': 'input.html', 'input_type': 'text', 'template_pack': 'rest_framework/horizontal', 'renderer': <rest_framework.renderers.HTMLFormRenderer object at 0x10fa554e0>}
Exception while resolving variable 'autofocus' in template 'rest_framework/horizontal/input.html'.
Traceback (most recent call last):
  File "/Users/cribbee/Virtualenv/V-ZoomIn/lib/python3.6/site-packages/django/template/base.py", line 835, in _resolve_lookup
    current = current[bit]
KeyError: 'autofocus'

During handling of the above exception, another exception occurred:

Traceback (most recent call last):
  File "/Users/cribbee/Virtualenv/V-ZoomIn/lib/python3.6/site-packages/django/template/base.py", line 843, in _resolve_lookup
    current = getattr(current, bit)
AttributeError: 'dict' object has no attribute 'autofocus'

During handling of the above exception, another exception occurred:

Traceback (most recent call last):
  File "/Users/cribbee/Virtualenv/V-ZoomIn/lib/python3.6/site-packages/django/template/base.py", line 849, in _resolve_lookup
    current = current[int(bit)]
ValueError: invalid literal for int() with base 10: 'autofocus'

During handling of the above exception, another exception occurred:

Traceback (most recent call last):
  File "/Users/cribbee/Virtualenv/V-ZoomIn/lib/python3.6/site-packages/django/template/base.py", line 856, in _resolve_lookup
    (bit, current))  # missing attribute
django.template.base.VariableDoesNotExist: Failed lookup for key [autofocus] in {'base_template': 'input.html', 'input_type': 'text', 'template_pack': 'rest_framework/horizontal', 'renderer': <rest_framework.renderers.HTMLFormRenderer object at 0x10fa554e0>}
Exception while resolving variable 'hide_label' in template 'rest_framework/horizontal/input.html'.
Traceback (most recent call last):
  File "/Users/cribbee/Virtualenv/V-ZoomIn/lib/python3.6/site-packages/django/template/base.py", line 835, in _resolve_lookup
    current = current[bit]
KeyError: 'hide_label'

During handling of the above exception, another exception occurred:

Traceback (most recent call last):
  File "/Users/cribbee/Virtualenv/V-ZoomIn/lib/python3.6/site-packages/django/template/base.py", line 843, in _resolve_lookup
    current = getattr(current, bit)
AttributeError: 'dict' object has no attribute 'hide_label'

During handling of the above exception, another exception occurred:

Traceback (most recent call last):
  File "/Users/cribbee/Virtualenv/V-ZoomIn/lib/python3.6/site-packages/django/template/base.py", line 849, in _resolve_lookup
    current = current[int(bit)]
ValueError: invalid literal for int() with base 10: 'hide_label'

During handling of the above exception, another exception occurred:

Traceback (most recent call last):
  File "/Users/cribbee/Virtualenv/V-ZoomIn/lib/python3.6/site-packages/django/template/base.py", line 856, in _resolve_lookup
    (bit, current))  # missing attribute
django.template.base.VariableDoesNotExist: Failed lookup for key [hide_label] in {'base_template': 'input.html', 'input_type': 'password', 'template_pack': 'rest_framework/horizontal', 'renderer': <rest_framework.renderers.HTMLFormRenderer object at 0x10fa554e0>}
Exception while resolving variable 'placeholder' in template 'rest_framework/horizontal/input.html'.
Traceback (most recent call last):
  File "/Users/cribbee/Virtualenv/V-ZoomIn/lib/python3.6/site-packages/django/template/base.py", line 835, in _resolve_lookup
    current = current[bit]
KeyError: 'placeholder'

During handling of the above exception, another exception occurred:

Traceback (most recent call last):
  File "/Users/cribbee/Virtualenv/V-ZoomIn/lib/python3.6/site-packages/django/template/base.py", line 843, in _resolve_lookup
    current = getattr(current, bit)
AttributeError: 'dict' object has no attribute 'placeholder'

During handling of the above exception, another exception occurred:

Traceback (most recent call last):
  File "/Users/cribbee/Virtualenv/V-ZoomIn/lib/python3.6/site-packages/django/template/base.py", line 849, in _resolve_lookup
    current = current[int(bit)]
ValueError: invalid literal for int() with base 10: 'placeholder'

During handling of the above exception, another exception occurred:

Traceback (most recent call last):
  File "/Users/cribbee/Virtualenv/V-ZoomIn/lib/python3.6/site-packages/django/template/base.py", line 856, in _resolve_lookup
    (bit, current))  # missing attribute
django.template.base.VariableDoesNotExist: Failed lookup for key [placeholder] in {'base_template': 'input.html', 'input_type': 'password', 'template_pack': 'rest_framework/horizontal', 'renderer': <rest_framework.renderers.HTMLFormRenderer object at 0x10fa554e0>}
Exception while resolving variable 'autofocus' in template 'rest_framework/horizontal/input.html'.
Traceback (most recent call last):
  File "/Users/cribbee/Virtualenv/V-ZoomIn/lib/python3.6/site-packages/django/template/base.py", line 835, in _resolve_lookup
    current = current[bit]
KeyError: 'autofocus'

During handling of the above exception, another exception occurred:

Traceback (most recent call last):
  File "/Users/cribbee/Virtualenv/V-ZoomIn/lib/python3.6/site-packages/django/template/base.py", line 843, in _resolve_lookup
    current = getattr(current, bit)
AttributeError: 'dict' object has no attribute 'autofocus'

During handling of the above exception, another exception occurred:

Traceback (most recent call last):
  File "/Users/cribbee/Virtualenv/V-ZoomIn/lib/python3.6/site-packages/django/template/base.py", line 849, in _resolve_lookup
    current = current[int(bit)]
ValueError: invalid literal for int() with base 10: 'autofocus'

During handling of the above exception, another exception occurred:

Traceback (most recent call last):
  File "/Users/cribbee/Virtualenv/V-ZoomIn/lib/python3.6/site-packages/django/template/base.py", line 856, in _resolve_lookup
    (bit, current))  # missing attribute
django.template.base.VariableDoesNotExist: Failed lookup for key [autofocus] in {'base_template': 'input.html', 'input_type': 'password', 'template_pack': 'rest_framework/horizontal', 'renderer': <rest_framework.renderers.HTMLFormRenderer object at 0x10fa554e0>}
"POST /login/ HTTP/1.1" 400 7734
(0.001) SELECT @@SQL_AUTO_IS_NULL; args=None
(0.000) SET SESSION TRANSACTION ISOLATION LEVEL READ COMMITTED; args=None
(0.000) SELECT VERSION(); args=None
(0.000) SET SESSION TRANSACTION ISOLATION LEVEL READ COMMITTED; args=None
(0.006) SHOW FULL TABLES; args=None
(0.005) SELECT `django_migrations`.`app`, `django_migrations`.`name` FROM `django_migrations`; args=()
(0.001) SELECT @@SQL_AUTO_IS_NULL; args=None
(0.000) SET SESSION TRANSACTION ISOLATION LEVEL READ COMMITTED; args=None
(0.000) SELECT VERSION(); args=None
(0.000) SET SESSION TRANSACTION ISOLATION LEVEL READ COMMITTED; args=None
(0.006) SHOW FULL TABLES; args=None
(0.003) SELECT `django_migrations`.`app`, `django_migrations`.`name` FROM `django_migrations`; args=()
(0.000) SELECT @@SQL_AUTO_IS_NULL; args=None
(0.000) SET SESSION TRANSACTION ISOLATION LEVEL READ COMMITTED; args=None
(0.000) SELECT VERSION(); args=None
(0.000) SET SESSION TRANSACTION ISOLATION LEVEL READ COMMITTED; args=None
(0.015) SHOW FULL TABLES; args=None
(0.006) SELECT `django_migrations`.`app`, `django_migrations`.`name` FROM `django_migrations`; args=()
"GET / HTTP/1.1" 200 5224
Exception while resolving variable 'hide_label' in template 'rest_framework/horizontal/input.html'.
Traceback (most recent call last):
  File "/Users/cribbee/Virtualenv/V-ZoomIn/lib/python3.6/site-packages/django/template/base.py", line 835, in _resolve_lookup
    current = current[bit]
KeyError: 'hide_label'

During handling of the above exception, another exception occurred:

Traceback (most recent call last):
  File "/Users/cribbee/Virtualenv/V-ZoomIn/lib/python3.6/site-packages/django/template/base.py", line 843, in _resolve_lookup
    current = getattr(current, bit)
AttributeError: 'dict' object has no attribute 'hide_label'

During handling of the above exception, another exception occurred:

Traceback (most recent call last):
  File "/Users/cribbee/Virtualenv/V-ZoomIn/lib/python3.6/site-packages/django/template/base.py", line 849, in _resolve_lookup
    current = current[int(bit)]
ValueError: invalid literal for int() with base 10: 'hide_label'

During handling of the above exception, another exception occurred:

Traceback (most recent call last):
  File "/Users/cribbee/Virtualenv/V-ZoomIn/lib/python3.6/site-packages/django/template/base.py", line 856, in _resolve_lookup
    (bit, current))  # missing attribute
django.template.base.VariableDoesNotExist: Failed lookup for key [hide_label] in {'base_template': 'input.html', 'input_type': 'text', 'template_pack': 'rest_framework/horizontal', 'renderer': <rest_framework.renderers.HTMLFormRenderer object at 0x10a3efef0>}
Exception while resolving variable 'placeholder' in template 'rest_framework/horizontal/input.html'.
Traceback (most recent call last):
  File "/Users/cribbee/Virtualenv/V-ZoomIn/lib/python3.6/site-packages/django/template/base.py", line 835, in _resolve_lookup
    current = current[bit]
KeyError: 'placeholder'

During handling of the above exception, another exception occurred:

Traceback (most recent call last):
  File "/Users/cribbee/Virtualenv/V-ZoomIn/lib/python3.6/site-packages/django/template/base.py", line 843, in _resolve_lookup
    current = getattr(current, bit)
AttributeError: 'dict' object has no attribute 'placeholder'

During handling of the above exception, another exception occurred:

Traceback (most recent call last):
  File "/Users/cribbee/Virtualenv/V-ZoomIn/lib/python3.6/site-packages/django/template/base.py", line 849, in _resolve_lookup
    current = current[int(bit)]
ValueError: invalid literal for int() with base 10: 'placeholder'

During handling of the above exception, another exception occurred:

Traceback (most recent call last):
  File "/Users/cribbee/Virtualenv/V-ZoomIn/lib/python3.6/site-packages/django/template/base.py", line 856, in _resolve_lookup
    (bit, current))  # missing attribute
django.template.base.VariableDoesNotExist: Failed lookup for key [placeholder] in {'base_template': 'input.html', 'input_type': 'text', 'template_pack': 'rest_framework/horizontal', 'renderer': <rest_framework.renderers.HTMLFormRenderer object at 0x10a3efef0>}
Exception while resolving variable 'autofocus' in template 'rest_framework/horizontal/input.html'.
Traceback (most recent call last):
  File "/Users/cribbee/Virtualenv/V-ZoomIn/lib/python3.6/site-packages/django/template/base.py", line 835, in _resolve_lookup
    current = current[bit]
KeyError: 'autofocus'

During handling of the above exception, another exception occurred:

Traceback (most recent call last):
  File "/Users/cribbee/Virtualenv/V-ZoomIn/lib/python3.6/site-packages/django/template/base.py", line 843, in _resolve_lookup
    current = getattr(current, bit)
AttributeError: 'dict' object has no attribute 'autofocus'

During handling of the above exception, another exception occurred:

Traceback (most recent call last):
  File "/Users/cribbee/Virtualenv/V-ZoomIn/lib/python3.6/site-packages/django/template/base.py", line 849, in _resolve_lookup
    current = current[int(bit)]
ValueError: invalid literal for int() with base 10: 'autofocus'

During handling of the above exception, another exception occurred:

Traceback (most recent call last):
  File "/Users/cribbee/Virtualenv/V-ZoomIn/lib/python3.6/site-packages/django/template/base.py", line 856, in _resolve_lookup
    (bit, current))  # missing attribute
django.template.base.VariableDoesNotExist: Failed lookup for key [autofocus] in {'base_template': 'input.html', 'input_type': 'text', 'template_pack': 'rest_framework/horizontal', 'renderer': <rest_framework.renderers.HTMLFormRenderer object at 0x10a3efef0>}
Exception while resolving variable 'hide_label' in template 'rest_framework/horizontal/input.html'.
Traceback (most recent call last):
  File "/Users/cribbee/Virtualenv/V-ZoomIn/lib/python3.6/site-packages/django/template/base.py", line 835, in _resolve_lookup
    current = current[bit]
KeyError: 'hide_label'

During handling of the above exception, another exception occurred:

Traceback (most recent call last):
  File "/Users/cribbee/Virtualenv/V-ZoomIn/lib/python3.6/site-packages/django/template/base.py", line 843, in _resolve_lookup
    current = getattr(current, bit)
AttributeError: 'dict' object has no attribute 'hide_label'

During handling of the above exception, another exception occurred:

Traceback (most recent call last):
  File "/Users/cribbee/Virtualenv/V-ZoomIn/lib/python3.6/site-packages/django/template/base.py", line 849, in _resolve_lookup
    current = current[int(bit)]
ValueError: invalid literal for int() with base 10: 'hide_label'

During handling of the above exception, another exception occurred:

Traceback (most recent call last):
  File "/Users/cribbee/Virtualenv/V-ZoomIn/lib/python3.6/site-packages/django/template/base.py", line 856, in _resolve_lookup
    (bit, current))  # missing attribute
django.template.base.VariableDoesNotExist: Failed lookup for key [hide_label] in {'base_template': 'input.html', 'input_type': 'password', 'template_pack': 'rest_framework/horizontal', 'renderer': <rest_framework.renderers.HTMLFormRenderer object at 0x10a3efef0>}
Exception while resolving variable 'placeholder' in template 'rest_framework/horizontal/input.html'.
Traceback (most recent call last):
  File "/Users/cribbee/Virtualenv/V-ZoomIn/lib/python3.6/site-packages/django/template/base.py", line 835, in _resolve_lookup
    current = current[bit]
KeyError: 'placeholder'

During handling of the above exception, another exception occurred:

Traceback (most recent call last):
  File "/Users/cribbee/Virtualenv/V-ZoomIn/lib/python3.6/site-packages/django/template/base.py", line 843, in _resolve_lookup
    current = getattr(current, bit)
AttributeError: 'dict' object has no attribute 'placeholder'

During handling of the above exception, another exception occurred:

Traceback (most recent call last):
  File "/Users/cribbee/Virtualenv/V-ZoomIn/lib/python3.6/site-packages/django/template/base.py", line 849, in _resolve_lookup
    current = current[int(bit)]
ValueError: invalid literal for int() with base 10: 'placeholder'

During handling of the above exception, another exception occurred:

Traceback (most recent call last):
  File "/Users/cribbee/Virtualenv/V-ZoomIn/lib/python3.6/site-packages/django/template/base.py", line 856, in _resolve_lookup
    (bit, current))  # missing attribute
django.template.base.VariableDoesNotExist: Failed lookup for key [placeholder] in {'base_template': 'input.html', 'input_type': 'password', 'template_pack': 'rest_framework/horizontal', 'renderer': <rest_framework.renderers.HTMLFormRenderer object at 0x10a3efef0>}
Exception while resolving variable 'autofocus' in template 'rest_framework/horizontal/input.html'.
Traceback (most recent call last):
  File "/Users/cribbee/Virtualenv/V-ZoomIn/lib/python3.6/site-packages/django/template/base.py", line 835, in _resolve_lookup
    current = current[bit]
KeyError: 'autofocus'

During handling of the above exception, another exception occurred:

Traceback (most recent call last):
  File "/Users/cribbee/Virtualenv/V-ZoomIn/lib/python3.6/site-packages/django/template/base.py", line 843, in _resolve_lookup
    current = getattr(current, bit)
AttributeError: 'dict' object has no attribute 'autofocus'

During handling of the above exception, another exception occurred:

Traceback (most recent call last):
  File "/Users/cribbee/Virtualenv/V-ZoomIn/lib/python3.6/site-packages/django/template/base.py", line 849, in _resolve_lookup
    current = current[int(bit)]
ValueError: invalid literal for int() with base 10: 'autofocus'

During handling of the above exception, another exception occurred:

Traceback (most recent call last):
  File "/Users/cribbee/Virtualenv/V-ZoomIn/lib/python3.6/site-packages/django/template/base.py", line 856, in _resolve_lookup
    (bit, current))  # missing attribute
django.template.base.VariableDoesNotExist: Failed lookup for key [autofocus] in {'base_template': 'input.html', 'input_type': 'password', 'template_pack': 'rest_framework/horizontal', 'renderer': <rest_framework.renderers.HTMLFormRenderer object at 0x10a3efef0>}
"GET /users/ HTTP/1.1" 405 7634
Exception while resolving variable 'name' in template 'unknown'.
Traceback (most recent call last):
  File "/Users/cribbee/Virtualenv/V-ZoomIn/lib/python3.6/site-packages/django/core/handlers/exception.py", line 35, in inner
    response = get_response(request)
  File "/Users/cribbee/Virtualenv/V-ZoomIn/lib/python3.6/site-packages/django/core/handlers/base.py", line 113, in _get_response
    resolver_match = resolver.resolve(request.path_info)
  File "/Users/cribbee/Virtualenv/V-ZoomIn/lib/python3.6/site-packages/django/urls/resolvers.py", line 523, in resolve
    raise Resolver404({'tried': tried, 'path': new_path})
django.urls.exceptions.Resolver404: {'tried': [[<URLPattern '^upload/(?P<path>.*)$'>], [<URLResolver <module 'rest_framework.urls' from '/Users/cribbee/Virtualenv/V-ZoomIn/lib/python3.6/site-packages/rest_framework/urls.py'> (rest_framework:rest_framework) '^api-auth/'>], [<URLResolver <module 'tasks.urls' from '/Users/cribbee/PycharmProjects/ZoomInDev/apps/tasks/urls.py'> (None:None) '^task'>], [<URLResolver <URLPattern list> (None:None) '^'>, <URLPattern '^users/$' [name='users-list']>], [<URLResolver <URLPattern list> (None:None) '^'>, <URLPattern '^users\.(?P<format>[a-z0-9]+)/?$' [name='users-list']>], [<URLResolver <URLPattern list> (None:None) '^'>, <URLPattern '^$' [name='api-root']>], [<URLResolver <URLPattern list> (None:None) '^'>, <URLPattern '^\.(?P<format>[a-z0-9]+)/?$' [name='api-root']>], [<URLPattern '^api-token-auth/'>], [<URLPattern '^login/'>]], 'path': 'users/1'}

During handling of the above exception, another exception occurred:

Traceback (most recent call last):
  File "/Users/cribbee/Virtualenv/V-ZoomIn/lib/python3.6/site-packages/django/template/base.py", line 835, in _resolve_lookup
    current = current[bit]
TypeError: 'URLResolver' object is not subscriptable

During handling of the above exception, another exception occurred:

Traceback (most recent call last):
  File "/Users/cribbee/Virtualenv/V-ZoomIn/lib/python3.6/site-packages/django/template/base.py", line 843, in _resolve_lookup
    current = getattr(current, bit)
AttributeError: 'URLResolver' object has no attribute 'name'

During handling of the above exception, another exception occurred:

Traceback (most recent call last):
  File "/Users/cribbee/Virtualenv/V-ZoomIn/lib/python3.6/site-packages/django/template/base.py", line 849, in _resolve_lookup
    current = current[int(bit)]
ValueError: invalid literal for int() with base 10: 'name'

During handling of the above exception, another exception occurred:

Traceback (most recent call last):
  File "/Users/cribbee/Virtualenv/V-ZoomIn/lib/python3.6/site-packages/django/template/base.py", line 856, in _resolve_lookup
    (bit, current))  # missing attribute
django.template.base.VariableDoesNotExist: Failed lookup for key [name] in <URLResolver <module 'rest_framework.urls' from '/Users/cribbee/Virtualenv/V-ZoomIn/lib/python3.6/site-packages/rest_framework/urls.py'> (rest_framework:rest_framework) '^api-auth/'>
Exception while resolving variable 'name' in template 'unknown'.
Traceback (most recent call last):
  File "/Users/cribbee/Virtualenv/V-ZoomIn/lib/python3.6/site-packages/django/core/handlers/exception.py", line 35, in inner
    response = get_response(request)
  File "/Users/cribbee/Virtualenv/V-ZoomIn/lib/python3.6/site-packages/django/core/handlers/base.py", line 113, in _get_response
    resolver_match = resolver.resolve(request.path_info)
  File "/Users/cribbee/Virtualenv/V-ZoomIn/lib/python3.6/site-packages/django/urls/resolvers.py", line 523, in resolve
    raise Resolver404({'tried': tried, 'path': new_path})
django.urls.exceptions.Resolver404: {'tried': [[<URLPattern '^upload/(?P<path>.*)$'>], [<URLResolver <module 'rest_framework.urls' from '/Users/cribbee/Virtualenv/V-ZoomIn/lib/python3.6/site-packages/rest_framework/urls.py'> (rest_framework:rest_framework) '^api-auth/'>], [<URLResolver <module 'tasks.urls' from '/Users/cribbee/PycharmProjects/ZoomInDev/apps/tasks/urls.py'> (None:None) '^task'>], [<URLResolver <URLPattern list> (None:None) '^'>, <URLPattern '^users/$' [name='users-list']>], [<URLResolver <URLPattern list> (None:None) '^'>, <URLPattern '^users\.(?P<format>[a-z0-9]+)/?$' [name='users-list']>], [<URLResolver <URLPattern list> (None:None) '^'>, <URLPattern '^$' [name='api-root']>], [<URLResolver <URLPattern list> (None:None) '^'>, <URLPattern '^\.(?P<format>[a-z0-9]+)/?$' [name='api-root']>], [<URLPattern '^api-token-auth/'>], [<URLPattern '^login/'>]], 'path': 'users/1'}

During handling of the above exception, another exception occurred:

Traceback (most recent call last):
  File "/Users/cribbee/Virtualenv/V-ZoomIn/lib/python3.6/site-packages/django/template/base.py", line 835, in _resolve_lookup
    current = current[bit]
TypeError: 'URLResolver' object is not subscriptable

During handling of the above exception, another exception occurred:

Traceback (most recent call last):
  File "/Users/cribbee/Virtualenv/V-ZoomIn/lib/python3.6/site-packages/django/template/base.py", line 843, in _resolve_lookup
    current = getattr(current, bit)
AttributeError: 'URLResolver' object has no attribute 'name'

During handling of the above exception, another exception occurred:

Traceback (most recent call last):
  File "/Users/cribbee/Virtualenv/V-ZoomIn/lib/python3.6/site-packages/django/template/base.py", line 849, in _resolve_lookup
    current = current[int(bit)]
ValueError: invalid literal for int() with base 10: 'name'

During handling of the above exception, another exception occurred:

Traceback (most recent call last):
  File "/Users/cribbee/Virtualenv/V-ZoomIn/lib/python3.6/site-packages/django/template/base.py", line 856, in _resolve_lookup
    (bit, current))  # missing attribute
django.template.base.VariableDoesNotExist: Failed lookup for key [name] in <URLResolver <module 'tasks.urls' from '/Users/cribbee/PycharmProjects/ZoomInDev/apps/tasks/urls.py'> (None:None) '^task'>
Not Found: /users/1
"GET /users/1 HTTP/1.1" 404 3167
Exception while resolving variable 'name' in template 'unknown'.
Traceback (most recent call last):
  File "/Users/cribbee/Virtualenv/V-ZoomIn/lib/python3.6/site-packages/django/core/handlers/exception.py", line 35, in inner
    response = get_response(request)
  File "/Users/cribbee/Virtualenv/V-ZoomIn/lib/python3.6/site-packages/django/core/handlers/base.py", line 113, in _get_response
    resolver_match = resolver.resolve(request.path_info)
  File "/Users/cribbee/Virtualenv/V-ZoomIn/lib/python3.6/site-packages/django/urls/resolvers.py", line 523, in resolve
    raise Resolver404({'tried': tried, 'path': new_path})
django.urls.exceptions.Resolver404: {'tried': [[<URLPattern '^upload/(?P<path>.*)$'>], [<URLResolver <module 'rest_framework.urls' from '/Users/cribbee/Virtualenv/V-ZoomIn/lib/python3.6/site-packages/rest_framework/urls.py'> (rest_framework:rest_framework) '^api-auth/'>], [<URLResolver <module 'tasks.urls' from '/Users/cribbee/PycharmProjects/ZoomInDev/apps/tasks/urls.py'> (None:None) '^task'>], [<URLResolver <URLPattern list> (None:None) '^'>, <URLPattern '^users/$' [name='users-list']>], [<URLResolver <URLPattern list> (None:None) '^'>, <URLPattern '^users\.(?P<format>[a-z0-9]+)/?$' [name='users-list']>], [<URLResolver <URLPattern list> (None:None) '^'>, <URLPattern '^$' [name='api-root']>], [<URLResolver <URLPattern list> (None:None) '^'>, <URLPattern '^\.(?P<format>[a-z0-9]+)/?$' [name='api-root']>], [<URLPattern '^api-token-auth/'>], [<URLPattern '^login/'>]], 'path': 'users/4'}

During handling of the above exception, another exception occurred:

Traceback (most recent call last):
  File "/Users/cribbee/Virtualenv/V-ZoomIn/lib/python3.6/site-packages/django/template/base.py", line 835, in _resolve_lookup
    current = current[bit]
TypeError: 'URLResolver' object is not subscriptable

During handling of the above exception, another exception occurred:

Traceback (most recent call last):
  File "/Users/cribbee/Virtualenv/V-ZoomIn/lib/python3.6/site-packages/django/template/base.py", line 843, in _resolve_lookup
    current = getattr(current, bit)
AttributeError: 'URLResolver' object has no attribute 'name'

During handling of the above exception, another exception occurred:

Traceback (most recent call last):
  File "/Users/cribbee/Virtualenv/V-ZoomIn/lib/python3.6/site-packages/django/template/base.py", line 849, in _resolve_lookup
    current = current[int(bit)]
ValueError: invalid literal for int() with base 10: 'name'

During handling of the above exception, another exception occurred:

Traceback (most recent call last):
  File "/Users/cribbee/Virtualenv/V-ZoomIn/lib/python3.6/site-packages/django/template/base.py", line 856, in _resolve_lookup
    (bit, current))  # missing attribute
django.template.base.VariableDoesNotExist: Failed lookup for key [name] in <URLResolver <module 'rest_framework.urls' from '/Users/cribbee/Virtualenv/V-ZoomIn/lib/python3.6/site-packages/rest_framework/urls.py'> (rest_framework:rest_framework) '^api-auth/'>
Exception while resolving variable 'name' in template 'unknown'.
Traceback (most recent call last):
  File "/Users/cribbee/Virtualenv/V-ZoomIn/lib/python3.6/site-packages/django/core/handlers/exception.py", line 35, in inner
    response = get_response(request)
  File "/Users/cribbee/Virtualenv/V-ZoomIn/lib/python3.6/site-packages/django/core/handlers/base.py", line 113, in _get_response
    resolver_match = resolver.resolve(request.path_info)
  File "/Users/cribbee/Virtualenv/V-ZoomIn/lib/python3.6/site-packages/django/urls/resolvers.py", line 523, in resolve
    raise Resolver404({'tried': tried, 'path': new_path})
django.urls.exceptions.Resolver404: {'tried': [[<URLPattern '^upload/(?P<path>.*)$'>], [<URLResolver <module 'rest_framework.urls' from '/Users/cribbee/Virtualenv/V-ZoomIn/lib/python3.6/site-packages/rest_framework/urls.py'> (rest_framework:rest_framework) '^api-auth/'>], [<URLResolver <module 'tasks.urls' from '/Users/cribbee/PycharmProjects/ZoomInDev/apps/tasks/urls.py'> (None:None) '^task'>], [<URLResolver <URLPattern list> (None:None) '^'>, <URLPattern '^users/$' [name='users-list']>], [<URLResolver <URLPattern list> (None:None) '^'>, <URLPattern '^users\.(?P<format>[a-z0-9]+)/?$' [name='users-list']>], [<URLResolver <URLPattern list> (None:None) '^'>, <URLPattern '^$' [name='api-root']>], [<URLResolver <URLPattern list> (None:None) '^'>, <URLPattern '^\.(?P<format>[a-z0-9]+)/?$' [name='api-root']>], [<URLPattern '^api-token-auth/'>], [<URLPattern '^login/'>]], 'path': 'users/4'}

During handling of the above exception, another exception occurred:

Traceback (most recent call last):
  File "/Users/cribbee/Virtualenv/V-ZoomIn/lib/python3.6/site-packages/django/template/base.py", line 835, in _resolve_lookup
    current = current[bit]
TypeError: 'URLResolver' object is not subscriptable

During handling of the above exception, another exception occurred:

Traceback (most recent call last):
  File "/Users/cribbee/Virtualenv/V-ZoomIn/lib/python3.6/site-packages/django/template/base.py", line 843, in _resolve_lookup
    current = getattr(current, bit)
AttributeError: 'URLResolver' object has no attribute 'name'

During handling of the above exception, another exception occurred:

Traceback (most recent call last):
  File "/Users/cribbee/Virtualenv/V-ZoomIn/lib/python3.6/site-packages/django/template/base.py", line 849, in _resolve_lookup
    current = current[int(bit)]
ValueError: invalid literal for int() with base 10: 'name'

During handling of the above exception, another exception occurred:

Traceback (most recent call last):
  File "/Users/cribbee/Virtualenv/V-ZoomIn/lib/python3.6/site-packages/django/template/base.py", line 856, in _resolve_lookup
    (bit, current))  # missing attribute
django.template.base.VariableDoesNotExist: Failed lookup for key [name] in <URLResolver <module 'tasks.urls' from '/Users/cribbee/PycharmProjects/ZoomInDev/apps/tasks/urls.py'> (None:None) '^task'>
Not Found: /users/4
"GET /users/4 HTTP/1.1" 404 3167
Exception while resolving variable 'name' in template 'unknown'.
Traceback (most recent call last):
  File "/Users/cribbee/Virtualenv/V-ZoomIn/lib/python3.6/site-packages/django/core/handlers/exception.py", line 35, in inner
    response = get_response(request)
  File "/Users/cribbee/Virtualenv/V-ZoomIn/lib/python3.6/site-packages/django/core/handlers/base.py", line 113, in _get_response
    resolver_match = resolver.resolve(request.path_info)
  File "/Users/cribbee/Virtualenv/V-ZoomIn/lib/python3.6/site-packages/django/urls/resolvers.py", line 523, in resolve
    raise Resolver404({'tried': tried, 'path': new_path})
django.urls.exceptions.Resolver404: {'tried': [[<URLPattern '^upload/(?P<path>.*)$'>], [<URLResolver <module 'rest_framework.urls' from '/Users/cribbee/Virtualenv/V-ZoomIn/lib/python3.6/site-packages/rest_framework/urls.py'> (rest_framework:rest_framework) '^api-auth/'>], [<URLResolver <module 'tasks.urls' from '/Users/cribbee/PycharmProjects/ZoomInDev/apps/tasks/urls.py'> (None:None) '^task'>], [<URLResolver <URLPattern list> (None:None) '^'>, <URLPattern '^users/$' [name='users-list']>], [<URLResolver <URLPattern list> (None:None) '^'>, <URLPattern '^users\.(?P<format>[a-z0-9]+)/?$' [name='users-list']>], [<URLResolver <URLPattern list> (None:None) '^'>, <URLPattern '^$' [name='api-root']>], [<URLResolver <URLPattern list> (None:None) '^'>, <URLPattern '^\.(?P<format>[a-z0-9]+)/?$' [name='api-root']>], [<URLPattern '^api-token-auth/'>], [<URLPattern '^login/'>]], 'path': 'users/22'}

During handling of the above exception, another exception occurred:

Traceback (most recent call last):
  File "/Users/cribbee/Virtualenv/V-ZoomIn/lib/python3.6/site-packages/django/template/base.py", line 835, in _resolve_lookup
    current = current[bit]
TypeError: 'URLResolver' object is not subscriptable

During handling of the above exception, another exception occurred:

Traceback (most recent call last):
  File "/Users/cribbee/Virtualenv/V-ZoomIn/lib/python3.6/site-packages/django/template/base.py", line 843, in _resolve_lookup
    current = getattr(current, bit)
AttributeError: 'URLResolver' object has no attribute 'name'

During handling of the above exception, another exception occurred:

Traceback (most recent call last):
  File "/Users/cribbee/Virtualenv/V-ZoomIn/lib/python3.6/site-packages/django/template/base.py", line 849, in _resolve_lookup
    current = current[int(bit)]
ValueError: invalid literal for int() with base 10: 'name'

During handling of the above exception, another exception occurred:

Traceback (most recent call last):
  File "/Users/cribbee/Virtualenv/V-ZoomIn/lib/python3.6/site-packages/django/template/base.py", line 856, in _resolve_lookup
    (bit, current))  # missing attribute
django.template.base.VariableDoesNotExist: Failed lookup for key [name] in <URLResolver <module 'rest_framework.urls' from '/Users/cribbee/Virtualenv/V-ZoomIn/lib/python3.6/site-packages/rest_framework/urls.py'> (rest_framework:rest_framework) '^api-auth/'>
Exception while resolving variable 'name' in template 'unknown'.
Traceback (most recent call last):
  File "/Users/cribbee/Virtualenv/V-ZoomIn/lib/python3.6/site-packages/django/core/handlers/exception.py", line 35, in inner
    response = get_response(request)
  File "/Users/cribbee/Virtualenv/V-ZoomIn/lib/python3.6/site-packages/django/core/handlers/base.py", line 113, in _get_response
    resolver_match = resolver.resolve(request.path_info)
  File "/Users/cribbee/Virtualenv/V-ZoomIn/lib/python3.6/site-packages/django/urls/resolvers.py", line 523, in resolve
    raise Resolver404({'tried': tried, 'path': new_path})
django.urls.exceptions.Resolver404: {'tried': [[<URLPattern '^upload/(?P<path>.*)$'>], [<URLResolver <module 'rest_framework.urls' from '/Users/cribbee/Virtualenv/V-ZoomIn/lib/python3.6/site-packages/rest_framework/urls.py'> (rest_framework:rest_framework) '^api-auth/'>], [<URLResolver <module 'tasks.urls' from '/Users/cribbee/PycharmProjects/ZoomInDev/apps/tasks/urls.py'> (None:None) '^task'>], [<URLResolver <URLPattern list> (None:None) '^'>, <URLPattern '^users/$' [name='users-list']>], [<URLResolver <URLPattern list> (None:None) '^'>, <URLPattern '^users\.(?P<format>[a-z0-9]+)/?$' [name='users-list']>], [<URLResolver <URLPattern list> (None:None) '^'>, <URLPattern '^$' [name='api-root']>], [<URLResolver <URLPattern list> (None:None) '^'>, <URLPattern '^\.(?P<format>[a-z0-9]+)/?$' [name='api-root']>], [<URLPattern '^api-token-auth/'>], [<URLPattern '^login/'>]], 'path': 'users/22'}

During handling of the above exception, another exception occurred:

Traceback (most recent call last):
  File "/Users/cribbee/Virtualenv/V-ZoomIn/lib/python3.6/site-packages/django/template/base.py", line 835, in _resolve_lookup
    current = current[bit]
TypeError: 'URLResolver' object is not subscriptable

During handling of the above exception, another exception occurred:

Traceback (most recent call last):
  File "/Users/cribbee/Virtualenv/V-ZoomIn/lib/python3.6/site-packages/django/template/base.py", line 843, in _resolve_lookup
    current = getattr(current, bit)
AttributeError: 'URLResolver' object has no attribute 'name'

During handling of the above exception, another exception occurred:

Traceback (most recent call last):
  File "/Users/cribbee/Virtualenv/V-ZoomIn/lib/python3.6/site-packages/django/template/base.py", line 849, in _resolve_lookup
    current = current[int(bit)]
ValueError: invalid literal for int() with base 10: 'name'

During handling of the above exception, another exception occurred:

Traceback (most recent call last):
  File "/Users/cribbee/Virtualenv/V-ZoomIn/lib/python3.6/site-packages/django/template/base.py", line 856, in _resolve_lookup
    (bit, current))  # missing attribute
django.template.base.VariableDoesNotExist: Failed lookup for key [name] in <URLResolver <module 'tasks.urls' from '/Users/cribbee/PycharmProjects/ZoomInDev/apps/tasks/urls.py'> (None:None) '^task'>
Not Found: /users/22
"GET /users/22 HTTP/1.1" 404 3170
Exception while resolving variable 'name' in template 'unknown'.
Traceback (most recent call last):
  File "/Users/cribbee/Virtualenv/V-ZoomIn/lib/python3.6/site-packages/django/core/handlers/exception.py", line 35, in inner
    response = get_response(request)
  File "/Users/cribbee/Virtualenv/V-ZoomIn/lib/python3.6/site-packages/django/core/handlers/base.py", line 113, in _get_response
    resolver_match = resolver.resolve(request.path_info)
  File "/Users/cribbee/Virtualenv/V-ZoomIn/lib/python3.6/site-packages/django/urls/resolvers.py", line 523, in resolve
    raise Resolver404({'tried': tried, 'path': new_path})
django.urls.exceptions.Resolver404: {'tried': [[<URLPattern '^upload/(?P<path>.*)$'>], [<URLResolver <module 'rest_framework.urls' from '/Users/cribbee/Virtualenv/V-ZoomIn/lib/python3.6/site-packages/rest_framework/urls.py'> (rest_framework:rest_framework) '^api-auth/'>], [<URLResolver <module 'tasks.urls' from '/Users/cribbee/PycharmProjects/ZoomInDev/apps/tasks/urls.py'> (None:None) '^task'>], [<URLResolver <URLPattern list> (None:None) '^'>, <URLPattern '^users/$' [name='users-list']>], [<URLResolver <URLPattern list> (None:None) '^'>, <URLPattern '^users\.(?P<format>[a-z0-9]+)/?$' [name='users-list']>], [<URLResolver <URLPattern list> (None:None) '^'>, <URLPattern '^$' [name='api-root']>], [<URLResolver <URLPattern list> (None:None) '^'>, <URLPattern '^\.(?P<format>[a-z0-9]+)/?$' [name='api-root']>], [<URLPattern '^api-token-auth/'>], [<URLPattern '^login/'>]], 'path': 'users/admin2'}

During handling of the above exception, another exception occurred:

Traceback (most recent call last):
  File "/Users/cribbee/Virtualenv/V-ZoomIn/lib/python3.6/site-packages/django/template/base.py", line 835, in _resolve_lookup
    current = current[bit]
TypeError: 'URLResolver' object is not subscriptable

During handling of the above exception, another exception occurred:

Traceback (most recent call last):
  File "/Users/cribbee/Virtualenv/V-ZoomIn/lib/python3.6/site-packages/django/template/base.py", line 843, in _resolve_lookup
    current = getattr(current, bit)
AttributeError: 'URLResolver' object has no attribute 'name'

During handling of the above exception, another exception occurred:

Traceback (most recent call last):
  File "/Users/cribbee/Virtualenv/V-ZoomIn/lib/python3.6/site-packages/django/template/base.py", line 849, in _resolve_lookup
    current = current[int(bit)]
ValueError: invalid literal for int() with base 10: 'name'

During handling of the above exception, another exception occurred:

Traceback (most recent call last):
  File "/Users/cribbee/Virtualenv/V-ZoomIn/lib/python3.6/site-packages/django/template/base.py", line 856, in _resolve_lookup
    (bit, current))  # missing attribute
django.template.base.VariableDoesNotExist: Failed lookup for key [name] in <URLResolver <module 'rest_framework.urls' from '/Users/cribbee/Virtualenv/V-ZoomIn/lib/python3.6/site-packages/rest_framework/urls.py'> (rest_framework:rest_framework) '^api-auth/'>
Exception while resolving variable 'name' in template 'unknown'.
Traceback (most recent call last):
  File "/Users/cribbee/Virtualenv/V-ZoomIn/lib/python3.6/site-packages/django/core/handlers/exception.py", line 35, in inner
    response = get_response(request)
  File "/Users/cribbee/Virtualenv/V-ZoomIn/lib/python3.6/site-packages/django/core/handlers/base.py", line 113, in _get_response
    resolver_match = resolver.resolve(request.path_info)
  File "/Users/cribbee/Virtualenv/V-ZoomIn/lib/python3.6/site-packages/django/urls/resolvers.py", line 523, in resolve
    raise Resolver404({'tried': tried, 'path': new_path})
django.urls.exceptions.Resolver404: {'tried': [[<URLPattern '^upload/(?P<path>.*)$'>], [<URLResolver <module 'rest_framework.urls' from '/Users/cribbee/Virtualenv/V-ZoomIn/lib/python3.6/site-packages/rest_framework/urls.py'> (rest_framework:rest_framework) '^api-auth/'>], [<URLResolver <module 'tasks.urls' from '/Users/cribbee/PycharmProjects/ZoomInDev/apps/tasks/urls.py'> (None:None) '^task'>], [<URLResolver <URLPattern list> (None:None) '^'>, <URLPattern '^users/$' [name='users-list']>], [<URLResolver <URLPattern list> (None:None) '^'>, <URLPattern '^users\.(?P<format>[a-z0-9]+)/?$' [name='users-list']>], [<URLResolver <URLPattern list> (None:None) '^'>, <URLPattern '^$' [name='api-root']>], [<URLResolver <URLPattern list> (None:None) '^'>, <URLPattern '^\.(?P<format>[a-z0-9]+)/?$' [name='api-root']>], [<URLPattern '^api-token-auth/'>], [<URLPattern '^login/'>]], 'path': 'users/admin2'}

During handling of the above exception, another exception occurred:

Traceback (most recent call last):
  File "/Users/cribbee/Virtualenv/V-ZoomIn/lib/python3.6/site-packages/django/template/base.py", line 835, in _resolve_lookup
    current = current[bit]
TypeError: 'URLResolver' object is not subscriptable

During handling of the above exception, another exception occurred:

Traceback (most recent call last):
  File "/Users/cribbee/Virtualenv/V-ZoomIn/lib/python3.6/site-packages/django/template/base.py", line 843, in _resolve_lookup
    current = getattr(current, bit)
AttributeError: 'URLResolver' object has no attribute 'name'

During handling of the above exception, another exception occurred:

Traceback (most recent call last):
  File "/Users/cribbee/Virtualenv/V-ZoomIn/lib/python3.6/site-packages/django/template/base.py", line 849, in _resolve_lookup
    current = current[int(bit)]
ValueError: invalid literal for int() with base 10: 'name'

During handling of the above exception, another exception occurred:

Traceback (most recent call last):
  File "/Users/cribbee/Virtualenv/V-ZoomIn/lib/python3.6/site-packages/django/template/base.py", line 856, in _resolve_lookup
    (bit, current))  # missing attribute
django.template.base.VariableDoesNotExist: Failed lookup for key [name] in <URLResolver <module 'tasks.urls' from '/Users/cribbee/PycharmProjects/ZoomInDev/apps/tasks/urls.py'> (None:None) '^task'>
Not Found: /users/admin2
"GET /users/admin2 HTTP/1.1" 404 3182
Exception while resolving variable 'name' in template 'unknown'.
Traceback (most recent call last):
  File "/Users/cribbee/Virtualenv/V-ZoomIn/lib/python3.6/site-packages/django/core/handlers/exception.py", line 35, in inner
    response = get_response(request)
  File "/Users/cribbee/Virtualenv/V-ZoomIn/lib/python3.6/site-packages/django/core/handlers/base.py", line 113, in _get_response
    resolver_match = resolver.resolve(request.path_info)
  File "/Users/cribbee/Virtualenv/V-ZoomIn/lib/python3.6/site-packages/django/urls/resolvers.py", line 523, in resolve
    raise Resolver404({'tried': tried, 'path': new_path})
django.urls.exceptions.Resolver404: {'tried': [[<URLPattern '^upload/(?P<path>.*)$'>], [<URLResolver <module 'rest_framework.urls' from '/Users/cribbee/Virtualenv/V-ZoomIn/lib/python3.6/site-packages/rest_framework/urls.py'> (rest_framework:rest_framework) '^api-auth/'>], [<URLResolver <module 'tasks.urls' from '/Users/cribbee/PycharmProjects/ZoomInDev/apps/tasks/urls.py'> (None:None) '^task'>], [<URLResolver <URLPattern list> (None:None) '^'>, <URLPattern '^users/$' [name='users-list']>], [<URLResolver <URLPattern list> (None:None) '^'>, <URLPattern '^users\.(?P<format>[a-z0-9]+)/?$' [name='users-list']>], [<URLResolver <URLPattern list> (None:None) '^'>, <URLPattern '^$' [name='api-root']>], [<URLResolver <URLPattern list> (None:None) '^'>, <URLPattern '^\.(?P<format>[a-z0-9]+)/?$' [name='api-root']>], [<URLPattern '^api-token-auth/'>], [<URLPattern '^login/'>]], 'path': "users/name='admin2'"}

During handling of the above exception, another exception occurred:

Traceback (most recent call last):
  File "/Users/cribbee/Virtualenv/V-ZoomIn/lib/python3.6/site-packages/django/template/base.py", line 835, in _resolve_lookup
    current = current[bit]
TypeError: 'URLResolver' object is not subscriptable

During handling of the above exception, another exception occurred:

Traceback (most recent call last):
  File "/Users/cribbee/Virtualenv/V-ZoomIn/lib/python3.6/site-packages/django/template/base.py", line 843, in _resolve_lookup
    current = getattr(current, bit)
AttributeError: 'URLResolver' object has no attribute 'name'

During handling of the above exception, another exception occurred:

Traceback (most recent call last):
  File "/Users/cribbee/Virtualenv/V-ZoomIn/lib/python3.6/site-packages/django/template/base.py", line 849, in _resolve_lookup
    current = current[int(bit)]
ValueError: invalid literal for int() with base 10: 'name'

During handling of the above exception, another exception occurred:

Traceback (most recent call last):
  File "/Users/cribbee/Virtualenv/V-ZoomIn/lib/python3.6/site-packages/django/template/base.py", line 856, in _resolve_lookup
    (bit, current))  # missing attribute
django.template.base.VariableDoesNotExist: Failed lookup for key [name] in <URLResolver <module 'rest_framework.urls' from '/Users/cribbee/Virtualenv/V-ZoomIn/lib/python3.6/site-packages/rest_framework/urls.py'> (rest_framework:rest_framework) '^api-auth/'>
Exception while resolving variable 'name' in template 'unknown'.
Traceback (most recent call last):
  File "/Users/cribbee/Virtualenv/V-ZoomIn/lib/python3.6/site-packages/django/core/handlers/exception.py", line 35, in inner
    response = get_response(request)
  File "/Users/cribbee/Virtualenv/V-ZoomIn/lib/python3.6/site-packages/django/core/handlers/base.py", line 113, in _get_response
    resolver_match = resolver.resolve(request.path_info)
  File "/Users/cribbee/Virtualenv/V-ZoomIn/lib/python3.6/site-packages/django/urls/resolvers.py", line 523, in resolve
    raise Resolver404({'tried': tried, 'path': new_path})
django.urls.exceptions.Resolver404: {'tried': [[<URLPattern '^upload/(?P<path>.*)$'>], [<URLResolver <module 'rest_framework.urls' from '/Users/cribbee/Virtualenv/V-ZoomIn/lib/python3.6/site-packages/rest_framework/urls.py'> (rest_framework:rest_framework) '^api-auth/'>], [<URLResolver <module 'tasks.urls' from '/Users/cribbee/PycharmProjects/ZoomInDev/apps/tasks/urls.py'> (None:None) '^task'>], [<URLResolver <URLPattern list> (None:None) '^'>, <URLPattern '^users/$' [name='users-list']>], [<URLResolver <URLPattern list> (None:None) '^'>, <URLPattern '^users\.(?P<format>[a-z0-9]+)/?$' [name='users-list']>], [<URLResolver <URLPattern list> (None:None) '^'>, <URLPattern '^$' [name='api-root']>], [<URLResolver <URLPattern list> (None:None) '^'>, <URLPattern '^\.(?P<format>[a-z0-9]+)/?$' [name='api-root']>], [<URLPattern '^api-token-auth/'>], [<URLPattern '^login/'>]], 'path': "users/name='admin2'"}

During handling of the above exception, another exception occurred:

Traceback (most recent call last):
  File "/Users/cribbee/Virtualenv/V-ZoomIn/lib/python3.6/site-packages/django/template/base.py", line 835, in _resolve_lookup
    current = current[bit]
TypeError: 'URLResolver' object is not subscriptable

During handling of the above exception, another exception occurred:

Traceback (most recent call last):
  File "/Users/cribbee/Virtualenv/V-ZoomIn/lib/python3.6/site-packages/django/template/base.py", line 843, in _resolve_lookup
    current = getattr(current, bit)
AttributeError: 'URLResolver' object has no attribute 'name'

During handling of the above exception, another exception occurred:

Traceback (most recent call last):
  File "/Users/cribbee/Virtualenv/V-ZoomIn/lib/python3.6/site-packages/django/template/base.py", line 849, in _resolve_lookup
    current = current[int(bit)]
ValueError: invalid literal for int() with base 10: 'name'

During handling of the above exception, another exception occurred:

Traceback (most recent call last):
  File "/Users/cribbee/Virtualenv/V-ZoomIn/lib/python3.6/site-packages/django/template/base.py", line 856, in _resolve_lookup
    (bit, current))  # missing attribute
django.template.base.VariableDoesNotExist: Failed lookup for key [name] in <URLResolver <module 'tasks.urls' from '/Users/cribbee/PycharmProjects/ZoomInDev/apps/tasks/urls.py'> (None:None) '^task'>
Not Found: /users/name='admin2'
"GET /users/name='admin2' HTTP/1.1" 404 3229
Exception while resolving variable 'name' in template 'unknown'.
Traceback (most recent call last):
  File "/Users/cribbee/Virtualenv/V-ZoomIn/lib/python3.6/site-packages/django/core/handlers/exception.py", line 35, in inner
    response = get_response(request)
  File "/Users/cribbee/Virtualenv/V-ZoomIn/lib/python3.6/site-packages/django/core/handlers/base.py", line 113, in _get_response
    resolver_match = resolver.resolve(request.path_info)
  File "/Users/cribbee/Virtualenv/V-ZoomIn/lib/python3.6/site-packages/django/urls/resolvers.py", line 523, in resolve
    raise Resolver404({'tried': tried, 'path': new_path})
django.urls.exceptions.Resolver404: {'tried': [[<URLPattern '^upload/(?P<path>.*)$'>], [<URLResolver <module 'rest_framework.urls' from '/Users/cribbee/Virtualenv/V-ZoomIn/lib/python3.6/site-packages/rest_framework/urls.py'> (rest_framework:rest_framework) '^api-auth/'>], [<URLResolver <module 'tasks.urls' from '/Users/cribbee/PycharmProjects/ZoomInDev/apps/tasks/urls.py'> (None:None) '^task'>], [<URLResolver <URLPattern list> (None:None) '^'>, <URLPattern '^users/$' [name='users-list']>], [<URLResolver <URLPattern list> (None:None) '^'>, <URLPattern '^users\.(?P<format>[a-z0-9]+)/?$' [name='users-list']>], [<URLResolver <URLPattern list> (None:None) '^'>, <URLPattern '^$' [name='api-root']>], [<URLResolver <URLPattern list> (None:None) '^'>, <URLPattern '^\.(?P<format>[a-z0-9]+)/?$' [name='api-root']>], [<URLPattern '^api-token-auth/'>], [<URLPattern '^login/'>]], 'path': 'users/users-list'}

During handling of the above exception, another exception occurred:

Traceback (most recent call last):
  File "/Users/cribbee/Virtualenv/V-ZoomIn/lib/python3.6/site-packages/django/template/base.py", line 835, in _resolve_lookup
    current = current[bit]
TypeError: 'URLResolver' object is not subscriptable

During handling of the above exception, another exception occurred:

Traceback (most recent call last):
  File "/Users/cribbee/Virtualenv/V-ZoomIn/lib/python3.6/site-packages/django/template/base.py", line 843, in _resolve_lookup
    current = getattr(current, bit)
AttributeError: 'URLResolver' object has no attribute 'name'

During handling of the above exception, another exception occurred:

Traceback (most recent call last):
  File "/Users/cribbee/Virtualenv/V-ZoomIn/lib/python3.6/site-packages/django/template/base.py", line 849, in _resolve_lookup
    current = current[int(bit)]
ValueError: invalid literal for int() with base 10: 'name'

During handling of the above exception, another exception occurred:

Traceback (most recent call last):
  File "/Users/cribbee/Virtualenv/V-ZoomIn/lib/python3.6/site-packages/django/template/base.py", line 856, in _resolve_lookup
    (bit, current))  # missing attribute
django.template.base.VariableDoesNotExist: Failed lookup for key [name] in <URLResolver <module 'rest_framework.urls' from '/Users/cribbee/Virtualenv/V-ZoomIn/lib/python3.6/site-packages/rest_framework/urls.py'> (rest_framework:rest_framework) '^api-auth/'>
Exception while resolving variable 'name' in template 'unknown'.
Traceback (most recent call last):
  File "/Users/cribbee/Virtualenv/V-ZoomIn/lib/python3.6/site-packages/django/core/handlers/exception.py", line 35, in inner
    response = get_response(request)
  File "/Users/cribbee/Virtualenv/V-ZoomIn/lib/python3.6/site-packages/django/core/handlers/base.py", line 113, in _get_response
    resolver_match = resolver.resolve(request.path_info)
  File "/Users/cribbee/Virtualenv/V-ZoomIn/lib/python3.6/site-packages/django/urls/resolvers.py", line 523, in resolve
    raise Resolver404({'tried': tried, 'path': new_path})
django.urls.exceptions.Resolver404: {'tried': [[<URLPattern '^upload/(?P<path>.*)$'>], [<URLResolver <module 'rest_framework.urls' from '/Users/cribbee/Virtualenv/V-ZoomIn/lib/python3.6/site-packages/rest_framework/urls.py'> (rest_framework:rest_framework) '^api-auth/'>], [<URLResolver <module 'tasks.urls' from '/Users/cribbee/PycharmProjects/ZoomInDev/apps/tasks/urls.py'> (None:None) '^task'>], [<URLResolver <URLPattern list> (None:None) '^'>, <URLPattern '^users/$' [name='users-list']>], [<URLResolver <URLPattern list> (None:None) '^'>, <URLPattern '^users\.(?P<format>[a-z0-9]+)/?$' [name='users-list']>], [<URLResolver <URLPattern list> (None:None) '^'>, <URLPattern '^$' [name='api-root']>], [<URLResolver <URLPattern list> (None:None) '^'>, <URLPattern '^\.(?P<format>[a-z0-9]+)/?$' [name='api-root']>], [<URLPattern '^api-token-auth/'>], [<URLPattern '^login/'>]], 'path': 'users/users-list'}

During handling of the above exception, another exception occurred:

Traceback (most recent call last):
  File "/Users/cribbee/Virtualenv/V-ZoomIn/lib/python3.6/site-packages/django/template/base.py", line 835, in _resolve_lookup
    current = current[bit]
TypeError: 'URLResolver' object is not subscriptable

During handling of the above exception, another exception occurred:

Traceback (most recent call last):
  File "/Users/cribbee/Virtualenv/V-ZoomIn/lib/python3.6/site-packages/django/template/base.py", line 843, in _resolve_lookup
    current = getattr(current, bit)
AttributeError: 'URLResolver' object has no attribute 'name'

During handling of the above exception, another exception occurred:

Traceback (most recent call last):
  File "/Users/cribbee/Virtualenv/V-ZoomIn/lib/python3.6/site-packages/django/template/base.py", line 849, in _resolve_lookup
    current = current[int(bit)]
ValueError: invalid literal for int() with base 10: 'name'

During handling of the above exception, another exception occurred:

Traceback (most recent call last):
  File "/Users/cribbee/Virtualenv/V-ZoomIn/lib/python3.6/site-packages/django/template/base.py", line 856, in _resolve_lookup
    (bit, current))  # missing attribute
django.template.base.VariableDoesNotExist: Failed lookup for key [name] in <URLResolver <module 'tasks.urls' from '/Users/cribbee/PycharmProjects/ZoomInDev/apps/tasks/urls.py'> (None:None) '^task'>
Not Found: /users/users-list
"GET /users/users-list HTTP/1.1" 404 3194
(0.000) SELECT @@SQL_AUTO_IS_NULL; args=None
(0.000) SET SESSION TRANSACTION ISOLATION LEVEL READ COMMITTED; args=None
(0.000) SELECT VERSION(); args=None
(0.000) SET SESSION TRANSACTION ISOLATION LEVEL READ COMMITTED; args=None
(0.012) SHOW FULL TABLES; args=None
(0.001) SELECT `django_migrations`.`app`, `django_migrations`.`name` FROM `django_migrations`; args=()
(0.000) SELECT @@SQL_AUTO_IS_NULL; args=None
(0.000) SET SESSION TRANSACTION ISOLATION LEVEL READ COMMITTED; args=None
(0.001) SELECT @@sql_mode; args=None
(0.000) SELECT VERSION(); args=None
(0.001) SHOW FULL TABLES; args=None
(0.002) SELECT `django_migrations`.`app`, `django_migrations`.`name` FROM `django_migrations`; args=()
(0.002) SHOW FULL TABLES; args=None
(0.000) SELECT `django_migrations`.`app`, `django_migrations`.`name` FROM `django_migrations`; args=()
(0.001) SHOW FULL TABLES; args=None
CREATE TABLE `authtoken_token` (`key` varchar(40) NOT NULL PRIMARY KEY, `created` datetime(6) NOT NULL, `user_id` integer NOT NULL UNIQUE); (params None)
(0.105) CREATE TABLE `authtoken_token` (`key` varchar(40) NOT NULL PRIMARY KEY, `created` datetime(6) NOT NULL, `user_id` integer NOT NULL UNIQUE); args=None
(0.008) SELECT engine FROM information_schema.tables WHERE table_name = 'authtoken_token'; args=['authtoken_token']
(0.001) SELECT engine FROM information_schema.tables WHERE table_name = 'authtoken_token'; args=['authtoken_token']
(0.001) SELECT engine FROM information_schema.tables WHERE table_name = 'authtoken_token'; args=['authtoken_token']
ALTER TABLE `authtoken_token` ADD CONSTRAINT `authtoken_token_user_id_35299eff_fk_users_userprofile_id` FOREIGN KEY (`user_id`) REFERENCES `users_userprofile` (`id`); (params ())
(0.045) ALTER TABLE `authtoken_token` ADD CONSTRAINT `authtoken_token_user_id_35299eff_fk_users_userprofile_id` FOREIGN KEY (`user_id`) REFERENCES `users_userprofile` (`id`); args=()
(0.001) SHOW FULL TABLES; args=None
(0.005) INSERT INTO `django_migrations` (`app`, `name`, `applied`) VALUES ('authtoken', '0001_initial', '2018-06-05 13:21:07.226932'); args=['authtoken', '0001_initial', '2018-06-05 13:21:07.226932']
(0.004) 
            SELECT kc.`constraint_name`, kc.`column_name`,
                kc.`referenced_table_name`, kc.`referenced_column_name`
            FROM information_schema.key_column_usage AS kc
            WHERE
                kc.table_schema = DATABASE() AND
                kc.table_name = 'authtoken_token'
        ; args=['authtoken_token']
(0.002) 
            SELECT c.constraint_name, c.constraint_type
            FROM information_schema.table_constraints AS c
            WHERE
                c.table_schema = DATABASE() AND
                c.table_name = 'authtoken_token'
        ; args=['authtoken_token']
(0.001) SHOW INDEX FROM `authtoken_token`; args=None
ALTER TABLE `authtoken_token` DROP FOREIGN KEY `authtoken_token_user_id_35299eff_fk_users_userprofile_id`; (params ())
(0.011) ALTER TABLE `authtoken_token` DROP FOREIGN KEY `authtoken_token_user_id_35299eff_fk_users_userprofile_id`; args=()
ALTER TABLE `authtoken_token` ADD CONSTRAINT `authtoken_token_user_id_35299eff_fk_users_userprofile_id` FOREIGN KEY (`user_id`) REFERENCES `users_userprofile` (`id`); (params ())
(0.020) ALTER TABLE `authtoken_token` ADD CONSTRAINT `authtoken_token_user_id_35299eff_fk_users_userprofile_id` FOREIGN KEY (`user_id`) REFERENCES `users_userprofile` (`id`); args=()
(0.002) SHOW FULL TABLES; args=None
(0.000) INSERT INTO `django_migrations` (`app`, `name`, `applied`) VALUES ('authtoken', '0002_auto_20160226_1747', '2018-06-05 13:21:07.329798'); args=['authtoken', '0002_auto_20160226_1747', '2018-06-05 13:21:07.329798']
CREATE TABLE `user_operation_usertask` (`id` integer AUTO_INCREMENT NOT NULL PRIMARY KEY, `add_time` datetime(6) NOT NULL, `tasks_id` integer NOT NULL, `user_id` integer NOT NULL); (params None)
(0.010) CREATE TABLE `user_operation_usertask` (`id` integer AUTO_INCREMENT NOT NULL PRIMARY KEY, `add_time` datetime(6) NOT NULL, `tasks_id` integer NOT NULL, `user_id` integer NOT NULL); args=None
(0.005) SELECT engine FROM information_schema.tables WHERE table_name = 'user_operation_usertask'; args=['user_operation_usertask']
(0.001) SELECT engine FROM information_schema.tables WHERE table_name = 'user_operation_usertask'; args=['user_operation_usertask']
(0.000) SELECT engine FROM information_schema.tables WHERE table_name = 'user_operation_usertask'; args=['user_operation_usertask']
(0.000) SELECT engine FROM information_schema.tables WHERE table_name = 'user_operation_usertask'; args=['user_operation_usertask']
ALTER TABLE `user_operation_usertask` ADD CONSTRAINT user_operation_usertask_user_id_tasks_id_fefa885d_uniq UNIQUE (`user_id`, `tasks_id`); (params ())
(0.012) ALTER TABLE `user_operation_usertask` ADD CONSTRAINT user_operation_usertask_user_id_tasks_id_fefa885d_uniq UNIQUE (`user_id`, `tasks_id`); args=()
ALTER TABLE `user_operation_usertask` ADD CONSTRAINT `user_operation_usertask_tasks_id_ee2c4363_fk_tasks_taskinfo_id` FOREIGN KEY (`tasks_id`) REFERENCES `tasks_taskinfo` (`id`); (params ())
(0.020) ALTER TABLE `user_operation_usertask` ADD CONSTRAINT `user_operation_usertask_tasks_id_ee2c4363_fk_tasks_taskinfo_id` FOREIGN KEY (`tasks_id`) REFERENCES `tasks_taskinfo` (`id`); args=()
ALTER TABLE `user_operation_usertask` ADD CONSTRAINT `user_operation_usertask_user_id_8385090a_fk_users_userprofile_id` FOREIGN KEY (`user_id`) REFERENCES `users_userprofile` (`id`); (params ())
(0.025) ALTER TABLE `user_operation_usertask` ADD CONSTRAINT `user_operation_usertask_user_id_8385090a_fk_users_userprofile_id` FOREIGN KEY (`user_id`) REFERENCES `users_userprofile` (`id`); args=()
(0.001) SHOW FULL TABLES; args=None
(0.000) INSERT INTO `django_migrations` (`app`, `name`, `applied`) VALUES ('user_operation', '0001_initial', '2018-06-05 13:21:07.428178'); args=['user_operation', '0001_initial', '2018-06-05 13:21:07.428178']
(0.001) SHOW FULL TABLES; args=None
(0.000) SELECT `django_migrations`.`app`, `django_migrations`.`name` FROM `django_migrations`; args=()
(0.002) SELECT `django_content_type`.`id`, `django_content_type`.`app_label`, `django_content_type`.`model` FROM `django_content_type` WHERE (`django_content_type`.`app_label` = 'auth' AND `django_content_type`.`model` = 'permission'); args=('auth', 'permission')
(0.001) SELECT `django_content_type`.`id`, `django_content_type`.`app_label`, `django_content_type`.`model` FROM `django_content_type` WHERE (`django_content_type`.`app_label` = 'auth' AND `django_content_type`.`model` = 'group'); args=('auth', 'group')
(0.006) SELECT `auth_permission`.`content_type_id`, `auth_permission`.`codename` FROM `auth_permission` INNER JOIN `django_content_type` ON (`auth_permission`.`content_type_id` = `django_content_type`.`id`) WHERE `auth_permission`.`content_type_id` IN (1, 2) ORDER BY `django_content_type`.`app_label` ASC, `django_content_type`.`model` ASC, `auth_permission`.`codename` ASC; args=(1, 2)
(0.000) SELECT `django_content_type`.`id`, `django_content_type`.`app_label`, `django_content_type`.`model` FROM `django_content_type` WHERE `django_content_type`.`app_label` = 'auth'; args=('auth',)
(0.000) SELECT `django_content_type`.`id`, `django_content_type`.`app_label`, `django_content_type`.`model` FROM `django_content_type` WHERE (`django_content_type`.`app_label` = 'contenttypes' AND `django_content_type`.`model` = 'contenttype'); args=('contenttypes', 'contenttype')
(0.001) SELECT `auth_permission`.`content_type_id`, `auth_permission`.`codename` FROM `auth_permission` INNER JOIN `django_content_type` ON (`auth_permission`.`content_type_id` = `django_content_type`.`id`) WHERE `auth_permission`.`content_type_id` IN (3) ORDER BY `django_content_type`.`app_label` ASC, `django_content_type`.`model` ASC, `auth_permission`.`codename` ASC; args=(3,)
(0.000) SELECT `django_content_type`.`id`, `django_content_type`.`app_label`, `django_content_type`.`model` FROM `django_content_type` WHERE `django_content_type`.`app_label` = 'contenttypes'; args=('contenttypes',)
(0.000) SELECT `django_content_type`.`id`, `django_content_type`.`app_label`, `django_content_type`.`model` FROM `django_content_type` WHERE (`django_content_type`.`app_label` = 'sessions' AND `django_content_type`.`model` = 'session'); args=('sessions', 'session')
(0.000) SELECT `auth_permission`.`content_type_id`, `auth_permission`.`codename` FROM `auth_permission` INNER JOIN `django_content_type` ON (`auth_permission`.`content_type_id` = `django_content_type`.`id`) WHERE `auth_permission`.`content_type_id` IN (6) ORDER BY `django_content_type`.`app_label` ASC, `django_content_type`.`model` ASC, `auth_permission`.`codename` ASC; args=(6,)
(0.000) SELECT `django_content_type`.`id`, `django_content_type`.`app_label`, `django_content_type`.`model` FROM `django_content_type` WHERE `django_content_type`.`app_label` = 'sessions'; args=('sessions',)
(0.000) SELECT `django_content_type`.`id`, `django_content_type`.`app_label`, `django_content_type`.`model` FROM `django_content_type` WHERE `django_content_type`.`app_label` = 'corsheaders'; args=('corsheaders',)
(0.000) SELECT `django_content_type`.`id`, `django_content_type`.`app_label`, `django_content_type`.`model` FROM `django_content_type` WHERE `django_content_type`.`app_label` = 'rest_framework'; args=('rest_framework',)
(0.000) SELECT `django_content_type`.`id`, `django_content_type`.`app_label`, `django_content_type`.`model` FROM `django_content_type` WHERE (`django_content_type`.`app_label` = 'authtoken' AND `django_content_type`.`model` = 'token'); args=('authtoken', 'token')
(0.000) SELECT `django_content_type`.`id`, `django_content_type`.`app_label`, `django_content_type`.`model` FROM `django_content_type` WHERE (`django_content_type`.`app_label` = 'authtoken' AND `django_content_type`.`model` = 'token'); args=('authtoken', 'token')
(0.000) INSERT INTO `django_content_type` (`app_label`, `model`) VALUES ('authtoken', 'token'); args=['authtoken', 'token']
(0.000) SELECT `auth_permission`.`content_type_id`, `auth_permission`.`codename` FROM `auth_permission` INNER JOIN `django_content_type` ON (`auth_permission`.`content_type_id` = `django_content_type`.`id`) WHERE `auth_permission`.`content_type_id` IN (11) ORDER BY `django_content_type`.`app_label` ASC, `django_content_type`.`model` ASC, `auth_permission`.`codename` ASC; args=(11,)
(0.000) INSERT INTO `auth_permission` (`name`, `content_type_id`, `codename`) VALUES ('Can add Token', 11, 'add_token'), ('Can change Token', 11, 'change_token'), ('Can delete Token', 11, 'delete_token'); args=('Can add Token', 11, 'add_token', 'Can change Token', 11, 'change_token', 'Can delete Token', 11, 'delete_token')
(0.000) SELECT `django_content_type`.`id`, `django_content_type`.`app_label`, `django_content_type`.`model` FROM `django_content_type` WHERE `django_content_type`.`app_label` = 'authtoken'; args=('authtoken',)
(0.000) SELECT `django_content_type`.`id`, `django_content_type`.`app_label`, `django_content_type`.`model` FROM `django_content_type` WHERE `django_content_type`.`app_label` = 'django_filters'; args=('django_filters',)
(0.000) SELECT `django_content_type`.`id`, `django_content_type`.`app_label`, `django_content_type`.`model` FROM `django_content_type` WHERE (`django_content_type`.`app_label` = 'guardian' AND `django_content_type`.`model` = 'groupobjectpermission'); args=('guardian', 'groupobjectpermission')
(0.000) SELECT `django_content_type`.`id`, `django_content_type`.`app_label`, `django_content_type`.`model` FROM `django_content_type` WHERE (`django_content_type`.`app_label` = 'guardian' AND `django_content_type`.`model` = 'userobjectpermission'); args=('guardian', 'userobjectpermission')
(0.000) SELECT `auth_permission`.`content_type_id`, `auth_permission`.`codename` FROM `auth_permission` INNER JOIN `django_content_type` ON (`auth_permission`.`content_type_id` = `django_content_type`.`id`) WHERE `auth_permission`.`content_type_id` IN (8, 7) ORDER BY `django_content_type`.`app_label` ASC, `django_content_type`.`model` ASC, `auth_permission`.`codename` ASC; args=(8, 7)
(0.000) SELECT `django_content_type`.`id`, `django_content_type`.`app_label`, `django_content_type`.`model` FROM `django_content_type` WHERE `django_content_type`.`app_label` = 'guardian'; args=('guardian',)
(0.000) SELECT `users_userprofile`.`id`, `users_userprofile`.`password`, `users_userprofile`.`last_login`, `users_userprofile`.`is_superuser`, `users_userprofile`.`username`, `users_userprofile`.`first_name`, `users_userprofile`.`last_name`, `users_userprofile`.`is_staff`, `users_userprofile`.`is_active`, `users_userprofile`.`date_joined`, `users_userprofile`.`name`, `users_userprofile`.`birthday`, `users_userprofile`.`mobile`, `users_userprofile`.`gender`, `users_userprofile`.`email`, `users_userprofile`.`task_num` FROM `users_userprofile` WHERE `users_userprofile`.`username` = 'AnonymousUser'; args=('AnonymousUser',)
(0.000) SELECT `django_content_type`.`id`, `django_content_type`.`app_label`, `django_content_type`.`model` FROM `django_content_type` WHERE `django_content_type`.`app_label` = 'DjangoUeditor'; args=('DjangoUeditor',)
(0.000) SELECT `django_content_type`.`id`, `django_content_type`.`app_label`, `django_content_type`.`model` FROM `django_content_type` WHERE (`django_content_type`.`app_label` = 'users' AND `django_content_type`.`model` = 'userprofile'); args=('users', 'userprofile')
(0.000) SELECT `django_content_type`.`id`, `django_content_type`.`app_label`, `django_content_type`.`model` FROM `django_content_type` WHERE (`django_content_type`.`app_label` = 'users' AND `django_content_type`.`model` = 'verifycode'); args=('users', 'verifycode')
(0.000) SELECT `auth_permission`.`content_type_id`, `auth_permission`.`codename` FROM `auth_permission` INNER JOIN `django_content_type` ON (`auth_permission`.`content_type_id` = `django_content_type`.`id`) WHERE `auth_permission`.`content_type_id` IN (4, 5) ORDER BY `django_content_type`.`app_label` ASC, `django_content_type`.`model` ASC, `auth_permission`.`codename` ASC; args=(4, 5)
(0.000) SELECT `django_content_type`.`id`, `django_content_type`.`app_label`, `django_content_type`.`model` FROM `django_content_type` WHERE `django_content_type`.`app_label` = 'users'; args=('users',)
(0.000) SELECT `django_content_type`.`id`, `django_content_type`.`app_label`, `django_content_type`.`model` FROM `django_content_type` WHERE (`django_content_type`.`app_label` = 'tasks' AND `django_content_type`.`model` = 'dataset'); args=('tasks', 'dataset')
(0.000) SELECT `django_content_type`.`id`, `django_content_type`.`app_label`, `django_content_type`.`model` FROM `django_content_type` WHERE (`django_content_type`.`app_label` = 'tasks' AND `django_content_type`.`model` = 'taskinfo'); args=('tasks', 'taskinfo')
(0.000) SELECT `auth_permission`.`content_type_id`, `auth_permission`.`codename` FROM `auth_permission` INNER JOIN `django_content_type` ON (`auth_permission`.`content_type_id` = `django_content_type`.`id`) WHERE `auth_permission`.`content_type_id` IN (9, 10) ORDER BY `django_content_type`.`app_label` ASC, `django_content_type`.`model` ASC, `auth_permission`.`codename` ASC; args=(9, 10)
(0.000) SELECT `django_content_type`.`id`, `django_content_type`.`app_label`, `django_content_type`.`model` FROM `django_content_type` WHERE `django_content_type`.`app_label` = 'tasks'; args=('tasks',)
(0.000) SELECT `django_content_type`.`id`, `django_content_type`.`app_label`, `django_content_type`.`model` FROM `django_content_type` WHERE (`django_content_type`.`app_label` = 'user_operation' AND `django_content_type`.`model` = 'usertask'); args=('user_operation', 'usertask')
(0.000) SELECT `django_content_type`.`id`, `django_content_type`.`app_label`, `django_content_type`.`model` FROM `django_content_type` WHERE (`django_content_type`.`app_label` = 'user_operation' AND `django_content_type`.`model` = 'usertask'); args=('user_operation', 'usertask')
(0.001) INSERT INTO `django_content_type` (`app_label`, `model`) VALUES ('user_operation', 'usertask'); args=['user_operation', 'usertask']
(0.000) SELECT `auth_permission`.`content_type_id`, `auth_permission`.`codename` FROM `auth_permission` INNER JOIN `django_content_type` ON (`auth_permission`.`content_type_id` = `django_content_type`.`id`) WHERE `auth_permission`.`content_type_id` IN (12) ORDER BY `django_content_type`.`app_label` ASC, `django_content_type`.`model` ASC, `auth_permission`.`codename` ASC; args=(12,)
(0.000) SELECT `django_content_type`.`id`, `django_content_type`.`app_label`, `django_content_type`.`model` FROM `django_content_type` WHERE `django_content_type`.`app_label` = 'user_operation'; args=('user_operation',)
(0.000) SELECT @@SQL_AUTO_IS_NULL; args=None
(0.000) SET SESSION TRANSACTION ISOLATION LEVEL READ COMMITTED; args=None
(0.000) SELECT VERSION(); args=None
(0.001) SET SESSION TRANSACTION ISOLATION LEVEL READ COMMITTED; args=None
(0.006) SHOW FULL TABLES; args=None
(0.001) SELECT `django_migrations`.`app`, `django_migrations`.`name` FROM `django_migrations`; args=()
"GET / HTTP/1.1" 200 5224
(0.000) SELECT @@SQL_AUTO_IS_NULL; args=None
(0.000) SET SESSION TRANSACTION ISOLATION LEVEL READ COMMITTED; args=None
(0.000) SELECT VERSION(); args=None
(0.000) SET SESSION TRANSACTION ISOLATION LEVEL READ COMMITTED; args=None
(0.006) SHOW FULL TABLES; args=None
(0.002) SELECT `django_migrations`.`app`, `django_migrations`.`name` FROM `django_migrations`; args=()
"GET / HTTP/1.1" 200 5356
(0.000) SELECT @@SQL_AUTO_IS_NULL; args=None
(0.000) SET SESSION TRANSACTION ISOLATION LEVEL READ COMMITTED; args=None
(0.001) SELECT `user_operation_usertask`.`id`, `user_operation_usertask`.`user_id`, `user_operation_usertask`.`tasks_id`, `user_operation_usertask`.`add_time` FROM `user_operation_usertask`; args=()
Exception while resolving variable 'hide_label' in template 'rest_framework/horizontal/select.html'.
Traceback (most recent call last):
  File "/Users/cribbee/Virtualenv/V-ZoomIn/lib/python3.6/site-packages/django/template/base.py", line 835, in _resolve_lookup
    current = current[bit]
KeyError: 'hide_label'

During handling of the above exception, another exception occurred:

Traceback (most recent call last):
  File "/Users/cribbee/Virtualenv/V-ZoomIn/lib/python3.6/site-packages/django/template/base.py", line 843, in _resolve_lookup
    current = getattr(current, bit)
AttributeError: 'dict' object has no attribute 'hide_label'

During handling of the above exception, another exception occurred:

Traceback (most recent call last):
  File "/Users/cribbee/Virtualenv/V-ZoomIn/lib/python3.6/site-packages/django/template/base.py", line 849, in _resolve_lookup
    current = current[int(bit)]
ValueError: invalid literal for int() with base 10: 'hide_label'

During handling of the above exception, another exception occurred:

Traceback (most recent call last):
  File "/Users/cribbee/Virtualenv/V-ZoomIn/lib/python3.6/site-packages/django/template/base.py", line 856, in _resolve_lookup
    (bit, current))  # missing attribute
django.template.base.VariableDoesNotExist: Failed lookup for key [hide_label] in {'base_template': 'select.html', 'template_pack': 'rest_framework/horizontal', 'renderer': <rest_framework.renderers.HTMLFormRenderer object at 0x105d60080>}
Exception while resolving variable 'allow_blank' in template 'rest_framework/horizontal/select.html'.
Traceback (most recent call last):
  File "/Users/cribbee/Virtualenv/V-ZoomIn/lib/python3.6/site-packages/django/template/base.py", line 835, in _resolve_lookup
    current = current[bit]
TypeError: 'BoundField' object is not subscriptable

During handling of the above exception, another exception occurred:

Traceback (most recent call last):
  File "/Users/cribbee/Virtualenv/V-ZoomIn/lib/python3.6/site-packages/django/template/base.py", line 843, in _resolve_lookup
    current = getattr(current, bit)
  File "/Users/cribbee/Virtualenv/V-ZoomIn/lib/python3.6/site-packages/rest_framework/utils/serializer_helpers.py", line 70, in __getattr__
    return getattr(self._field, attr_name)
AttributeError: 'PrimaryKeyRelatedField' object has no attribute 'allow_blank'

During handling of the above exception, another exception occurred:

Traceback (most recent call last):
  File "/Users/cribbee/Virtualenv/V-ZoomIn/lib/python3.6/site-packages/django/template/base.py", line 849, in _resolve_lookup
    current = current[int(bit)]
ValueError: invalid literal for int() with base 10: 'allow_blank'

During handling of the above exception, another exception occurred:

Traceback (most recent call last):
  File "/Users/cribbee/Virtualenv/V-ZoomIn/lib/python3.6/site-packages/django/template/base.py", line 856, in _resolve_lookup
    (bit, current))  # missing attribute
django.template.base.VariableDoesNotExist: Failed lookup for key [allow_blank] in <BoundField value= errors=None>
(0.008) SELECT `tasks_taskinfo`.`id`, `tasks_taskinfo`.`user_id`, `tasks_taskinfo`.`task_name`, `tasks_taskinfo`.`data_num`, `tasks_taskinfo`.`state_type`, `tasks_taskinfo`.`add_time` FROM `tasks_taskinfo` LIMIT 1000; args=()
"GET /usertask/ HTTP/1.1" 200 8605
(0.000) SELECT @@SQL_AUTO_IS_NULL; args=None
(0.000) SET SESSION TRANSACTION ISOLATION LEVEL READ COMMITTED; args=None
(0.000) SELECT VERSION(); args=None
(0.000) SET SESSION TRANSACTION ISOLATION LEVEL READ COMMITTED; args=None
(0.011) SHOW FULL TABLES; args=None
(0.004) SELECT `django_migrations`.`app`, `django_migrations`.`name` FROM `django_migrations`; args=()
"GET / HTTP/1.1" 200 5356
"GET /usertask/ HTTP/1.1" 401 5221
"GET /usertask/ HTTP/1.1" 401 5221
Exception while resolving variable 'hide_label' in template 'rest_framework/horizontal/input.html'.
Traceback (most recent call last):
  File "/Users/cribbee/Virtualenv/V-ZoomIn/lib/python3.6/site-packages/django/template/base.py", line 835, in _resolve_lookup
    current = current[bit]
KeyError: 'hide_label'

During handling of the above exception, another exception occurred:

Traceback (most recent call last):
  File "/Users/cribbee/Virtualenv/V-ZoomIn/lib/python3.6/site-packages/django/template/base.py", line 843, in _resolve_lookup
    current = getattr(current, bit)
AttributeError: 'dict' object has no attribute 'hide_label'

During handling of the above exception, another exception occurred:

Traceback (most recent call last):
  File "/Users/cribbee/Virtualenv/V-ZoomIn/lib/python3.6/site-packages/django/template/base.py", line 849, in _resolve_lookup
    current = current[int(bit)]
ValueError: invalid literal for int() with base 10: 'hide_label'

During handling of the above exception, another exception occurred:

Traceback (most recent call last):
  File "/Users/cribbee/Virtualenv/V-ZoomIn/lib/python3.6/site-packages/django/template/base.py", line 856, in _resolve_lookup
    (bit, current))  # missing attribute
django.template.base.VariableDoesNotExist: Failed lookup for key [hide_label] in {'base_template': 'input.html', 'input_type': 'text', 'template_pack': 'rest_framework/horizontal', 'renderer': <rest_framework.renderers.HTMLFormRenderer object at 0x10d47e940>}
Exception while resolving variable 'placeholder' in template 'rest_framework/horizontal/input.html'.
Traceback (most recent call last):
  File "/Users/cribbee/Virtualenv/V-ZoomIn/lib/python3.6/site-packages/django/template/base.py", line 835, in _resolve_lookup
    current = current[bit]
KeyError: 'placeholder'

During handling of the above exception, another exception occurred:

Traceback (most recent call last):
  File "/Users/cribbee/Virtualenv/V-ZoomIn/lib/python3.6/site-packages/django/template/base.py", line 843, in _resolve_lookup
    current = getattr(current, bit)
AttributeError: 'dict' object has no attribute 'placeholder'

During handling of the above exception, another exception occurred:

Traceback (most recent call last):
  File "/Users/cribbee/Virtualenv/V-ZoomIn/lib/python3.6/site-packages/django/template/base.py", line 849, in _resolve_lookup
    current = current[int(bit)]
ValueError: invalid literal for int() with base 10: 'placeholder'

During handling of the above exception, another exception occurred:

Traceback (most recent call last):
  File "/Users/cribbee/Virtualenv/V-ZoomIn/lib/python3.6/site-packages/django/template/base.py", line 856, in _resolve_lookup
    (bit, current))  # missing attribute
django.template.base.VariableDoesNotExist: Failed lookup for key [placeholder] in {'base_template': 'input.html', 'input_type': 'text', 'template_pack': 'rest_framework/horizontal', 'renderer': <rest_framework.renderers.HTMLFormRenderer object at 0x10d47e940>}
Exception while resolving variable 'autofocus' in template 'rest_framework/horizontal/input.html'.
Traceback (most recent call last):
  File "/Users/cribbee/Virtualenv/V-ZoomIn/lib/python3.6/site-packages/django/template/base.py", line 835, in _resolve_lookup
    current = current[bit]
KeyError: 'autofocus'

During handling of the above exception, another exception occurred:

Traceback (most recent call last):
  File "/Users/cribbee/Virtualenv/V-ZoomIn/lib/python3.6/site-packages/django/template/base.py", line 843, in _resolve_lookup
    current = getattr(current, bit)
AttributeError: 'dict' object has no attribute 'autofocus'

During handling of the above exception, another exception occurred:

Traceback (most recent call last):
  File "/Users/cribbee/Virtualenv/V-ZoomIn/lib/python3.6/site-packages/django/template/base.py", line 849, in _resolve_lookup
    current = current[int(bit)]
ValueError: invalid literal for int() with base 10: 'autofocus'

During handling of the above exception, another exception occurred:

Traceback (most recent call last):
  File "/Users/cribbee/Virtualenv/V-ZoomIn/lib/python3.6/site-packages/django/template/base.py", line 856, in _resolve_lookup
    (bit, current))  # missing attribute
django.template.base.VariableDoesNotExist: Failed lookup for key [autofocus] in {'base_template': 'input.html', 'input_type': 'text', 'template_pack': 'rest_framework/horizontal', 'renderer': <rest_framework.renderers.HTMLFormRenderer object at 0x10d47e940>}
Exception while resolving variable 'hide_label' in template 'rest_framework/horizontal/input.html'.
Traceback (most recent call last):
  File "/Users/cribbee/Virtualenv/V-ZoomIn/lib/python3.6/site-packages/django/template/base.py", line 835, in _resolve_lookup
    current = current[bit]
KeyError: 'hide_label'

During handling of the above exception, another exception occurred:

Traceback (most recent call last):
  File "/Users/cribbee/Virtualenv/V-ZoomIn/lib/python3.6/site-packages/django/template/base.py", line 843, in _resolve_lookup
    current = getattr(current, bit)
AttributeError: 'dict' object has no attribute 'hide_label'

During handling of the above exception, another exception occurred:

Traceback (most recent call last):
  File "/Users/cribbee/Virtualenv/V-ZoomIn/lib/python3.6/site-packages/django/template/base.py", line 849, in _resolve_lookup
    current = current[int(bit)]
ValueError: invalid literal for int() with base 10: 'hide_label'

During handling of the above exception, another exception occurred:

Traceback (most recent call last):
  File "/Users/cribbee/Virtualenv/V-ZoomIn/lib/python3.6/site-packages/django/template/base.py", line 856, in _resolve_lookup
    (bit, current))  # missing attribute
django.template.base.VariableDoesNotExist: Failed lookup for key [hide_label] in {'base_template': 'input.html', 'input_type': 'password', 'template_pack': 'rest_framework/horizontal', 'renderer': <rest_framework.renderers.HTMLFormRenderer object at 0x10d47e940>}
Exception while resolving variable 'placeholder' in template 'rest_framework/horizontal/input.html'.
Traceback (most recent call last):
  File "/Users/cribbee/Virtualenv/V-ZoomIn/lib/python3.6/site-packages/django/template/base.py", line 835, in _resolve_lookup
    current = current[bit]
KeyError: 'placeholder'

During handling of the above exception, another exception occurred:

Traceback (most recent call last):
  File "/Users/cribbee/Virtualenv/V-ZoomIn/lib/python3.6/site-packages/django/template/base.py", line 843, in _resolve_lookup
    current = getattr(current, bit)
AttributeError: 'dict' object has no attribute 'placeholder'

During handling of the above exception, another exception occurred:

Traceback (most recent call last):
  File "/Users/cribbee/Virtualenv/V-ZoomIn/lib/python3.6/site-packages/django/template/base.py", line 849, in _resolve_lookup
    current = current[int(bit)]
ValueError: invalid literal for int() with base 10: 'placeholder'

During handling of the above exception, another exception occurred:

Traceback (most recent call last):
  File "/Users/cribbee/Virtualenv/V-ZoomIn/lib/python3.6/site-packages/django/template/base.py", line 856, in _resolve_lookup
    (bit, current))  # missing attribute
django.template.base.VariableDoesNotExist: Failed lookup for key [placeholder] in {'base_template': 'input.html', 'input_type': 'password', 'template_pack': 'rest_framework/horizontal', 'renderer': <rest_framework.renderers.HTMLFormRenderer object at 0x10d47e940>}
Exception while resolving variable 'autofocus' in template 'rest_framework/horizontal/input.html'.
Traceback (most recent call last):
  File "/Users/cribbee/Virtualenv/V-ZoomIn/lib/python3.6/site-packages/django/template/base.py", line 835, in _resolve_lookup
    current = current[bit]
KeyError: 'autofocus'

During handling of the above exception, another exception occurred:

Traceback (most recent call last):
  File "/Users/cribbee/Virtualenv/V-ZoomIn/lib/python3.6/site-packages/django/template/base.py", line 843, in _resolve_lookup
    current = getattr(current, bit)
AttributeError: 'dict' object has no attribute 'autofocus'

During handling of the above exception, another exception occurred:

Traceback (most recent call last):
  File "/Users/cribbee/Virtualenv/V-ZoomIn/lib/python3.6/site-packages/django/template/base.py", line 849, in _resolve_lookup
    current = current[int(bit)]
ValueError: invalid literal for int() with base 10: 'autofocus'

During handling of the above exception, another exception occurred:

Traceback (most recent call last):
  File "/Users/cribbee/Virtualenv/V-ZoomIn/lib/python3.6/site-packages/django/template/base.py", line 856, in _resolve_lookup
    (bit, current))  # missing attribute
django.template.base.VariableDoesNotExist: Failed lookup for key [autofocus] in {'base_template': 'input.html', 'input_type': 'password', 'template_pack': 'rest_framework/horizontal', 'renderer': <rest_framework.renderers.HTMLFormRenderer object at 0x10d47e940>}
"GET /login/ HTTP/1.1" 405 7693
(0.000) SELECT @@SQL_AUTO_IS_NULL; args=None
(0.000) SET SESSION TRANSACTION ISOLATION LEVEL READ COMMITTED; args=None
(0.000) SELECT VERSION(); args=None
(0.000) SET SESSION TRANSACTION ISOLATION LEVEL READ COMMITTED; args=None
(0.003) SELECT `users_userprofile`.`id`, `users_userprofile`.`password`, `users_userprofile`.`last_login`, `users_userprofile`.`is_superuser`, `users_userprofile`.`username`, `users_userprofile`.`first_name`, `users_userprofile`.`last_name`, `users_userprofile`.`is_staff`, `users_userprofile`.`is_active`, `users_userprofile`.`date_joined`, `users_userprofile`.`name`, `users_userprofile`.`birthday`, `users_userprofile`.`mobile`, `users_userprofile`.`gender`, `users_userprofile`.`email`, `users_userprofile`.`task_num` FROM `users_userprofile` WHERE (`users_userprofile`.`username` = 'lxy' OR `users_userprofile`.`mobile` = 'lxy'); args=('lxy', 'lxy')
Exception while resolving variable 'hide_label' in template 'rest_framework/horizontal/input.html'.
Traceback (most recent call last):
  File "/Users/cribbee/Virtualenv/V-ZoomIn/lib/python3.6/site-packages/django/template/base.py", line 835, in _resolve_lookup
    current = current[bit]
KeyError: 'hide_label'

During handling of the above exception, another exception occurred:

Traceback (most recent call last):
  File "/Users/cribbee/Virtualenv/V-ZoomIn/lib/python3.6/site-packages/django/template/base.py", line 843, in _resolve_lookup
    current = getattr(current, bit)
AttributeError: 'dict' object has no attribute 'hide_label'

During handling of the above exception, another exception occurred:

Traceback (most recent call last):
  File "/Users/cribbee/Virtualenv/V-ZoomIn/lib/python3.6/site-packages/django/template/base.py", line 849, in _resolve_lookup
    current = current[int(bit)]
ValueError: invalid literal for int() with base 10: 'hide_label'

During handling of the above exception, another exception occurred:

Traceback (most recent call last):
  File "/Users/cribbee/Virtualenv/V-ZoomIn/lib/python3.6/site-packages/django/template/base.py", line 856, in _resolve_lookup
    (bit, current))  # missing attribute
django.template.base.VariableDoesNotExist: Failed lookup for key [hide_label] in {'base_template': 'input.html', 'input_type': 'text', 'template_pack': 'rest_framework/horizontal', 'renderer': <rest_framework.renderers.HTMLFormRenderer object at 0x10d3fbd30>}
Exception while resolving variable 'placeholder' in template 'rest_framework/horizontal/input.html'.
Traceback (most recent call last):
  File "/Users/cribbee/Virtualenv/V-ZoomIn/lib/python3.6/site-packages/django/template/base.py", line 835, in _resolve_lookup
    current = current[bit]
KeyError: 'placeholder'

During handling of the above exception, another exception occurred:

Traceback (most recent call last):
  File "/Users/cribbee/Virtualenv/V-ZoomIn/lib/python3.6/site-packages/django/template/base.py", line 843, in _resolve_lookup
    current = getattr(current, bit)
AttributeError: 'dict' object has no attribute 'placeholder'

During handling of the above exception, another exception occurred:

Traceback (most recent call last):
  File "/Users/cribbee/Virtualenv/V-ZoomIn/lib/python3.6/site-packages/django/template/base.py", line 849, in _resolve_lookup
    current = current[int(bit)]
ValueError: invalid literal for int() with base 10: 'placeholder'

During handling of the above exception, another exception occurred:

Traceback (most recent call last):
  File "/Users/cribbee/Virtualenv/V-ZoomIn/lib/python3.6/site-packages/django/template/base.py", line 856, in _resolve_lookup
    (bit, current))  # missing attribute
django.template.base.VariableDoesNotExist: Failed lookup for key [placeholder] in {'base_template': 'input.html', 'input_type': 'text', 'template_pack': 'rest_framework/horizontal', 'renderer': <rest_framework.renderers.HTMLFormRenderer object at 0x10d3fbd30>}
Exception while resolving variable 'autofocus' in template 'rest_framework/horizontal/input.html'.
Traceback (most recent call last):
  File "/Users/cribbee/Virtualenv/V-ZoomIn/lib/python3.6/site-packages/django/template/base.py", line 835, in _resolve_lookup
    current = current[bit]
KeyError: 'autofocus'

During handling of the above exception, another exception occurred:

Traceback (most recent call last):
  File "/Users/cribbee/Virtualenv/V-ZoomIn/lib/python3.6/site-packages/django/template/base.py", line 843, in _resolve_lookup
    current = getattr(current, bit)
AttributeError: 'dict' object has no attribute 'autofocus'

During handling of the above exception, another exception occurred:

Traceback (most recent call last):
  File "/Users/cribbee/Virtualenv/V-ZoomIn/lib/python3.6/site-packages/django/template/base.py", line 849, in _resolve_lookup
    current = current[int(bit)]
ValueError: invalid literal for int() with base 10: 'autofocus'

During handling of the above exception, another exception occurred:

Traceback (most recent call last):
  File "/Users/cribbee/Virtualenv/V-ZoomIn/lib/python3.6/site-packages/django/template/base.py", line 856, in _resolve_lookup
    (bit, current))  # missing attribute
django.template.base.VariableDoesNotExist: Failed lookup for key [autofocus] in {'base_template': 'input.html', 'input_type': 'text', 'template_pack': 'rest_framework/horizontal', 'renderer': <rest_framework.renderers.HTMLFormRenderer object at 0x10d3fbd30>}
Exception while resolving variable 'hide_label' in template 'rest_framework/horizontal/input.html'.
Traceback (most recent call last):
  File "/Users/cribbee/Virtualenv/V-ZoomIn/lib/python3.6/site-packages/django/template/base.py", line 835, in _resolve_lookup
    current = current[bit]
KeyError: 'hide_label'

During handling of the above exception, another exception occurred:

Traceback (most recent call last):
  File "/Users/cribbee/Virtualenv/V-ZoomIn/lib/python3.6/site-packages/django/template/base.py", line 843, in _resolve_lookup
    current = getattr(current, bit)
AttributeError: 'dict' object has no attribute 'hide_label'

During handling of the above exception, another exception occurred:

Traceback (most recent call last):
  File "/Users/cribbee/Virtualenv/V-ZoomIn/lib/python3.6/site-packages/django/template/base.py", line 849, in _resolve_lookup
    current = current[int(bit)]
ValueError: invalid literal for int() with base 10: 'hide_label'

During handling of the above exception, another exception occurred:

Traceback (most recent call last):
  File "/Users/cribbee/Virtualenv/V-ZoomIn/lib/python3.6/site-packages/django/template/base.py", line 856, in _resolve_lookup
    (bit, current))  # missing attribute
django.template.base.VariableDoesNotExist: Failed lookup for key [hide_label] in {'base_template': 'input.html', 'input_type': 'password', 'template_pack': 'rest_framework/horizontal', 'renderer': <rest_framework.renderers.HTMLFormRenderer object at 0x10d3fbd30>}
Exception while resolving variable 'placeholder' in template 'rest_framework/horizontal/input.html'.
Traceback (most recent call last):
  File "/Users/cribbee/Virtualenv/V-ZoomIn/lib/python3.6/site-packages/django/template/base.py", line 835, in _resolve_lookup
    current = current[bit]
KeyError: 'placeholder'

During handling of the above exception, another exception occurred:

Traceback (most recent call last):
  File "/Users/cribbee/Virtualenv/V-ZoomIn/lib/python3.6/site-packages/django/template/base.py", line 843, in _resolve_lookup
    current = getattr(current, bit)
AttributeError: 'dict' object has no attribute 'placeholder'

During handling of the above exception, another exception occurred:

Traceback (most recent call last):
  File "/Users/cribbee/Virtualenv/V-ZoomIn/lib/python3.6/site-packages/django/template/base.py", line 849, in _resolve_lookup
    current = current[int(bit)]
ValueError: invalid literal for int() with base 10: 'placeholder'

During handling of the above exception, another exception occurred:

Traceback (most recent call last):
  File "/Users/cribbee/Virtualenv/V-ZoomIn/lib/python3.6/site-packages/django/template/base.py", line 856, in _resolve_lookup
    (bit, current))  # missing attribute
django.template.base.VariableDoesNotExist: Failed lookup for key [placeholder] in {'base_template': 'input.html', 'input_type': 'password', 'template_pack': 'rest_framework/horizontal', 'renderer': <rest_framework.renderers.HTMLFormRenderer object at 0x10d3fbd30>}
Exception while resolving variable 'autofocus' in template 'rest_framework/horizontal/input.html'.
Traceback (most recent call last):
  File "/Users/cribbee/Virtualenv/V-ZoomIn/lib/python3.6/site-packages/django/template/base.py", line 835, in _resolve_lookup
    current = current[bit]
KeyError: 'autofocus'

During handling of the above exception, another exception occurred:

Traceback (most recent call last):
  File "/Users/cribbee/Virtualenv/V-ZoomIn/lib/python3.6/site-packages/django/template/base.py", line 843, in _resolve_lookup
    current = getattr(current, bit)
AttributeError: 'dict' object has no attribute 'autofocus'

During handling of the above exception, another exception occurred:

Traceback (most recent call last):
  File "/Users/cribbee/Virtualenv/V-ZoomIn/lib/python3.6/site-packages/django/template/base.py", line 849, in _resolve_lookup
    current = current[int(bit)]
ValueError: invalid literal for int() with base 10: 'autofocus'

During handling of the above exception, another exception occurred:

Traceback (most recent call last):
  File "/Users/cribbee/Virtualenv/V-ZoomIn/lib/python3.6/site-packages/django/template/base.py", line 856, in _resolve_lookup
    (bit, current))  # missing attribute
django.template.base.VariableDoesNotExist: Failed lookup for key [autofocus] in {'base_template': 'input.html', 'input_type': 'password', 'template_pack': 'rest_framework/horizontal', 'renderer': <rest_framework.renderers.HTMLFormRenderer object at 0x10d3fbd30>}
"POST /login/ HTTP/1.1" 400 7734
(0.000) SELECT @@SQL_AUTO_IS_NULL; args=None
(0.000) SET SESSION TRANSACTION ISOLATION LEVEL READ COMMITTED; args=None
(0.000) SELECT VERSION(); args=None
(0.000) SET SESSION TRANSACTION ISOLATION LEVEL READ COMMITTED; args=None
(0.001) SELECT `users_userprofile`.`id`, `users_userprofile`.`password`, `users_userprofile`.`last_login`, `users_userprofile`.`is_superuser`, `users_userprofile`.`username`, `users_userprofile`.`first_name`, `users_userprofile`.`last_name`, `users_userprofile`.`is_staff`, `users_userprofile`.`is_active`, `users_userprofile`.`date_joined`, `users_userprofile`.`name`, `users_userprofile`.`birthday`, `users_userprofile`.`mobile`, `users_userprofile`.`gender`, `users_userprofile`.`email`, `users_userprofile`.`task_num` FROM `users_userprofile` WHERE (`users_userprofile`.`username` = 'admin2' OR `users_userprofile`.`mobile` = 'admin2'); args=('admin2', 'admin2')
Exception while resolving variable 'hide_label' in template 'rest_framework/horizontal/input.html'.
Traceback (most recent call last):
  File "/Users/cribbee/Virtualenv/V-ZoomIn/lib/python3.6/site-packages/django/template/base.py", line 835, in _resolve_lookup
    current = current[bit]
KeyError: 'hide_label'

During handling of the above exception, another exception occurred:

Traceback (most recent call last):
  File "/Users/cribbee/Virtualenv/V-ZoomIn/lib/python3.6/site-packages/django/template/base.py", line 843, in _resolve_lookup
    current = getattr(current, bit)
AttributeError: 'dict' object has no attribute 'hide_label'

During handling of the above exception, another exception occurred:

Traceback (most recent call last):
  File "/Users/cribbee/Virtualenv/V-ZoomIn/lib/python3.6/site-packages/django/template/base.py", line 849, in _resolve_lookup
    current = current[int(bit)]
ValueError: invalid literal for int() with base 10: 'hide_label'

During handling of the above exception, another exception occurred:

Traceback (most recent call last):
  File "/Users/cribbee/Virtualenv/V-ZoomIn/lib/python3.6/site-packages/django/template/base.py", line 856, in _resolve_lookup
    (bit, current))  # missing attribute
django.template.base.VariableDoesNotExist: Failed lookup for key [hide_label] in {'base_template': 'input.html', 'input_type': 'text', 'template_pack': 'rest_framework/horizontal', 'renderer': <rest_framework.renderers.HTMLFormRenderer object at 0x10d45d3c8>}
Exception while resolving variable 'placeholder' in template 'rest_framework/horizontal/input.html'.
Traceback (most recent call last):
  File "/Users/cribbee/Virtualenv/V-ZoomIn/lib/python3.6/site-packages/django/template/base.py", line 835, in _resolve_lookup
    current = current[bit]
KeyError: 'placeholder'

During handling of the above exception, another exception occurred:

Traceback (most recent call last):
  File "/Users/cribbee/Virtualenv/V-ZoomIn/lib/python3.6/site-packages/django/template/base.py", line 843, in _resolve_lookup
    current = getattr(current, bit)
AttributeError: 'dict' object has no attribute 'placeholder'

During handling of the above exception, another exception occurred:

Traceback (most recent call last):
  File "/Users/cribbee/Virtualenv/V-ZoomIn/lib/python3.6/site-packages/django/template/base.py", line 849, in _resolve_lookup
    current = current[int(bit)]
ValueError: invalid literal for int() with base 10: 'placeholder'

During handling of the above exception, another exception occurred:

Traceback (most recent call last):
  File "/Users/cribbee/Virtualenv/V-ZoomIn/lib/python3.6/site-packages/django/template/base.py", line 856, in _resolve_lookup
    (bit, current))  # missing attribute
django.template.base.VariableDoesNotExist: Failed lookup for key [placeholder] in {'base_template': 'input.html', 'input_type': 'text', 'template_pack': 'rest_framework/horizontal', 'renderer': <rest_framework.renderers.HTMLFormRenderer object at 0x10d45d3c8>}
Exception while resolving variable 'autofocus' in template 'rest_framework/horizontal/input.html'.
Traceback (most recent call last):
  File "/Users/cribbee/Virtualenv/V-ZoomIn/lib/python3.6/site-packages/django/template/base.py", line 835, in _resolve_lookup
    current = current[bit]
KeyError: 'autofocus'

During handling of the above exception, another exception occurred:

Traceback (most recent call last):
  File "/Users/cribbee/Virtualenv/V-ZoomIn/lib/python3.6/site-packages/django/template/base.py", line 843, in _resolve_lookup
    current = getattr(current, bit)
AttributeError: 'dict' object has no attribute 'autofocus'

During handling of the above exception, another exception occurred:

Traceback (most recent call last):
  File "/Users/cribbee/Virtualenv/V-ZoomIn/lib/python3.6/site-packages/django/template/base.py", line 849, in _resolve_lookup
    current = current[int(bit)]
ValueError: invalid literal for int() with base 10: 'autofocus'

During handling of the above exception, another exception occurred:

Traceback (most recent call last):
  File "/Users/cribbee/Virtualenv/V-ZoomIn/lib/python3.6/site-packages/django/template/base.py", line 856, in _resolve_lookup
    (bit, current))  # missing attribute
django.template.base.VariableDoesNotExist: Failed lookup for key [autofocus] in {'base_template': 'input.html', 'input_type': 'text', 'template_pack': 'rest_framework/horizontal', 'renderer': <rest_framework.renderers.HTMLFormRenderer object at 0x10d45d3c8>}
Exception while resolving variable 'hide_label' in template 'rest_framework/horizontal/input.html'.
Traceback (most recent call last):
  File "/Users/cribbee/Virtualenv/V-ZoomIn/lib/python3.6/site-packages/django/template/base.py", line 835, in _resolve_lookup
    current = current[bit]
KeyError: 'hide_label'

During handling of the above exception, another exception occurred:

Traceback (most recent call last):
  File "/Users/cribbee/Virtualenv/V-ZoomIn/lib/python3.6/site-packages/django/template/base.py", line 843, in _resolve_lookup
    current = getattr(current, bit)
AttributeError: 'dict' object has no attribute 'hide_label'

During handling of the above exception, another exception occurred:

Traceback (most recent call last):
  File "/Users/cribbee/Virtualenv/V-ZoomIn/lib/python3.6/site-packages/django/template/base.py", line 849, in _resolve_lookup
    current = current[int(bit)]
ValueError: invalid literal for int() with base 10: 'hide_label'

During handling of the above exception, another exception occurred:

Traceback (most recent call last):
  File "/Users/cribbee/Virtualenv/V-ZoomIn/lib/python3.6/site-packages/django/template/base.py", line 856, in _resolve_lookup
    (bit, current))  # missing attribute
django.template.base.VariableDoesNotExist: Failed lookup for key [hide_label] in {'base_template': 'input.html', 'input_type': 'password', 'template_pack': 'rest_framework/horizontal', 'renderer': <rest_framework.renderers.HTMLFormRenderer object at 0x10d45d3c8>}
Exception while resolving variable 'placeholder' in template 'rest_framework/horizontal/input.html'.
Traceback (most recent call last):
  File "/Users/cribbee/Virtualenv/V-ZoomIn/lib/python3.6/site-packages/django/template/base.py", line 835, in _resolve_lookup
    current = current[bit]
KeyError: 'placeholder'

During handling of the above exception, another exception occurred:

Traceback (most recent call last):
  File "/Users/cribbee/Virtualenv/V-ZoomIn/lib/python3.6/site-packages/django/template/base.py", line 843, in _resolve_lookup
    current = getattr(current, bit)
AttributeError: 'dict' object has no attribute 'placeholder'

During handling of the above exception, another exception occurred:

Traceback (most recent call last):
  File "/Users/cribbee/Virtualenv/V-ZoomIn/lib/python3.6/site-packages/django/template/base.py", line 849, in _resolve_lookup
    current = current[int(bit)]
ValueError: invalid literal for int() with base 10: 'placeholder'

During handling of the above exception, another exception occurred:

Traceback (most recent call last):
  File "/Users/cribbee/Virtualenv/V-ZoomIn/lib/python3.6/site-packages/django/template/base.py", line 856, in _resolve_lookup
    (bit, current))  # missing attribute
django.template.base.VariableDoesNotExist: Failed lookup for key [placeholder] in {'base_template': 'input.html', 'input_type': 'password', 'template_pack': 'rest_framework/horizontal', 'renderer': <rest_framework.renderers.HTMLFormRenderer object at 0x10d45d3c8>}
Exception while resolving variable 'autofocus' in template 'rest_framework/horizontal/input.html'.
Traceback (most recent call last):
  File "/Users/cribbee/Virtualenv/V-ZoomIn/lib/python3.6/site-packages/django/template/base.py", line 835, in _resolve_lookup
    current = current[bit]
KeyError: 'autofocus'

During handling of the above exception, another exception occurred:

Traceback (most recent call last):
  File "/Users/cribbee/Virtualenv/V-ZoomIn/lib/python3.6/site-packages/django/template/base.py", line 843, in _resolve_lookup
    current = getattr(current, bit)
AttributeError: 'dict' object has no attribute 'autofocus'

During handling of the above exception, another exception occurred:

Traceback (most recent call last):
  File "/Users/cribbee/Virtualenv/V-ZoomIn/lib/python3.6/site-packages/django/template/base.py", line 849, in _resolve_lookup
    current = current[int(bit)]
ValueError: invalid literal for int() with base 10: 'autofocus'

During handling of the above exception, another exception occurred:

Traceback (most recent call last):
  File "/Users/cribbee/Virtualenv/V-ZoomIn/lib/python3.6/site-packages/django/template/base.py", line 856, in _resolve_lookup
    (bit, current))  # missing attribute
django.template.base.VariableDoesNotExist: Failed lookup for key [autofocus] in {'base_template': 'input.html', 'input_type': 'password', 'template_pack': 'rest_framework/horizontal', 'renderer': <rest_framework.renderers.HTMLFormRenderer object at 0x10d45d3c8>}
"POST /login/ HTTP/1.1" 400 7733
(0.000) SELECT @@SQL_AUTO_IS_NULL; args=None
(0.000) SET SESSION TRANSACTION ISOLATION LEVEL READ COMMITTED; args=None
(0.000) SELECT VERSION(); args=None
(0.000) SET SESSION TRANSACTION ISOLATION LEVEL READ COMMITTED; args=None
(0.001) SELECT `users_userprofile`.`id`, `users_userprofile`.`password`, `users_userprofile`.`last_login`, `users_userprofile`.`is_superuser`, `users_userprofile`.`username`, `users_userprofile`.`first_name`, `users_userprofile`.`last_name`, `users_userprofile`.`is_staff`, `users_userprofile`.`is_active`, `users_userprofile`.`date_joined`, `users_userprofile`.`name`, `users_userprofile`.`birthday`, `users_userprofile`.`mobile`, `users_userprofile`.`gender`, `users_userprofile`.`email`, `users_userprofile`.`task_num` FROM `users_userprofile` WHERE (`users_userprofile`.`username` = 'admin2' OR `users_userprofile`.`mobile` = 'admin2'); args=('admin2', 'admin2')
Exception while resolving variable 'hide_label' in template 'rest_framework/horizontal/input.html'.
Traceback (most recent call last):
  File "/Users/cribbee/Virtualenv/V-ZoomIn/lib/python3.6/site-packages/django/template/base.py", line 835, in _resolve_lookup
    current = current[bit]
KeyError: 'hide_label'

During handling of the above exception, another exception occurred:

Traceback (most recent call last):
  File "/Users/cribbee/Virtualenv/V-ZoomIn/lib/python3.6/site-packages/django/template/base.py", line 843, in _resolve_lookup
    current = getattr(current, bit)
AttributeError: 'dict' object has no attribute 'hide_label'

During handling of the above exception, another exception occurred:

Traceback (most recent call last):
  File "/Users/cribbee/Virtualenv/V-ZoomIn/lib/python3.6/site-packages/django/template/base.py", line 849, in _resolve_lookup
    current = current[int(bit)]
ValueError: invalid literal for int() with base 10: 'hide_label'

During handling of the above exception, another exception occurred:

Traceback (most recent call last):
  File "/Users/cribbee/Virtualenv/V-ZoomIn/lib/python3.6/site-packages/django/template/base.py", line 856, in _resolve_lookup
    (bit, current))  # missing attribute
django.template.base.VariableDoesNotExist: Failed lookup for key [hide_label] in {'base_template': 'input.html', 'input_type': 'text', 'template_pack': 'rest_framework/horizontal', 'renderer': <rest_framework.renderers.HTMLFormRenderer object at 0x10d4b4e10>}
Exception while resolving variable 'placeholder' in template 'rest_framework/horizontal/input.html'.
Traceback (most recent call last):
  File "/Users/cribbee/Virtualenv/V-ZoomIn/lib/python3.6/site-packages/django/template/base.py", line 835, in _resolve_lookup
    current = current[bit]
KeyError: 'placeholder'

During handling of the above exception, another exception occurred:

Traceback (most recent call last):
  File "/Users/cribbee/Virtualenv/V-ZoomIn/lib/python3.6/site-packages/django/template/base.py", line 843, in _resolve_lookup
    current = getattr(current, bit)
AttributeError: 'dict' object has no attribute 'placeholder'

During handling of the above exception, another exception occurred:

Traceback (most recent call last):
  File "/Users/cribbee/Virtualenv/V-ZoomIn/lib/python3.6/site-packages/django/template/base.py", line 849, in _resolve_lookup
    current = current[int(bit)]
ValueError: invalid literal for int() with base 10: 'placeholder'

During handling of the above exception, another exception occurred:

Traceback (most recent call last):
  File "/Users/cribbee/Virtualenv/V-ZoomIn/lib/python3.6/site-packages/django/template/base.py", line 856, in _resolve_lookup
    (bit, current))  # missing attribute
django.template.base.VariableDoesNotExist: Failed lookup for key [placeholder] in {'base_template': 'input.html', 'input_type': 'text', 'template_pack': 'rest_framework/horizontal', 'renderer': <rest_framework.renderers.HTMLFormRenderer object at 0x10d4b4e10>}
Exception while resolving variable 'autofocus' in template 'rest_framework/horizontal/input.html'.
Traceback (most recent call last):
  File "/Users/cribbee/Virtualenv/V-ZoomIn/lib/python3.6/site-packages/django/template/base.py", line 835, in _resolve_lookup
    current = current[bit]
KeyError: 'autofocus'

During handling of the above exception, another exception occurred:

Traceback (most recent call last):
  File "/Users/cribbee/Virtualenv/V-ZoomIn/lib/python3.6/site-packages/django/template/base.py", line 843, in _resolve_lookup
    current = getattr(current, bit)
AttributeError: 'dict' object has no attribute 'autofocus'

During handling of the above exception, another exception occurred:

Traceback (most recent call last):
  File "/Users/cribbee/Virtualenv/V-ZoomIn/lib/python3.6/site-packages/django/template/base.py", line 849, in _resolve_lookup
    current = current[int(bit)]
ValueError: invalid literal for int() with base 10: 'autofocus'

During handling of the above exception, another exception occurred:

Traceback (most recent call last):
  File "/Users/cribbee/Virtualenv/V-ZoomIn/lib/python3.6/site-packages/django/template/base.py", line 856, in _resolve_lookup
    (bit, current))  # missing attribute
django.template.base.VariableDoesNotExist: Failed lookup for key [autofocus] in {'base_template': 'input.html', 'input_type': 'text', 'template_pack': 'rest_framework/horizontal', 'renderer': <rest_framework.renderers.HTMLFormRenderer object at 0x10d4b4e10>}
Exception while resolving variable 'hide_label' in template 'rest_framework/horizontal/input.html'.
Traceback (most recent call last):
  File "/Users/cribbee/Virtualenv/V-ZoomIn/lib/python3.6/site-packages/django/template/base.py", line 835, in _resolve_lookup
    current = current[bit]
KeyError: 'hide_label'

During handling of the above exception, another exception occurred:

Traceback (most recent call last):
  File "/Users/cribbee/Virtualenv/V-ZoomIn/lib/python3.6/site-packages/django/template/base.py", line 843, in _resolve_lookup
    current = getattr(current, bit)
AttributeError: 'dict' object has no attribute 'hide_label'

During handling of the above exception, another exception occurred:

Traceback (most recent call last):
  File "/Users/cribbee/Virtualenv/V-ZoomIn/lib/python3.6/site-packages/django/template/base.py", line 849, in _resolve_lookup
    current = current[int(bit)]
ValueError: invalid literal for int() with base 10: 'hide_label'

During handling of the above exception, another exception occurred:

Traceback (most recent call last):
  File "/Users/cribbee/Virtualenv/V-ZoomIn/lib/python3.6/site-packages/django/template/base.py", line 856, in _resolve_lookup
    (bit, current))  # missing attribute
django.template.base.VariableDoesNotExist: Failed lookup for key [hide_label] in {'base_template': 'input.html', 'input_type': 'password', 'template_pack': 'rest_framework/horizontal', 'renderer': <rest_framework.renderers.HTMLFormRenderer object at 0x10d4b4e10>}
Exception while resolving variable 'placeholder' in template 'rest_framework/horizontal/input.html'.
Traceback (most recent call last):
  File "/Users/cribbee/Virtualenv/V-ZoomIn/lib/python3.6/site-packages/django/template/base.py", line 835, in _resolve_lookup
    current = current[bit]
KeyError: 'placeholder'

During handling of the above exception, another exception occurred:

Traceback (most recent call last):
  File "/Users/cribbee/Virtualenv/V-ZoomIn/lib/python3.6/site-packages/django/template/base.py", line 843, in _resolve_lookup
    current = getattr(current, bit)
AttributeError: 'dict' object has no attribute 'placeholder'

During handling of the above exception, another exception occurred:

Traceback (most recent call last):
  File "/Users/cribbee/Virtualenv/V-ZoomIn/lib/python3.6/site-packages/django/template/base.py", line 849, in _resolve_lookup
    current = current[int(bit)]
ValueError: invalid literal for int() with base 10: 'placeholder'

During handling of the above exception, another exception occurred:

Traceback (most recent call last):
  File "/Users/cribbee/Virtualenv/V-ZoomIn/lib/python3.6/site-packages/django/template/base.py", line 856, in _resolve_lookup
    (bit, current))  # missing attribute
django.template.base.VariableDoesNotExist: Failed lookup for key [placeholder] in {'base_template': 'input.html', 'input_type': 'password', 'template_pack': 'rest_framework/horizontal', 'renderer': <rest_framework.renderers.HTMLFormRenderer object at 0x10d4b4e10>}
Exception while resolving variable 'autofocus' in template 'rest_framework/horizontal/input.html'.
Traceback (most recent call last):
  File "/Users/cribbee/Virtualenv/V-ZoomIn/lib/python3.6/site-packages/django/template/base.py", line 835, in _resolve_lookup
    current = current[bit]
KeyError: 'autofocus'

During handling of the above exception, another exception occurred:

Traceback (most recent call last):
  File "/Users/cribbee/Virtualenv/V-ZoomIn/lib/python3.6/site-packages/django/template/base.py", line 843, in _resolve_lookup
    current = getattr(current, bit)
AttributeError: 'dict' object has no attribute 'autofocus'

During handling of the above exception, another exception occurred:

Traceback (most recent call last):
  File "/Users/cribbee/Virtualenv/V-ZoomIn/lib/python3.6/site-packages/django/template/base.py", line 849, in _resolve_lookup
    current = current[int(bit)]
ValueError: invalid literal for int() with base 10: 'autofocus'

During handling of the above exception, another exception occurred:

Traceback (most recent call last):
  File "/Users/cribbee/Virtualenv/V-ZoomIn/lib/python3.6/site-packages/django/template/base.py", line 856, in _resolve_lookup
    (bit, current))  # missing attribute
django.template.base.VariableDoesNotExist: Failed lookup for key [autofocus] in {'base_template': 'input.html', 'input_type': 'password', 'template_pack': 'rest_framework/horizontal', 'renderer': <rest_framework.renderers.HTMLFormRenderer object at 0x10d4b4e10>}
"POST /login/ HTTP/1.1" 400 7733
(0.000) SELECT @@SQL_AUTO_IS_NULL; args=None
(0.000) SET SESSION TRANSACTION ISOLATION LEVEL READ COMMITTED; args=None
(0.000) SELECT VERSION(); args=None
(0.000) SET SESSION TRANSACTION ISOLATION LEVEL READ COMMITTED; args=None
(0.001) SELECT `users_userprofile`.`id`, `users_userprofile`.`password`, `users_userprofile`.`last_login`, `users_userprofile`.`is_superuser`, `users_userprofile`.`username`, `users_userprofile`.`first_name`, `users_userprofile`.`last_name`, `users_userprofile`.`is_staff`, `users_userprofile`.`is_active`, `users_userprofile`.`date_joined`, `users_userprofile`.`name`, `users_userprofile`.`birthday`, `users_userprofile`.`mobile`, `users_userprofile`.`gender`, `users_userprofile`.`email`, `users_userprofile`.`task_num` FROM `users_userprofile` WHERE (`users_userprofile`.`username` = 'admin2' OR `users_userprofile`.`mobile` = 'admin2'); args=('admin2', 'admin2')
Exception while resolving variable 'hide_label' in template 'rest_framework/horizontal/input.html'.
Traceback (most recent call last):
  File "/Users/cribbee/Virtualenv/V-ZoomIn/lib/python3.6/site-packages/django/template/base.py", line 835, in _resolve_lookup
    current = current[bit]
KeyError: 'hide_label'

During handling of the above exception, another exception occurred:

Traceback (most recent call last):
  File "/Users/cribbee/Virtualenv/V-ZoomIn/lib/python3.6/site-packages/django/template/base.py", line 843, in _resolve_lookup
    current = getattr(current, bit)
AttributeError: 'dict' object has no attribute 'hide_label'

During handling of the above exception, another exception occurred:

Traceback (most recent call last):
  File "/Users/cribbee/Virtualenv/V-ZoomIn/lib/python3.6/site-packages/django/template/base.py", line 849, in _resolve_lookup
    current = current[int(bit)]
ValueError: invalid literal for int() with base 10: 'hide_label'

During handling of the above exception, another exception occurred:

Traceback (most recent call last):
  File "/Users/cribbee/Virtualenv/V-ZoomIn/lib/python3.6/site-packages/django/template/base.py", line 856, in _resolve_lookup
    (bit, current))  # missing attribute
django.template.base.VariableDoesNotExist: Failed lookup for key [hide_label] in {'base_template': 'input.html', 'input_type': 'text', 'template_pack': 'rest_framework/horizontal', 'renderer': <rest_framework.renderers.HTMLFormRenderer object at 0x10d457a20>}
Exception while resolving variable 'placeholder' in template 'rest_framework/horizontal/input.html'.
Traceback (most recent call last):
  File "/Users/cribbee/Virtualenv/V-ZoomIn/lib/python3.6/site-packages/django/template/base.py", line 835, in _resolve_lookup
    current = current[bit]
KeyError: 'placeholder'

During handling of the above exception, another exception occurred:

Traceback (most recent call last):
  File "/Users/cribbee/Virtualenv/V-ZoomIn/lib/python3.6/site-packages/django/template/base.py", line 843, in _resolve_lookup
    current = getattr(current, bit)
AttributeError: 'dict' object has no attribute 'placeholder'

During handling of the above exception, another exception occurred:

Traceback (most recent call last):
  File "/Users/cribbee/Virtualenv/V-ZoomIn/lib/python3.6/site-packages/django/template/base.py", line 849, in _resolve_lookup
    current = current[int(bit)]
ValueError: invalid literal for int() with base 10: 'placeholder'

During handling of the above exception, another exception occurred:

Traceback (most recent call last):
  File "/Users/cribbee/Virtualenv/V-ZoomIn/lib/python3.6/site-packages/django/template/base.py", line 856, in _resolve_lookup
    (bit, current))  # missing attribute
django.template.base.VariableDoesNotExist: Failed lookup for key [placeholder] in {'base_template': 'input.html', 'input_type': 'text', 'template_pack': 'rest_framework/horizontal', 'renderer': <rest_framework.renderers.HTMLFormRenderer object at 0x10d457a20>}
Exception while resolving variable 'autofocus' in template 'rest_framework/horizontal/input.html'.
Traceback (most recent call last):
  File "/Users/cribbee/Virtualenv/V-ZoomIn/lib/python3.6/site-packages/django/template/base.py", line 835, in _resolve_lookup
    current = current[bit]
KeyError: 'autofocus'

During handling of the above exception, another exception occurred:

Traceback (most recent call last):
  File "/Users/cribbee/Virtualenv/V-ZoomIn/lib/python3.6/site-packages/django/template/base.py", line 843, in _resolve_lookup
    current = getattr(current, bit)
AttributeError: 'dict' object has no attribute 'autofocus'

During handling of the above exception, another exception occurred:

Traceback (most recent call last):
  File "/Users/cribbee/Virtualenv/V-ZoomIn/lib/python3.6/site-packages/django/template/base.py", line 849, in _resolve_lookup
    current = current[int(bit)]
ValueError: invalid literal for int() with base 10: 'autofocus'

During handling of the above exception, another exception occurred:

Traceback (most recent call last):
  File "/Users/cribbee/Virtualenv/V-ZoomIn/lib/python3.6/site-packages/django/template/base.py", line 856, in _resolve_lookup
    (bit, current))  # missing attribute
django.template.base.VariableDoesNotExist: Failed lookup for key [autofocus] in {'base_template': 'input.html', 'input_type': 'text', 'template_pack': 'rest_framework/horizontal', 'renderer': <rest_framework.renderers.HTMLFormRenderer object at 0x10d457a20>}
Exception while resolving variable 'hide_label' in template 'rest_framework/horizontal/input.html'.
Traceback (most recent call last):
  File "/Users/cribbee/Virtualenv/V-ZoomIn/lib/python3.6/site-packages/django/template/base.py", line 835, in _resolve_lookup
    current = current[bit]
KeyError: 'hide_label'

During handling of the above exception, another exception occurred:

Traceback (most recent call last):
  File "/Users/cribbee/Virtualenv/V-ZoomIn/lib/python3.6/site-packages/django/template/base.py", line 843, in _resolve_lookup
    current = getattr(current, bit)
AttributeError: 'dict' object has no attribute 'hide_label'

During handling of the above exception, another exception occurred:

Traceback (most recent call last):
  File "/Users/cribbee/Virtualenv/V-ZoomIn/lib/python3.6/site-packages/django/template/base.py", line 849, in _resolve_lookup
    current = current[int(bit)]
ValueError: invalid literal for int() with base 10: 'hide_label'

During handling of the above exception, another exception occurred:

Traceback (most recent call last):
  File "/Users/cribbee/Virtualenv/V-ZoomIn/lib/python3.6/site-packages/django/template/base.py", line 856, in _resolve_lookup
    (bit, current))  # missing attribute
django.template.base.VariableDoesNotExist: Failed lookup for key [hide_label] in {'base_template': 'input.html', 'input_type': 'password', 'template_pack': 'rest_framework/horizontal', 'renderer': <rest_framework.renderers.HTMLFormRenderer object at 0x10d457a20>}
Exception while resolving variable 'placeholder' in template 'rest_framework/horizontal/input.html'.
Traceback (most recent call last):
  File "/Users/cribbee/Virtualenv/V-ZoomIn/lib/python3.6/site-packages/django/template/base.py", line 835, in _resolve_lookup
    current = current[bit]
KeyError: 'placeholder'

During handling of the above exception, another exception occurred:

Traceback (most recent call last):
  File "/Users/cribbee/Virtualenv/V-ZoomIn/lib/python3.6/site-packages/django/template/base.py", line 843, in _resolve_lookup
    current = getattr(current, bit)
AttributeError: 'dict' object has no attribute 'placeholder'

During handling of the above exception, another exception occurred:

Traceback (most recent call last):
  File "/Users/cribbee/Virtualenv/V-ZoomIn/lib/python3.6/site-packages/django/template/base.py", line 849, in _resolve_lookup
    current = current[int(bit)]
ValueError: invalid literal for int() with base 10: 'placeholder'

During handling of the above exception, another exception occurred:

Traceback (most recent call last):
  File "/Users/cribbee/Virtualenv/V-ZoomIn/lib/python3.6/site-packages/django/template/base.py", line 856, in _resolve_lookup
    (bit, current))  # missing attribute
django.template.base.VariableDoesNotExist: Failed lookup for key [placeholder] in {'base_template': 'input.html', 'input_type': 'password', 'template_pack': 'rest_framework/horizontal', 'renderer': <rest_framework.renderers.HTMLFormRenderer object at 0x10d457a20>}
Exception while resolving variable 'autofocus' in template 'rest_framework/horizontal/input.html'.
Traceback (most recent call last):
  File "/Users/cribbee/Virtualenv/V-ZoomIn/lib/python3.6/site-packages/django/template/base.py", line 835, in _resolve_lookup
    current = current[bit]
KeyError: 'autofocus'

During handling of the above exception, another exception occurred:

Traceback (most recent call last):
  File "/Users/cribbee/Virtualenv/V-ZoomIn/lib/python3.6/site-packages/django/template/base.py", line 843, in _resolve_lookup
    current = getattr(current, bit)
AttributeError: 'dict' object has no attribute 'autofocus'

During handling of the above exception, another exception occurred:

Traceback (most recent call last):
  File "/Users/cribbee/Virtualenv/V-ZoomIn/lib/python3.6/site-packages/django/template/base.py", line 849, in _resolve_lookup
    current = current[int(bit)]
ValueError: invalid literal for int() with base 10: 'autofocus'

During handling of the above exception, another exception occurred:

Traceback (most recent call last):
  File "/Users/cribbee/Virtualenv/V-ZoomIn/lib/python3.6/site-packages/django/template/base.py", line 856, in _resolve_lookup
    (bit, current))  # missing attribute
django.template.base.VariableDoesNotExist: Failed lookup for key [autofocus] in {'base_template': 'input.html', 'input_type': 'password', 'template_pack': 'rest_framework/horizontal', 'renderer': <rest_framework.renderers.HTMLFormRenderer object at 0x10d457a20>}
"POST /login/ HTTP/1.1" 400 7733
(0.000) SELECT @@SQL_AUTO_IS_NULL; args=None
(0.000) SET SESSION TRANSACTION ISOLATION LEVEL READ COMMITTED; args=None
(0.000) SELECT VERSION(); args=None
(0.000) SET SESSION TRANSACTION ISOLATION LEVEL READ COMMITTED; args=None
(0.001) SELECT `users_userprofile`.`id`, `users_userprofile`.`password`, `users_userprofile`.`last_login`, `users_userprofile`.`is_superuser`, `users_userprofile`.`username`, `users_userprofile`.`first_name`, `users_userprofile`.`last_name`, `users_userprofile`.`is_staff`, `users_userprofile`.`is_active`, `users_userprofile`.`date_joined`, `users_userprofile`.`name`, `users_userprofile`.`birthday`, `users_userprofile`.`mobile`, `users_userprofile`.`gender`, `users_userprofile`.`email`, `users_userprofile`.`task_num` FROM `users_userprofile` WHERE (`users_userprofile`.`username` = 'admin2' OR `users_userprofile`.`mobile` = 'admin2'); args=('admin2', 'admin2')
Exception while resolving variable 'hide_label' in template 'rest_framework/horizontal/input.html'.
Traceback (most recent call last):
  File "/Users/cribbee/Virtualenv/V-ZoomIn/lib/python3.6/site-packages/django/template/base.py", line 835, in _resolve_lookup
    current = current[bit]
KeyError: 'hide_label'

During handling of the above exception, another exception occurred:

Traceback (most recent call last):
  File "/Users/cribbee/Virtualenv/V-ZoomIn/lib/python3.6/site-packages/django/template/base.py", line 843, in _resolve_lookup
    current = getattr(current, bit)
AttributeError: 'dict' object has no attribute 'hide_label'

During handling of the above exception, another exception occurred:

Traceback (most recent call last):
  File "/Users/cribbee/Virtualenv/V-ZoomIn/lib/python3.6/site-packages/django/template/base.py", line 849, in _resolve_lookup
    current = current[int(bit)]
ValueError: invalid literal for int() with base 10: 'hide_label'

During handling of the above exception, another exception occurred:

Traceback (most recent call last):
  File "/Users/cribbee/Virtualenv/V-ZoomIn/lib/python3.6/site-packages/django/template/base.py", line 856, in _resolve_lookup
    (bit, current))  # missing attribute
django.template.base.VariableDoesNotExist: Failed lookup for key [hide_label] in {'base_template': 'input.html', 'input_type': 'text', 'template_pack': 'rest_framework/horizontal', 'renderer': <rest_framework.renderers.HTMLFormRenderer object at 0x10d44b550>}
Exception while resolving variable 'placeholder' in template 'rest_framework/horizontal/input.html'.
Traceback (most recent call last):
  File "/Users/cribbee/Virtualenv/V-ZoomIn/lib/python3.6/site-packages/django/template/base.py", line 835, in _resolve_lookup
    current = current[bit]
KeyError: 'placeholder'

During handling of the above exception, another exception occurred:

Traceback (most recent call last):
  File "/Users/cribbee/Virtualenv/V-ZoomIn/lib/python3.6/site-packages/django/template/base.py", line 843, in _resolve_lookup
    current = getattr(current, bit)
AttributeError: 'dict' object has no attribute 'placeholder'

During handling of the above exception, another exception occurred:

Traceback (most recent call last):
  File "/Users/cribbee/Virtualenv/V-ZoomIn/lib/python3.6/site-packages/django/template/base.py", line 849, in _resolve_lookup
    current = current[int(bit)]
ValueError: invalid literal for int() with base 10: 'placeholder'

During handling of the above exception, another exception occurred:

Traceback (most recent call last):
  File "/Users/cribbee/Virtualenv/V-ZoomIn/lib/python3.6/site-packages/django/template/base.py", line 856, in _resolve_lookup
    (bit, current))  # missing attribute
django.template.base.VariableDoesNotExist: Failed lookup for key [placeholder] in {'base_template': 'input.html', 'input_type': 'text', 'template_pack': 'rest_framework/horizontal', 'renderer': <rest_framework.renderers.HTMLFormRenderer object at 0x10d44b550>}
Exception while resolving variable 'autofocus' in template 'rest_framework/horizontal/input.html'.
Traceback (most recent call last):
  File "/Users/cribbee/Virtualenv/V-ZoomIn/lib/python3.6/site-packages/django/template/base.py", line 835, in _resolve_lookup
    current = current[bit]
KeyError: 'autofocus'

During handling of the above exception, another exception occurred:

Traceback (most recent call last):
  File "/Users/cribbee/Virtualenv/V-ZoomIn/lib/python3.6/site-packages/django/template/base.py", line 843, in _resolve_lookup
    current = getattr(current, bit)
AttributeError: 'dict' object has no attribute 'autofocus'

During handling of the above exception, another exception occurred:

Traceback (most recent call last):
  File "/Users/cribbee/Virtualenv/V-ZoomIn/lib/python3.6/site-packages/django/template/base.py", line 849, in _resolve_lookup
    current = current[int(bit)]
ValueError: invalid literal for int() with base 10: 'autofocus'

During handling of the above exception, another exception occurred:

Traceback (most recent call last):
  File "/Users/cribbee/Virtualenv/V-ZoomIn/lib/python3.6/site-packages/django/template/base.py", line 856, in _resolve_lookup
    (bit, current))  # missing attribute
django.template.base.VariableDoesNotExist: Failed lookup for key [autofocus] in {'base_template': 'input.html', 'input_type': 'text', 'template_pack': 'rest_framework/horizontal', 'renderer': <rest_framework.renderers.HTMLFormRenderer object at 0x10d44b550>}
Exception while resolving variable 'hide_label' in template 'rest_framework/horizontal/input.html'.
Traceback (most recent call last):
  File "/Users/cribbee/Virtualenv/V-ZoomIn/lib/python3.6/site-packages/django/template/base.py", line 835, in _resolve_lookup
    current = current[bit]
KeyError: 'hide_label'

During handling of the above exception, another exception occurred:

Traceback (most recent call last):
  File "/Users/cribbee/Virtualenv/V-ZoomIn/lib/python3.6/site-packages/django/template/base.py", line 843, in _resolve_lookup
    current = getattr(current, bit)
AttributeError: 'dict' object has no attribute 'hide_label'

During handling of the above exception, another exception occurred:

Traceback (most recent call last):
  File "/Users/cribbee/Virtualenv/V-ZoomIn/lib/python3.6/site-packages/django/template/base.py", line 849, in _resolve_lookup
    current = current[int(bit)]
ValueError: invalid literal for int() with base 10: 'hide_label'

During handling of the above exception, another exception occurred:

Traceback (most recent call last):
  File "/Users/cribbee/Virtualenv/V-ZoomIn/lib/python3.6/site-packages/django/template/base.py", line 856, in _resolve_lookup
    (bit, current))  # missing attribute
django.template.base.VariableDoesNotExist: Failed lookup for key [hide_label] in {'base_template': 'input.html', 'input_type': 'password', 'template_pack': 'rest_framework/horizontal', 'renderer': <rest_framework.renderers.HTMLFormRenderer object at 0x10d44b550>}
Exception while resolving variable 'placeholder' in template 'rest_framework/horizontal/input.html'.
Traceback (most recent call last):
  File "/Users/cribbee/Virtualenv/V-ZoomIn/lib/python3.6/site-packages/django/template/base.py", line 835, in _resolve_lookup
    current = current[bit]
KeyError: 'placeholder'

During handling of the above exception, another exception occurred:

Traceback (most recent call last):
  File "/Users/cribbee/Virtualenv/V-ZoomIn/lib/python3.6/site-packages/django/template/base.py", line 843, in _resolve_lookup
    current = getattr(current, bit)
AttributeError: 'dict' object has no attribute 'placeholder'

During handling of the above exception, another exception occurred:

Traceback (most recent call last):
  File "/Users/cribbee/Virtualenv/V-ZoomIn/lib/python3.6/site-packages/django/template/base.py", line 849, in _resolve_lookup
    current = current[int(bit)]
ValueError: invalid literal for int() with base 10: 'placeholder'

During handling of the above exception, another exception occurred:

Traceback (most recent call last):
  File "/Users/cribbee/Virtualenv/V-ZoomIn/lib/python3.6/site-packages/django/template/base.py", line 856, in _resolve_lookup
    (bit, current))  # missing attribute
django.template.base.VariableDoesNotExist: Failed lookup for key [placeholder] in {'base_template': 'input.html', 'input_type': 'password', 'template_pack': 'rest_framework/horizontal', 'renderer': <rest_framework.renderers.HTMLFormRenderer object at 0x10d44b550>}
Exception while resolving variable 'autofocus' in template 'rest_framework/horizontal/input.html'.
Traceback (most recent call last):
  File "/Users/cribbee/Virtualenv/V-ZoomIn/lib/python3.6/site-packages/django/template/base.py", line 835, in _resolve_lookup
    current = current[bit]
KeyError: 'autofocus'

During handling of the above exception, another exception occurred:

Traceback (most recent call last):
  File "/Users/cribbee/Virtualenv/V-ZoomIn/lib/python3.6/site-packages/django/template/base.py", line 843, in _resolve_lookup
    current = getattr(current, bit)
AttributeError: 'dict' object has no attribute 'autofocus'

During handling of the above exception, another exception occurred:

Traceback (most recent call last):
  File "/Users/cribbee/Virtualenv/V-ZoomIn/lib/python3.6/site-packages/django/template/base.py", line 849, in _resolve_lookup
    current = current[int(bit)]
ValueError: invalid literal for int() with base 10: 'autofocus'

During handling of the above exception, another exception occurred:

Traceback (most recent call last):
  File "/Users/cribbee/Virtualenv/V-ZoomIn/lib/python3.6/site-packages/django/template/base.py", line 856, in _resolve_lookup
    (bit, current))  # missing attribute
django.template.base.VariableDoesNotExist: Failed lookup for key [autofocus] in {'base_template': 'input.html', 'input_type': 'password', 'template_pack': 'rest_framework/horizontal', 'renderer': <rest_framework.renderers.HTMLFormRenderer object at 0x10d44b550>}
"POST /login/ HTTP/1.1" 400 7733
(0.000) SELECT @@SQL_AUTO_IS_NULL; args=None
(0.000) SET SESSION TRANSACTION ISOLATION LEVEL READ COMMITTED; args=None
(0.000) SELECT VERSION(); args=None
(0.000) SET SESSION TRANSACTION ISOLATION LEVEL READ COMMITTED; args=None
(0.014) SHOW FULL TABLES; args=None
(0.000) SELECT `django_migrations`.`app`, `django_migrations`.`name` FROM `django_migrations`; args=()
"GET / HTTP/1.1" 200 5356
Exception while resolving variable 'hide_label' in template 'rest_framework/horizontal/input.html'.
Traceback (most recent call last):
  File "/Users/cribbee/Virtualenv/V-ZoomIn/lib/python3.6/site-packages/django/template/base.py", line 835, in _resolve_lookup
    current = current[bit]
KeyError: 'hide_label'

During handling of the above exception, another exception occurred:

Traceback (most recent call last):
  File "/Users/cribbee/Virtualenv/V-ZoomIn/lib/python3.6/site-packages/django/template/base.py", line 843, in _resolve_lookup
    current = getattr(current, bit)
AttributeError: 'dict' object has no attribute 'hide_label'

During handling of the above exception, another exception occurred:

Traceback (most recent call last):
  File "/Users/cribbee/Virtualenv/V-ZoomIn/lib/python3.6/site-packages/django/template/base.py", line 849, in _resolve_lookup
    current = current[int(bit)]
ValueError: invalid literal for int() with base 10: 'hide_label'

During handling of the above exception, another exception occurred:

Traceback (most recent call last):
  File "/Users/cribbee/Virtualenv/V-ZoomIn/lib/python3.6/site-packages/django/template/base.py", line 856, in _resolve_lookup
    (bit, current))  # missing attribute
django.template.base.VariableDoesNotExist: Failed lookup for key [hide_label] in {'base_template': 'input.html', 'input_type': 'text', 'template_pack': 'rest_framework/horizontal', 'renderer': <rest_framework.renderers.HTMLFormRenderer object at 0x113a2b1d0>}
Exception while resolving variable 'placeholder' in template 'rest_framework/horizontal/input.html'.
Traceback (most recent call last):
  File "/Users/cribbee/Virtualenv/V-ZoomIn/lib/python3.6/site-packages/django/template/base.py", line 835, in _resolve_lookup
    current = current[bit]
KeyError: 'placeholder'

During handling of the above exception, another exception occurred:

Traceback (most recent call last):
  File "/Users/cribbee/Virtualenv/V-ZoomIn/lib/python3.6/site-packages/django/template/base.py", line 843, in _resolve_lookup
    current = getattr(current, bit)
AttributeError: 'dict' object has no attribute 'placeholder'

During handling of the above exception, another exception occurred:

Traceback (most recent call last):
  File "/Users/cribbee/Virtualenv/V-ZoomIn/lib/python3.6/site-packages/django/template/base.py", line 849, in _resolve_lookup
    current = current[int(bit)]
ValueError: invalid literal for int() with base 10: 'placeholder'

During handling of the above exception, another exception occurred:

Traceback (most recent call last):
  File "/Users/cribbee/Virtualenv/V-ZoomIn/lib/python3.6/site-packages/django/template/base.py", line 856, in _resolve_lookup
    (bit, current))  # missing attribute
django.template.base.VariableDoesNotExist: Failed lookup for key [placeholder] in {'base_template': 'input.html', 'input_type': 'text', 'template_pack': 'rest_framework/horizontal', 'renderer': <rest_framework.renderers.HTMLFormRenderer object at 0x113a2b1d0>}
Exception while resolving variable 'autofocus' in template 'rest_framework/horizontal/input.html'.
Traceback (most recent call last):
  File "/Users/cribbee/Virtualenv/V-ZoomIn/lib/python3.6/site-packages/django/template/base.py", line 835, in _resolve_lookup
    current = current[bit]
KeyError: 'autofocus'

During handling of the above exception, another exception occurred:

Traceback (most recent call last):
  File "/Users/cribbee/Virtualenv/V-ZoomIn/lib/python3.6/site-packages/django/template/base.py", line 843, in _resolve_lookup
    current = getattr(current, bit)
AttributeError: 'dict' object has no attribute 'autofocus'

During handling of the above exception, another exception occurred:

Traceback (most recent call last):
  File "/Users/cribbee/Virtualenv/V-ZoomIn/lib/python3.6/site-packages/django/template/base.py", line 849, in _resolve_lookup
    current = current[int(bit)]
ValueError: invalid literal for int() with base 10: 'autofocus'

During handling of the above exception, another exception occurred:

Traceback (most recent call last):
  File "/Users/cribbee/Virtualenv/V-ZoomIn/lib/python3.6/site-packages/django/template/base.py", line 856, in _resolve_lookup
    (bit, current))  # missing attribute
django.template.base.VariableDoesNotExist: Failed lookup for key [autofocus] in {'base_template': 'input.html', 'input_type': 'text', 'template_pack': 'rest_framework/horizontal', 'renderer': <rest_framework.renderers.HTMLFormRenderer object at 0x113a2b1d0>}
Exception while resolving variable 'hide_label' in template 'rest_framework/horizontal/input.html'.
Traceback (most recent call last):
  File "/Users/cribbee/Virtualenv/V-ZoomIn/lib/python3.6/site-packages/django/template/base.py", line 835, in _resolve_lookup
    current = current[bit]
KeyError: 'hide_label'

During handling of the above exception, another exception occurred:

Traceback (most recent call last):
  File "/Users/cribbee/Virtualenv/V-ZoomIn/lib/python3.6/site-packages/django/template/base.py", line 843, in _resolve_lookup
    current = getattr(current, bit)
AttributeError: 'dict' object has no attribute 'hide_label'

During handling of the above exception, another exception occurred:

Traceback (most recent call last):
  File "/Users/cribbee/Virtualenv/V-ZoomIn/lib/python3.6/site-packages/django/template/base.py", line 849, in _resolve_lookup
    current = current[int(bit)]
ValueError: invalid literal for int() with base 10: 'hide_label'

During handling of the above exception, another exception occurred:

Traceback (most recent call last):
  File "/Users/cribbee/Virtualenv/V-ZoomIn/lib/python3.6/site-packages/django/template/base.py", line 856, in _resolve_lookup
    (bit, current))  # missing attribute
django.template.base.VariableDoesNotExist: Failed lookup for key [hide_label] in {'base_template': 'input.html', 'input_type': 'password', 'template_pack': 'rest_framework/horizontal', 'renderer': <rest_framework.renderers.HTMLFormRenderer object at 0x113a2b1d0>}
Exception while resolving variable 'placeholder' in template 'rest_framework/horizontal/input.html'.
Traceback (most recent call last):
  File "/Users/cribbee/Virtualenv/V-ZoomIn/lib/python3.6/site-packages/django/template/base.py", line 835, in _resolve_lookup
    current = current[bit]
KeyError: 'placeholder'

During handling of the above exception, another exception occurred:

Traceback (most recent call last):
  File "/Users/cribbee/Virtualenv/V-ZoomIn/lib/python3.6/site-packages/django/template/base.py", line 843, in _resolve_lookup
    current = getattr(current, bit)
AttributeError: 'dict' object has no attribute 'placeholder'

During handling of the above exception, another exception occurred:

Traceback (most recent call last):
  File "/Users/cribbee/Virtualenv/V-ZoomIn/lib/python3.6/site-packages/django/template/base.py", line 849, in _resolve_lookup
    current = current[int(bit)]
ValueError: invalid literal for int() with base 10: 'placeholder'

During handling of the above exception, another exception occurred:

Traceback (most recent call last):
  File "/Users/cribbee/Virtualenv/V-ZoomIn/lib/python3.6/site-packages/django/template/base.py", line 856, in _resolve_lookup
    (bit, current))  # missing attribute
django.template.base.VariableDoesNotExist: Failed lookup for key [placeholder] in {'base_template': 'input.html', 'input_type': 'password', 'template_pack': 'rest_framework/horizontal', 'renderer': <rest_framework.renderers.HTMLFormRenderer object at 0x113a2b1d0>}
Exception while resolving variable 'autofocus' in template 'rest_framework/horizontal/input.html'.
Traceback (most recent call last):
  File "/Users/cribbee/Virtualenv/V-ZoomIn/lib/python3.6/site-packages/django/template/base.py", line 835, in _resolve_lookup
    current = current[bit]
KeyError: 'autofocus'

During handling of the above exception, another exception occurred:

Traceback (most recent call last):
  File "/Users/cribbee/Virtualenv/V-ZoomIn/lib/python3.6/site-packages/django/template/base.py", line 843, in _resolve_lookup
    current = getattr(current, bit)
AttributeError: 'dict' object has no attribute 'autofocus'

During handling of the above exception, another exception occurred:

Traceback (most recent call last):
  File "/Users/cribbee/Virtualenv/V-ZoomIn/lib/python3.6/site-packages/django/template/base.py", line 849, in _resolve_lookup
    current = current[int(bit)]
ValueError: invalid literal for int() with base 10: 'autofocus'

During handling of the above exception, another exception occurred:

Traceback (most recent call last):
  File "/Users/cribbee/Virtualenv/V-ZoomIn/lib/python3.6/site-packages/django/template/base.py", line 856, in _resolve_lookup
    (bit, current))  # missing attribute
django.template.base.VariableDoesNotExist: Failed lookup for key [autofocus] in {'base_template': 'input.html', 'input_type': 'password', 'template_pack': 'rest_framework/horizontal', 'renderer': <rest_framework.renderers.HTMLFormRenderer object at 0x113a2b1d0>}
"GET /users/ HTTP/1.1" 405 7634
(0.003) SELECT @@SQL_AUTO_IS_NULL; args=None
(0.002) SET SESSION TRANSACTION ISOLATION LEVEL READ COMMITTED; args=None
(0.002) SELECT VERSION(); args=None
(0.001) SET SESSION TRANSACTION ISOLATION LEVEL READ COMMITTED; args=None
(0.005) SELECT (1) AS `a` FROM `users_userprofile` WHERE `users_userprofile`.`username` = 'test12' LIMIT 1; args=('test12',)
(0.005) INSERT INTO `users_userprofile` (`password`, `last_login`, `is_superuser`, `username`, `first_name`, `last_name`, `is_staff`, `is_active`, `date_joined`, `name`, `birthday`, `mobile`, `gender`, `email`, `task_num`) VALUES ('test', NULL, 0, 'test12', '', '', 0, 1, '2018-06-05 14:00:12.226136', NULL, NULL, '', 'female', NULL, 0); args=['test', None, False, 'test12', '', '', False, True, '2018-06-05 14:00:12.226136', None, None, '', 'female', None, 0]
(0.002) UPDATE `users_userprofile` SET `password` = 'pbkdf2_sha256$100000$jy9zvvmc90v0$nLYAXEhuePyGTvlmnmeMKvhpis2SARFyaKVt85x8zc8=', `last_login` = NULL, `is_superuser` = 0, `username` = 'test12', `first_name` = '', `last_name` = '', `is_staff` = 0, `is_active` = 1, `date_joined` = '2018-06-05 14:00:12.226136', `name` = NULL, `birthday` = NULL, `mobile` = '', `gender` = 'female', `email` = NULL, `task_num` = 0 WHERE `users_userprofile`.`id` = 5; args=('pbkdf2_sha256$100000$jy9zvvmc90v0$nLYAXEhuePyGTvlmnmeMKvhpis2SARFyaKVt85x8zc8=', False, 'test12', '', '', False, True, '2018-06-05 14:00:12.226136', '', 'female', 0, 5)
Exception while resolving variable 'hide_label' in template 'rest_framework/horizontal/input.html'.
Traceback (most recent call last):
  File "/Users/cribbee/Virtualenv/V-ZoomIn/lib/python3.6/site-packages/django/template/base.py", line 835, in _resolve_lookup
    current = current[bit]
KeyError: 'hide_label'

During handling of the above exception, another exception occurred:

Traceback (most recent call last):
  File "/Users/cribbee/Virtualenv/V-ZoomIn/lib/python3.6/site-packages/django/template/base.py", line 843, in _resolve_lookup
    current = getattr(current, bit)
AttributeError: 'dict' object has no attribute 'hide_label'

During handling of the above exception, another exception occurred:

Traceback (most recent call last):
  File "/Users/cribbee/Virtualenv/V-ZoomIn/lib/python3.6/site-packages/django/template/base.py", line 849, in _resolve_lookup
    current = current[int(bit)]
ValueError: invalid literal for int() with base 10: 'hide_label'

During handling of the above exception, another exception occurred:

Traceback (most recent call last):
  File "/Users/cribbee/Virtualenv/V-ZoomIn/lib/python3.6/site-packages/django/template/base.py", line 856, in _resolve_lookup
    (bit, current))  # missing attribute
django.template.base.VariableDoesNotExist: Failed lookup for key [hide_label] in {'base_template': 'input.html', 'input_type': 'text', 'template_pack': 'rest_framework/horizontal', 'renderer': <rest_framework.renderers.HTMLFormRenderer object at 0x113a9deb8>}
Exception while resolving variable 'placeholder' in template 'rest_framework/horizontal/input.html'.
Traceback (most recent call last):
  File "/Users/cribbee/Virtualenv/V-ZoomIn/lib/python3.6/site-packages/django/template/base.py", line 835, in _resolve_lookup
    current = current[bit]
KeyError: 'placeholder'

During handling of the above exception, another exception occurred:

Traceback (most recent call last):
  File "/Users/cribbee/Virtualenv/V-ZoomIn/lib/python3.6/site-packages/django/template/base.py", line 843, in _resolve_lookup
    current = getattr(current, bit)
AttributeError: 'dict' object has no attribute 'placeholder'

During handling of the above exception, another exception occurred:

Traceback (most recent call last):
  File "/Users/cribbee/Virtualenv/V-ZoomIn/lib/python3.6/site-packages/django/template/base.py", line 849, in _resolve_lookup
    current = current[int(bit)]
ValueError: invalid literal for int() with base 10: 'placeholder'

During handling of the above exception, another exception occurred:

Traceback (most recent call last):
  File "/Users/cribbee/Virtualenv/V-ZoomIn/lib/python3.6/site-packages/django/template/base.py", line 856, in _resolve_lookup
    (bit, current))  # missing attribute
django.template.base.VariableDoesNotExist: Failed lookup for key [placeholder] in {'base_template': 'input.html', 'input_type': 'text', 'template_pack': 'rest_framework/horizontal', 'renderer': <rest_framework.renderers.HTMLFormRenderer object at 0x113a9deb8>}
Exception while resolving variable 'autofocus' in template 'rest_framework/horizontal/input.html'.
Traceback (most recent call last):
  File "/Users/cribbee/Virtualenv/V-ZoomIn/lib/python3.6/site-packages/django/template/base.py", line 835, in _resolve_lookup
    current = current[bit]
KeyError: 'autofocus'

During handling of the above exception, another exception occurred:

Traceback (most recent call last):
  File "/Users/cribbee/Virtualenv/V-ZoomIn/lib/python3.6/site-packages/django/template/base.py", line 843, in _resolve_lookup
    current = getattr(current, bit)
AttributeError: 'dict' object has no attribute 'autofocus'

During handling of the above exception, another exception occurred:

Traceback (most recent call last):
  File "/Users/cribbee/Virtualenv/V-ZoomIn/lib/python3.6/site-packages/django/template/base.py", line 849, in _resolve_lookup
    current = current[int(bit)]
ValueError: invalid literal for int() with base 10: 'autofocus'

During handling of the above exception, another exception occurred:

Traceback (most recent call last):
  File "/Users/cribbee/Virtualenv/V-ZoomIn/lib/python3.6/site-packages/django/template/base.py", line 856, in _resolve_lookup
    (bit, current))  # missing attribute
django.template.base.VariableDoesNotExist: Failed lookup for key [autofocus] in {'base_template': 'input.html', 'input_type': 'text', 'template_pack': 'rest_framework/horizontal', 'renderer': <rest_framework.renderers.HTMLFormRenderer object at 0x113a9deb8>}
Exception while resolving variable 'hide_label' in template 'rest_framework/horizontal/input.html'.
Traceback (most recent call last):
  File "/Users/cribbee/Virtualenv/V-ZoomIn/lib/python3.6/site-packages/django/template/base.py", line 835, in _resolve_lookup
    current = current[bit]
KeyError: 'hide_label'

During handling of the above exception, another exception occurred:

Traceback (most recent call last):
  File "/Users/cribbee/Virtualenv/V-ZoomIn/lib/python3.6/site-packages/django/template/base.py", line 843, in _resolve_lookup
    current = getattr(current, bit)
AttributeError: 'dict' object has no attribute 'hide_label'

During handling of the above exception, another exception occurred:

Traceback (most recent call last):
  File "/Users/cribbee/Virtualenv/V-ZoomIn/lib/python3.6/site-packages/django/template/base.py", line 849, in _resolve_lookup
    current = current[int(bit)]
ValueError: invalid literal for int() with base 10: 'hide_label'

During handling of the above exception, another exception occurred:

Traceback (most recent call last):
  File "/Users/cribbee/Virtualenv/V-ZoomIn/lib/python3.6/site-packages/django/template/base.py", line 856, in _resolve_lookup
    (bit, current))  # missing attribute
django.template.base.VariableDoesNotExist: Failed lookup for key [hide_label] in {'base_template': 'input.html', 'input_type': 'password', 'template_pack': 'rest_framework/horizontal', 'renderer': <rest_framework.renderers.HTMLFormRenderer object at 0x113a9deb8>}
Exception while resolving variable 'placeholder' in template 'rest_framework/horizontal/input.html'.
Traceback (most recent call last):
  File "/Users/cribbee/Virtualenv/V-ZoomIn/lib/python3.6/site-packages/django/template/base.py", line 835, in _resolve_lookup
    current = current[bit]
KeyError: 'placeholder'

During handling of the above exception, another exception occurred:

Traceback (most recent call last):
  File "/Users/cribbee/Virtualenv/V-ZoomIn/lib/python3.6/site-packages/django/template/base.py", line 843, in _resolve_lookup
    current = getattr(current, bit)
AttributeError: 'dict' object has no attribute 'placeholder'

During handling of the above exception, another exception occurred:

Traceback (most recent call last):
  File "/Users/cribbee/Virtualenv/V-ZoomIn/lib/python3.6/site-packages/django/template/base.py", line 849, in _resolve_lookup
    current = current[int(bit)]
ValueError: invalid literal for int() with base 10: 'placeholder'

During handling of the above exception, another exception occurred:

Traceback (most recent call last):
  File "/Users/cribbee/Virtualenv/V-ZoomIn/lib/python3.6/site-packages/django/template/base.py", line 856, in _resolve_lookup
    (bit, current))  # missing attribute
django.template.base.VariableDoesNotExist: Failed lookup for key [placeholder] in {'base_template': 'input.html', 'input_type': 'password', 'template_pack': 'rest_framework/horizontal', 'renderer': <rest_framework.renderers.HTMLFormRenderer object at 0x113a9deb8>}
Exception while resolving variable 'autofocus' in template 'rest_framework/horizontal/input.html'.
Traceback (most recent call last):
  File "/Users/cribbee/Virtualenv/V-ZoomIn/lib/python3.6/site-packages/django/template/base.py", line 835, in _resolve_lookup
    current = current[bit]
KeyError: 'autofocus'

During handling of the above exception, another exception occurred:

Traceback (most recent call last):
  File "/Users/cribbee/Virtualenv/V-ZoomIn/lib/python3.6/site-packages/django/template/base.py", line 843, in _resolve_lookup
    current = getattr(current, bit)
AttributeError: 'dict' object has no attribute 'autofocus'

During handling of the above exception, another exception occurred:

Traceback (most recent call last):
  File "/Users/cribbee/Virtualenv/V-ZoomIn/lib/python3.6/site-packages/django/template/base.py", line 849, in _resolve_lookup
    current = current[int(bit)]
ValueError: invalid literal for int() with base 10: 'autofocus'

During handling of the above exception, another exception occurred:

Traceback (most recent call last):
  File "/Users/cribbee/Virtualenv/V-ZoomIn/lib/python3.6/site-packages/django/template/base.py", line 856, in _resolve_lookup
    (bit, current))  # missing attribute
django.template.base.VariableDoesNotExist: Failed lookup for key [autofocus] in {'base_template': 'input.html', 'input_type': 'password', 'template_pack': 'rest_framework/horizontal', 'renderer': <rest_framework.renderers.HTMLFormRenderer object at 0x113a9deb8>}
"POST /users/ HTTP/1.1" 201 7803
(0.000) SELECT @@SQL_AUTO_IS_NULL; args=None
(0.000) SET SESSION TRANSACTION ISOLATION LEVEL READ COMMITTED; args=None
(0.000) SELECT VERSION(); args=None
(0.000) SET SESSION TRANSACTION ISOLATION LEVEL READ COMMITTED; args=None
(0.002) SELECT `users_userprofile`.`id`, `users_userprofile`.`password`, `users_userprofile`.`last_login`, `users_userprofile`.`is_superuser`, `users_userprofile`.`username`, `users_userprofile`.`first_name`, `users_userprofile`.`last_name`, `users_userprofile`.`is_staff`, `users_userprofile`.`is_active`, `users_userprofile`.`date_joined`, `users_userprofile`.`name`, `users_userprofile`.`birthday`, `users_userprofile`.`mobile`, `users_userprofile`.`gender`, `users_userprofile`.`email`, `users_userprofile`.`task_num` FROM `users_userprofile` WHERE `users_userprofile`.`username` = 'test12'; args=('test12',)
"POST /usertask/ HTTP/1.1" 400 37
(0.000) SELECT @@SQL_AUTO_IS_NULL; args=None
(0.000) SET SESSION TRANSACTION ISOLATION LEVEL READ COMMITTED; args=None
(0.000) SELECT VERSION(); args=None
(0.000) SET SESSION TRANSACTION ISOLATION LEVEL READ COMMITTED; args=None
(0.001) SELECT `users_userprofile`.`id`, `users_userprofile`.`password`, `users_userprofile`.`last_login`, `users_userprofile`.`is_superuser`, `users_userprofile`.`username`, `users_userprofile`.`first_name`, `users_userprofile`.`last_name`, `users_userprofile`.`is_staff`, `users_userprofile`.`is_active`, `users_userprofile`.`date_joined`, `users_userprofile`.`name`, `users_userprofile`.`birthday`, `users_userprofile`.`mobile`, `users_userprofile`.`gender`, `users_userprofile`.`email`, `users_userprofile`.`task_num` FROM `users_userprofile` WHERE `users_userprofile`.`username` = 'test12'; args=('test12',)
Internal Server Error: /usertask/
Traceback (most recent call last):
  File "/Users/cribbee/Virtualenv/V-ZoomIn/lib/python3.6/site-packages/django/core/handlers/exception.py", line 35, in inner
    response = get_response(request)
  File "/Users/cribbee/Virtualenv/V-ZoomIn/lib/python3.6/site-packages/django/core/handlers/base.py", line 128, in _get_response
    response = self.process_exception_by_middleware(e, request)
  File "/Users/cribbee/Virtualenv/V-ZoomIn/lib/python3.6/site-packages/django/core/handlers/base.py", line 126, in _get_response
    response = wrapped_callback(request, *callback_args, **callback_kwargs)
  File "/Users/cribbee/Virtualenv/V-ZoomIn/lib/python3.6/site-packages/django/views/decorators/csrf.py", line 54, in wrapped_view
    return view_func(*args, **kwargs)
  File "/Users/cribbee/Virtualenv/V-ZoomIn/lib/python3.6/site-packages/rest_framework/viewsets.py", line 103, in view
    return self.dispatch(request, *args, **kwargs)
  File "/Users/cribbee/Virtualenv/V-ZoomIn/lib/python3.6/site-packages/rest_framework/views.py", line 483, in dispatch
    response = self.handle_exception(exc)
  File "/Users/cribbee/Virtualenv/V-ZoomIn/lib/python3.6/site-packages/rest_framework/views.py", line 443, in handle_exception
    self.raise_uncaught_exception(exc)
  File "/Users/cribbee/Virtualenv/V-ZoomIn/lib/python3.6/site-packages/rest_framework/views.py", line 480, in dispatch
    response = handler(request, *args, **kwargs)
  File "/Users/cribbee/Virtualenv/V-ZoomIn/lib/python3.6/site-packages/rest_framework/mixins.py", line 47, in list
    serializer = self.get_serializer(queryset, many=True)
  File "/Users/cribbee/Virtualenv/V-ZoomIn/lib/python3.6/site-packages/rest_framework/generics.py", line 112, in get_serializer
    return serializer_class(*args, **kwargs)
TypeError: 'str' object is not callable
(0.001) SELECT `user_operation_usertask`.`id`, `user_operation_usertask`.`user_id`, `user_operation_usertask`.`tasks_id`, `user_operation_usertask`.`add_time` FROM `user_operation_usertask` WHERE `user_operation_usertask`.`user_id` = 5 LIMIT 21; args=(5,)
(0.000) SELECT `user_operation_usertask`.`id`, `user_operation_usertask`.`user_id`, `user_operation_usertask`.`tasks_id`, `user_operation_usertask`.`add_time` FROM `user_operation_usertask` WHERE `user_operation_usertask`.`user_id` = 5 LIMIT 21; args=(5,)
"GET /usertask/ HTTP/1.1" 500 16520
(0.000) SELECT @@SQL_AUTO_IS_NULL; args=None
(0.000) SET SESSION TRANSACTION ISOLATION LEVEL READ COMMITTED; args=None
(0.000) SELECT VERSION(); args=None
(0.000) SET SESSION TRANSACTION ISOLATION LEVEL READ COMMITTED; args=None
(0.000) SELECT `users_userprofile`.`id`, `users_userprofile`.`password`, `users_userprofile`.`last_login`, `users_userprofile`.`is_superuser`, `users_userprofile`.`username`, `users_userprofile`.`first_name`, `users_userprofile`.`last_name`, `users_userprofile`.`is_staff`, `users_userprofile`.`is_active`, `users_userprofile`.`date_joined`, `users_userprofile`.`name`, `users_userprofile`.`birthday`, `users_userprofile`.`mobile`, `users_userprofile`.`gender`, `users_userprofile`.`email`, `users_userprofile`.`task_num` FROM `users_userprofile` WHERE `users_userprofile`.`username` = 'test12'; args=('test12',)
"POST /usertask/ HTTP/1.1" 400 37
(0.000) SELECT @@SQL_AUTO_IS_NULL; args=None
(0.000) SET SESSION TRANSACTION ISOLATION LEVEL READ COMMITTED; args=None
(0.000) SELECT VERSION(); args=None
(0.000) SET SESSION TRANSACTION ISOLATION LEVEL READ COMMITTED; args=None
(0.000) SELECT `users_userprofile`.`id`, `users_userprofile`.`password`, `users_userprofile`.`last_login`, `users_userprofile`.`is_superuser`, `users_userprofile`.`username`, `users_userprofile`.`first_name`, `users_userprofile`.`last_name`, `users_userprofile`.`is_staff`, `users_userprofile`.`is_active`, `users_userprofile`.`date_joined`, `users_userprofile`.`name`, `users_userprofile`.`birthday`, `users_userprofile`.`mobile`, `users_userprofile`.`gender`, `users_userprofile`.`email`, `users_userprofile`.`task_num` FROM `users_userprofile` WHERE `users_userprofile`.`username` = 'test12'; args=('test12',)
"POST /usertask/ HTTP/1.1" 400 37
(0.000) SELECT @@SQL_AUTO_IS_NULL; args=None
(0.000) SET SESSION TRANSACTION ISOLATION LEVEL READ COMMITTED; args=None
(0.000) SELECT VERSION(); args=None
(0.000) SET SESSION TRANSACTION ISOLATION LEVEL READ COMMITTED; args=None
(0.000) SELECT `users_userprofile`.`id`, `users_userprofile`.`password`, `users_userprofile`.`last_login`, `users_userprofile`.`is_superuser`, `users_userprofile`.`username`, `users_userprofile`.`first_name`, `users_userprofile`.`last_name`, `users_userprofile`.`is_staff`, `users_userprofile`.`is_active`, `users_userprofile`.`date_joined`, `users_userprofile`.`name`, `users_userprofile`.`birthday`, `users_userprofile`.`mobile`, `users_userprofile`.`gender`, `users_userprofile`.`email`, `users_userprofile`.`task_num` FROM `users_userprofile` WHERE `users_userprofile`.`username` = 'test12'; args=('test12',)
"POST /usertask/ HTTP/1.1" 400 62
(0.000) SELECT @@SQL_AUTO_IS_NULL; args=None
(0.000) SET SESSION TRANSACTION ISOLATION LEVEL READ COMMITTED; args=None
(0.000) SELECT VERSION(); args=None
(0.000) SET SESSION TRANSACTION ISOLATION LEVEL READ COMMITTED; args=None
(0.000) SELECT `users_userprofile`.`id`, `users_userprofile`.`password`, `users_userprofile`.`last_login`, `users_userprofile`.`is_superuser`, `users_userprofile`.`username`, `users_userprofile`.`first_name`, `users_userprofile`.`last_name`, `users_userprofile`.`is_staff`, `users_userprofile`.`is_active`, `users_userprofile`.`date_joined`, `users_userprofile`.`name`, `users_userprofile`.`birthday`, `users_userprofile`.`mobile`, `users_userprofile`.`gender`, `users_userprofile`.`email`, `users_userprofile`.`task_num` FROM `users_userprofile` WHERE `users_userprofile`.`username` = 'test12'; args=('test12',)
"POST /usertask/ HTTP/1.1" 400 62
(0.000) SELECT @@SQL_AUTO_IS_NULL; args=None
(0.000) SET SESSION TRANSACTION ISOLATION LEVEL READ COMMITTED; args=None
(0.000) SELECT VERSION(); args=None
(0.000) SET SESSION TRANSACTION ISOLATION LEVEL READ COMMITTED; args=None
(0.002) SELECT `users_userprofile`.`id`, `users_userprofile`.`password`, `users_userprofile`.`last_login`, `users_userprofile`.`is_superuser`, `users_userprofile`.`username`, `users_userprofile`.`first_name`, `users_userprofile`.`last_name`, `users_userprofile`.`is_staff`, `users_userprofile`.`is_active`, `users_userprofile`.`date_joined`, `users_userprofile`.`name`, `users_userprofile`.`birthday`, `users_userprofile`.`mobile`, `users_userprofile`.`gender`, `users_userprofile`.`email`, `users_userprofile`.`task_num` FROM `users_userprofile` WHERE `users_userprofile`.`username` = 'test12'; args=('test12',)
"POST /usertask/ HTTP/1.1" 400 62
(0.000) SELECT @@SQL_AUTO_IS_NULL; args=None
(0.000) SET SESSION TRANSACTION ISOLATION LEVEL READ COMMITTED; args=None
(0.000) SELECT VERSION(); args=None
(0.000) SET SESSION TRANSACTION ISOLATION LEVEL READ COMMITTED; args=None
(0.000) SELECT `users_userprofile`.`id`, `users_userprofile`.`password`, `users_userprofile`.`last_login`, `users_userprofile`.`is_superuser`, `users_userprofile`.`username`, `users_userprofile`.`first_name`, `users_userprofile`.`last_name`, `users_userprofile`.`is_staff`, `users_userprofile`.`is_active`, `users_userprofile`.`date_joined`, `users_userprofile`.`name`, `users_userprofile`.`birthday`, `users_userprofile`.`mobile`, `users_userprofile`.`gender`, `users_userprofile`.`email`, `users_userprofile`.`task_num` FROM `users_userprofile` WHERE `users_userprofile`.`username` = 'test12'; args=('test12',)
"POST /usertask/ HTTP/1.1" 400 37
11111111111111111111

(0.000) SELECT @@SQL_AUTO_IS_NULL; args=None
(0.000) SET SESSION TRANSACTION ISOLATION LEVEL READ COMMITTED; args=None
(0.000) SELECT VERSION(); args=None
(0.000) SET SESSION TRANSACTION ISOLATION LEVEL READ COMMITTED; args=None
(0.009) SHOW FULL TABLES; args=None
(0.002) SELECT `django_migrations`.`app`, `django_migrations`.`name` FROM `django_migrations`; args=()
(0.000) SELECT @@SQL_AUTO_IS_NULL; args=None
(0.000) SET SESSION TRANSACTION ISOLATION LEVEL READ COMMITTED; args=None
(0.000) SELECT VERSION(); args=None
(0.000) SET SESSION TRANSACTION ISOLATION LEVEL READ COMMITTED; args=None
(0.001) SELECT `users_userprofile`.`id`, `users_userprofile`.`password`, `users_userprofile`.`last_login`, `users_userprofile`.`is_superuser`, `users_userprofile`.`username`, `users_userprofile`.`first_name`, `users_userprofile`.`last_name`, `users_userprofile`.`is_staff`, `users_userprofile`.`is_active`, `users_userprofile`.`date_joined`, `users_userprofile`.`name`, `users_userprofile`.`birthday`, `users_userprofile`.`mobile`, `users_userprofile`.`gender`, `users_userprofile`.`email`, `users_userprofile`.`task_num` FROM `users_userprofile` WHERE `users_userprofile`.`username` = 'test12'; args=('test12',)
(0.001) SELECT `tasks_taskinfo`.`id`, `tasks_taskinfo`.`user_id`, `tasks_taskinfo`.`task_name`, `tasks_taskinfo`.`data_num`, `tasks_taskinfo`.`state_type`, `tasks_taskinfo`.`add_time` FROM `tasks_taskinfo` WHERE `tasks_taskinfo`.`id` = 1; args=(1,)
(0.000) SELECT (1) AS `a` FROM `user_operation_usertask` WHERE (`user_operation_usertask`.`tasks_id` = 1 AND `user_operation_usertask`.`user_id` = 5) LIMIT 1; args=(1, 5)
"POST /usertask/ HTTP/1.1" 400 49
