Internal Server Error: /task/chart/sum
Traceback (most recent call last):
  File "/home/V-ZoomIn/lib/python3.6/site-packages/django/core/handlers/exception.py", line 35, in inner
    response = get_response(request)
  File "/home/V-ZoomIn/lib/python3.6/site-packages/django/core/handlers/base.py", line 128, in _get_response
    response = self.process_exception_by_middleware(e, request)
  File "/home/V-ZoomIn/lib/python3.6/site-packages/django/core/handlers/base.py", line 126, in _get_response
    response = wrapped_callback(request, *callback_args, **callback_kwargs)
  File "/home/V-ZoomIn/lib/python3.6/site-packages/django/views/decorators/csrf.py", line 54, in wrapped_view
    return view_func(*args, **kwargs)
  File "/home/V-ZoomIn/lib/python3.6/site-packages/django/views/generic/base.py", line 69, in view
    return self.dispatch(request, *args, **kwargs)
  File "/home/V-ZoomIn/lib/python3.6/site-packages/rest_framework/views.py", line 483, in dispatch
    response = self.handle_exception(exc)
  File "/home/V-ZoomIn/lib/python3.6/site-packages/rest_framework/views.py", line 443, in handle_exception
    self.raise_uncaught_exception(exc)
  File "/home/V-ZoomIn/lib/python3.6/site-packages/rest_framework/views.py", line 480, in dispatch
    response = handler(request, *args, **kwargs)
  File "/home/V-ZoomIn/lib/python3.6/site-packages/rest_framework/decorators.py", line 53, in handler
    return func(*args, **kwargs)
  File "/home/ZoomInDev/apps/tasks/views.py", line 421, in sum_analysis
    chart_type=request.data['chart_type'], x_axis=request.data['x_axis'], y_axis=request.data['y_axis'])
  File "/home/ZoomInDev/db_tools/dataAnalyze.py", line 26, in chart_sum
    df = df.groupby(x_axis)[y_axis].sum()
  File "/home/V-ZoomIn/lib/python3.6/site-packages/pandas/core/generic.py", line 6659, in groupby
    observed=observed, **kwargs)
  File "/home/V-ZoomIn/lib/python3.6/site-packages/pandas/core/groupby/groupby.py", line 2152, in groupby
    return klass(obj, by, **kwds)
  File "/home/V-ZoomIn/lib/python3.6/site-packages/pandas/core/groupby/groupby.py", line 599, in __init__
    mutated=self.mutated)
  File "/home/V-ZoomIn/lib/python3.6/site-packages/pandas/core/groupby/groupby.py", line 3291, in _get_grouper
    raise KeyError(gpr)
KeyError: '性别_x'
"POST /task/chart/sum HTTP/1.1" 500 17339
"POST /login/ HTTP/1.1" 200 173
"OPTIONS /taskinfo/ HTTP/1.1" 200 0
"OPTIONS /taskinfo/ HTTP/1.1" 200 0
"GET /taskinfo/ HTTP/1.1" 200 1447
"GET /taskinfo/ HTTP/1.1" 200 1447
"OPTIONS /task/dataProcessing/showDataSet1 HTTP/1.1" 200 0
"OPTIONS /chart/ HTTP/1.1" 200 0
"OPTIONS /task/chart/sum HTTP/1.1" 200 0
"OPTIONS /chart/ HTTP/1.1" 200 0
"POST /chart/ HTTP/1.1" 400 49
Internal Server Error: /task/chart/sum
Traceback (most recent call last):
  File "/home/V-ZoomIn/lib/python3.6/site-packages/django/core/handlers/exception.py", line 35, in inner
    response = get_response(request)
  File "/home/V-ZoomIn/lib/python3.6/site-packages/django/core/handlers/base.py", line 128, in _get_response
    response = self.process_exception_by_middleware(e, request)
  File "/home/V-ZoomIn/lib/python3.6/site-packages/django/core/handlers/base.py", line 126, in _get_response
    response = wrapped_callback(request, *callback_args, **callback_kwargs)
  File "/home/V-ZoomIn/lib/python3.6/site-packages/django/views/decorators/csrf.py", line 54, in wrapped_view
    return view_func(*args, **kwargs)
  File "/home/V-ZoomIn/lib/python3.6/site-packages/django/views/generic/base.py", line 69, in view
    return self.dispatch(request, *args, **kwargs)
  File "/home/V-ZoomIn/lib/python3.6/site-packages/rest_framework/views.py", line 483, in dispatch
    response = self.handle_exception(exc)
  File "/home/V-ZoomIn/lib/python3.6/site-packages/rest_framework/views.py", line 443, in handle_exception
    self.raise_uncaught_exception(exc)
  File "/home/V-ZoomIn/lib/python3.6/site-packages/rest_framework/views.py", line 480, in dispatch
    response = handler(request, *args, **kwargs)
  File "/home/V-ZoomIn/lib/python3.6/site-packages/rest_framework/decorators.py", line 53, in handler
    return func(*args, **kwargs)
  File "/home/ZoomInDev/apps/tasks/views.py", line 421, in sum_analysis
    chart_type=request.data['chart_type'], x_axis=request.data['x_axis'], y_axis=request.data['y_axis'])
  File "/home/ZoomInDev/db_tools/dataAnalyze.py", line 26, in chart_sum
    df = df.groupby(x_axis)[y_axis].sum()
  File "/home/V-ZoomIn/lib/python3.6/site-packages/pandas/core/generic.py", line 6659, in groupby
    observed=observed, **kwargs)
  File "/home/V-ZoomIn/lib/python3.6/site-packages/pandas/core/groupby/groupby.py", line 2152, in groupby
    return klass(obj, by, **kwds)
  File "/home/V-ZoomIn/lib/python3.6/site-packages/pandas/core/groupby/groupby.py", line 599, in __init__
    mutated=self.mutated)
  File "/home/V-ZoomIn/lib/python3.6/site-packages/pandas/core/groupby/groupby.py", line 3291, in _get_grouper
    raise KeyError(gpr)
KeyError: '性别_x'
"POST /task/chart/sum HTTP/1.1" 500 17514
"POST /task/dataProcessing/showDataSet1 HTTP/1.1" 200 470109
"GET /chart/ HTTP/1.1" 200 1108
Internal Server Error: /task/chart/sum
Traceback (most recent call last):
  File "/home/V-ZoomIn/lib/python3.6/site-packages/django/core/handlers/exception.py", line 35, in inner
    response = get_response(request)
  File "/home/V-ZoomIn/lib/python3.6/site-packages/django/core/handlers/base.py", line 128, in _get_response
    response = self.process_exception_by_middleware(e, request)
  File "/home/V-ZoomIn/lib/python3.6/site-packages/django/core/handlers/base.py", line 126, in _get_response
    response = wrapped_callback(request, *callback_args, **callback_kwargs)
  File "/home/V-ZoomIn/lib/python3.6/site-packages/django/views/decorators/csrf.py", line 54, in wrapped_view
    return view_func(*args, **kwargs)
  File "/home/V-ZoomIn/lib/python3.6/site-packages/django/views/generic/base.py", line 69, in view
    return self.dispatch(request, *args, **kwargs)
  File "/home/V-ZoomIn/lib/python3.6/site-packages/rest_framework/views.py", line 483, in dispatch
    response = self.handle_exception(exc)
  File "/home/V-ZoomIn/lib/python3.6/site-packages/rest_framework/views.py", line 443, in handle_exception
    self.raise_uncaught_exception(exc)
  File "/home/V-ZoomIn/lib/python3.6/site-packages/rest_framework/views.py", line 480, in dispatch
    response = handler(request, *args, **kwargs)
  File "/home/V-ZoomIn/lib/python3.6/site-packages/rest_framework/decorators.py", line 53, in handler
    return func(*args, **kwargs)
  File "/home/ZoomInDev/apps/tasks/views.py", line 421, in sum_analysis
    chart_type=request.data['chart_type'], x_axis=request.data['x_axis'], y_axis=request.data['y_axis'])
  File "/home/ZoomInDev/db_tools/dataAnalyze.py", line 26, in chart_sum
    df = df.groupby(x_axis)[y_axis].sum()
  File "/home/V-ZoomIn/lib/python3.6/site-packages/pandas/core/generic.py", line 6659, in groupby
    observed=observed, **kwargs)
  File "/home/V-ZoomIn/lib/python3.6/site-packages/pandas/core/groupby/groupby.py", line 2152, in groupby
    return klass(obj, by, **kwds)
  File "/home/V-ZoomIn/lib/python3.6/site-packages/pandas/core/groupby/groupby.py", line 599, in __init__
    mutated=self.mutated)
  File "/home/V-ZoomIn/lib/python3.6/site-packages/pandas/core/groupby/groupby.py", line 3291, in _get_grouper
    raise KeyError(gpr)
KeyError: '性别_x，考生号'
"POST /task/chart/sum HTTP/1.1" 500 17537
"POST /task/dataProcessing/showDataSet1 HTTP/1.1" 200 470109
"GET /chart/ HTTP/1.1" 200 1108
"POST /chart/ HTTP/1.1" 400 49
Internal Server Error: /task/chart/sum
Traceback (most recent call last):
  File "/home/V-ZoomIn/lib/python3.6/site-packages/django/core/handlers/exception.py", line 35, in inner
    response = get_response(request)
  File "/home/V-ZoomIn/lib/python3.6/site-packages/django/core/handlers/base.py", line 128, in _get_response
    response = self.process_exception_by_middleware(e, request)
  File "/home/V-ZoomIn/lib/python3.6/site-packages/django/core/handlers/base.py", line 126, in _get_response
    response = wrapped_callback(request, *callback_args, **callback_kwargs)
  File "/home/V-ZoomIn/lib/python3.6/site-packages/django/views/decorators/csrf.py", line 54, in wrapped_view
    return view_func(*args, **kwargs)
  File "/home/V-ZoomIn/lib/python3.6/site-packages/django/views/generic/base.py", line 69, in view
    return self.dispatch(request, *args, **kwargs)
  File "/home/V-ZoomIn/lib/python3.6/site-packages/rest_framework/views.py", line 483, in dispatch
    response = self.handle_exception(exc)
  File "/home/V-ZoomIn/lib/python3.6/site-packages/rest_framework/views.py", line 443, in handle_exception
    self.raise_uncaught_exception(exc)
  File "/home/V-ZoomIn/lib/python3.6/site-packages/rest_framework/views.py", line 480, in dispatch
    response = handler(request, *args, **kwargs)
  File "/home/V-ZoomIn/lib/python3.6/site-packages/rest_framework/decorators.py", line 53, in handler
    return func(*args, **kwargs)
  File "/home/ZoomInDev/apps/tasks/views.py", line 421, in sum_analysis
    chart_type=request.data['chart_type'], x_axis=request.data['x_axis'], y_axis=request.data['y_axis'])
  File "/home/ZoomInDev/db_tools/dataAnalyze.py", line 26, in chart_sum
    df = df.groupby(x_axis)[y_axis].sum()
  File "/home/V-ZoomIn/lib/python3.6/site-packages/pandas/core/generic.py", line 6659, in groupby
    observed=observed, **kwargs)
  File "/home/V-ZoomIn/lib/python3.6/site-packages/pandas/core/groupby/groupby.py", line 2152, in groupby
    return klass(obj, by, **kwds)
  File "/home/V-ZoomIn/lib/python3.6/site-packages/pandas/core/groupby/groupby.py", line 599, in __init__
    mutated=self.mutated)
  File "/home/V-ZoomIn/lib/python3.6/site-packages/pandas/core/groupby/groupby.py", line 3291, in _get_grouper
    raise KeyError(gpr)
KeyError: '性别_x，考生号'
"POST /task/chart/sum HTTP/1.1" 500 17570
"POST /task/dataProcessing/showDataSet1 HTTP/1.1" 200 470109
"POST /chart/ HTTP/1.1" 400 49
"GET /chart/ HTTP/1.1" 200 1108
Internal Server Error: /task/chart/sum
Traceback (most recent call last):
  File "/home/V-ZoomIn/lib/python3.6/site-packages/django/core/handlers/exception.py", line 35, in inner
    response = get_response(request)
  File "/home/V-ZoomIn/lib/python3.6/site-packages/django/core/handlers/base.py", line 128, in _get_response
    response = self.process_exception_by_middleware(e, request)
  File "/home/V-ZoomIn/lib/python3.6/site-packages/django/core/handlers/base.py", line 126, in _get_response
    response = wrapped_callback(request, *callback_args, **callback_kwargs)
  File "/home/V-ZoomIn/lib/python3.6/site-packages/django/views/decorators/csrf.py", line 54, in wrapped_view
    return view_func(*args, **kwargs)
  File "/home/V-ZoomIn/lib/python3.6/site-packages/django/views/generic/base.py", line 69, in view
    return self.dispatch(request, *args, **kwargs)
  File "/home/V-ZoomIn/lib/python3.6/site-packages/rest_framework/views.py", line 483, in dispatch
    response = self.handle_exception(exc)
  File "/home/V-ZoomIn/lib/python3.6/site-packages/rest_framework/views.py", line 443, in handle_exception
    self.raise_uncaught_exception(exc)
  File "/home/V-ZoomIn/lib/python3.6/site-packages/rest_framework/views.py", line 480, in dispatch
    response = handler(request, *args, **kwargs)
  File "/home/V-ZoomIn/lib/python3.6/site-packages/rest_framework/decorators.py", line 53, in handler
    return func(*args, **kwargs)
  File "/home/ZoomInDev/apps/tasks/views.py", line 418, in sum_analysis
    data_set = DataSet.objects.get(id=request.data['data_set'])
  File "/home/V-ZoomIn/lib/python3.6/site-packages/django/db/models/manager.py", line 82, in manager_method
    return getattr(self.get_queryset(), name)(*args, **kwargs)
  File "/home/V-ZoomIn/lib/python3.6/site-packages/django/db/models/query.py", line 403, in get
    self.model._meta.object_name
tasks.models.DoesNotExist: DataSet matching query does not exist.
"POST /task/chart/sum HTTP/1.1" 500 17133
"GET /chart/ HTTP/1.1" 200 1108
"POST /chart/ HTTP/1.1" 400 49
"POST /task/dataProcessing/showDataSet1 HTTP/1.1" 200 470109
"POST /chart/ HTTP/1.1" 400 49
Internal Server Error: /task/chart/sum
Traceback (most recent call last):
  File "/home/V-ZoomIn/lib/python3.6/site-packages/django/core/handlers/exception.py", line 35, in inner
    response = get_response(request)
  File "/home/V-ZoomIn/lib/python3.6/site-packages/django/core/handlers/base.py", line 128, in _get_response
    response = self.process_exception_by_middleware(e, request)
  File "/home/V-ZoomIn/lib/python3.6/site-packages/django/core/handlers/base.py", line 126, in _get_response
    response = wrapped_callback(request, *callback_args, **callback_kwargs)
  File "/home/V-ZoomIn/lib/python3.6/site-packages/django/views/decorators/csrf.py", line 54, in wrapped_view
    return view_func(*args, **kwargs)
  File "/home/V-ZoomIn/lib/python3.6/site-packages/django/views/generic/base.py", line 69, in view
    return self.dispatch(request, *args, **kwargs)
  File "/home/V-ZoomIn/lib/python3.6/site-packages/rest_framework/views.py", line 483, in dispatch
    response = self.handle_exception(exc)
  File "/home/V-ZoomIn/lib/python3.6/site-packages/rest_framework/views.py", line 443, in handle_exception
    self.raise_uncaught_exception(exc)
  File "/home/V-ZoomIn/lib/python3.6/site-packages/rest_framework/views.py", line 480, in dispatch
    response = handler(request, *args, **kwargs)
  File "/home/V-ZoomIn/lib/python3.6/site-packages/rest_framework/decorators.py", line 53, in handler
    return func(*args, **kwargs)
  File "/home/ZoomInDev/apps/tasks/views.py", line 418, in sum_analysis
    data_set = DataSet.objects.get(id=request.data['data_set'])
  File "/home/V-ZoomIn/lib/python3.6/site-packages/django/db/models/manager.py", line 82, in manager_method
    return getattr(self.get_queryset(), name)(*args, **kwargs)
  File "/home/V-ZoomIn/lib/python3.6/site-packages/django/db/models/query.py", line 403, in get
    self.model._meta.object_name
tasks.models.DoesNotExist: DataSet matching query does not exist.
"POST /task/chart/sum HTTP/1.1" 500 17167
"GET /chart/ HTTP/1.1" 200 1108
"POST /task/dataProcessing/showDataSet1 HTTP/1.1" 200 470109
"OPTIONS /task/dataProcessing/showDataSet1 HTTP/1.1" 200 0
"OPTIONS /task/chart/sum HTTP/1.1" 200 0
"OPTIONS /chart/ HTTP/1.1" 200 0
"OPTIONS /chart/ HTTP/1.1" 200 0
Internal Server Error: /task/chart/sum
Traceback (most recent call last):
  File "/home/V-ZoomIn/lib/python3.6/site-packages/django/core/handlers/exception.py", line 35, in inner
    response = get_response(request)
  File "/home/V-ZoomIn/lib/python3.6/site-packages/django/core/handlers/base.py", line 128, in _get_response
    response = self.process_exception_by_middleware(e, request)
  File "/home/V-ZoomIn/lib/python3.6/site-packages/django/core/handlers/base.py", line 126, in _get_response
    response = wrapped_callback(request, *callback_args, **callback_kwargs)
  File "/home/V-ZoomIn/lib/python3.6/site-packages/django/views/decorators/csrf.py", line 54, in wrapped_view
    return view_func(*args, **kwargs)
  File "/home/V-ZoomIn/lib/python3.6/site-packages/django/views/generic/base.py", line 69, in view
    return self.dispatch(request, *args, **kwargs)
  File "/home/V-ZoomIn/lib/python3.6/site-packages/rest_framework/views.py", line 483, in dispatch
    response = self.handle_exception(exc)
  File "/home/V-ZoomIn/lib/python3.6/site-packages/rest_framework/views.py", line 443, in handle_exception
    self.raise_uncaught_exception(exc)
  File "/home/V-ZoomIn/lib/python3.6/site-packages/rest_framework/views.py", line 480, in dispatch
    response = handler(request, *args, **kwargs)
  File "/home/V-ZoomIn/lib/python3.6/site-packages/rest_framework/decorators.py", line 53, in handler
    return func(*args, **kwargs)
  File "/home/ZoomInDev/apps/tasks/views.py", line 418, in sum_analysis
    data_set = DataSet.objects.get(id=request.data['data_set'])
  File "/home/V-ZoomIn/lib/python3.6/site-packages/django/db/models/manager.py", line 82, in manager_method
    return getattr(self.get_queryset(), name)(*args, **kwargs)
  File "/home/V-ZoomIn/lib/python3.6/site-packages/django/db/models/query.py", line 403, in get
    self.model._meta.object_name
tasks.models.DoesNotExist: DataSet matching query does not exist.
"POST /task/chart/sum HTTP/1.1" 500 17133
"POST /task/dataProcessing/showDataSet1 HTTP/1.1" 200 470109
"POST /chart/ HTTP/1.1" 400 49
"GET /chart/ HTTP/1.1" 200 1108
Internal Server Error: /task/chart/sum
Traceback (most recent call last):
  File "/home/V-ZoomIn/lib/python3.6/site-packages/django/core/handlers/exception.py", line 35, in inner
    response = get_response(request)
  File "/home/V-ZoomIn/lib/python3.6/site-packages/django/core/handlers/base.py", line 128, in _get_response
    response = self.process_exception_by_middleware(e, request)
  File "/home/V-ZoomIn/lib/python3.6/site-packages/django/core/handlers/base.py", line 126, in _get_response
    response = wrapped_callback(request, *callback_args, **callback_kwargs)
  File "/home/V-ZoomIn/lib/python3.6/site-packages/django/views/decorators/csrf.py", line 54, in wrapped_view
    return view_func(*args, **kwargs)
  File "/home/V-ZoomIn/lib/python3.6/site-packages/django/views/generic/base.py", line 69, in view
    return self.dispatch(request, *args, **kwargs)
  File "/home/V-ZoomIn/lib/python3.6/site-packages/rest_framework/views.py", line 483, in dispatch
    response = self.handle_exception(exc)
  File "/home/V-ZoomIn/lib/python3.6/site-packages/rest_framework/views.py", line 443, in handle_exception
    self.raise_uncaught_exception(exc)
  File "/home/V-ZoomIn/lib/python3.6/site-packages/rest_framework/views.py", line 480, in dispatch
    response = handler(request, *args, **kwargs)
  File "/home/V-ZoomIn/lib/python3.6/site-packages/rest_framework/decorators.py", line 53, in handler
    return func(*args, **kwargs)
  File "/home/ZoomInDev/apps/tasks/views.py", line 418, in sum_analysis
    data_set = DataSet.objects.get(id=request.data['data_set'])
  File "/home/V-ZoomIn/lib/python3.6/site-packages/django/db/models/manager.py", line 82, in manager_method
    return getattr(self.get_queryset(), name)(*args, **kwargs)
  File "/home/V-ZoomIn/lib/python3.6/site-packages/django/db/models/query.py", line 403, in get
    self.model._meta.object_name
tasks.models.DoesNotExist: DataSet matching query does not exist.
"POST /task/chart/sum HTTP/1.1" 500 17166
"POST /task/dataProcessing/showDataSet1 HTTP/1.1" 200 470109
"POST /chart/ HTTP/1.1" 400 49
"GET /chart/ HTTP/1.1" 200 1108
Internal Server Error: /task/chart/sum
Traceback (most recent call last):
  File "/home/V-ZoomIn/lib/python3.6/site-packages/django/core/handlers/exception.py", line 35, in inner
    response = get_response(request)
  File "/home/V-ZoomIn/lib/python3.6/site-packages/django/core/handlers/base.py", line 128, in _get_response
    response = self.process_exception_by_middleware(e, request)
  File "/home/V-ZoomIn/lib/python3.6/site-packages/django/core/handlers/base.py", line 126, in _get_response
    response = wrapped_callback(request, *callback_args, **callback_kwargs)
  File "/home/V-ZoomIn/lib/python3.6/site-packages/django/views/decorators/csrf.py", line 54, in wrapped_view
    return view_func(*args, **kwargs)
  File "/home/V-ZoomIn/lib/python3.6/site-packages/django/views/generic/base.py", line 69, in view
    return self.dispatch(request, *args, **kwargs)
  File "/home/V-ZoomIn/lib/python3.6/site-packages/rest_framework/views.py", line 483, in dispatch
    response = self.handle_exception(exc)
  File "/home/V-ZoomIn/lib/python3.6/site-packages/rest_framework/views.py", line 443, in handle_exception
    self.raise_uncaught_exception(exc)
  File "/home/V-ZoomIn/lib/python3.6/site-packages/rest_framework/views.py", line 480, in dispatch
    response = handler(request, *args, **kwargs)
  File "/home/V-ZoomIn/lib/python3.6/site-packages/rest_framework/decorators.py", line 53, in handler
    return func(*args, **kwargs)
  File "/home/ZoomInDev/apps/tasks/views.py", line 418, in sum_analysis
    data_set = DataSet.objects.get(id=request.data['data_set'])
  File "/home/V-ZoomIn/lib/python3.6/site-packages/django/db/models/manager.py", line 82, in manager_method
    return getattr(self.get_queryset(), name)(*args, **kwargs)
  File "/home/V-ZoomIn/lib/python3.6/site-packages/django/db/models/query.py", line 403, in get
    self.model._meta.object_name
tasks.models.DoesNotExist: DataSet matching query does not exist.
"GET /chart/ HTTP/1.1" 200 1108
"POST /task/chart/sum HTTP/1.1" 500 17133
"POST /chart/ HTTP/1.1" 400 49
"POST /task/dataProcessing/showDataSet1 HTTP/1.1" 200 470109
Internal Server Error: /task/chart/sum
Traceback (most recent call last):
  File "/home/V-ZoomIn/lib/python3.6/site-packages/django/core/handlers/exception.py", line 35, in inner
    response = get_response(request)
  File "/home/V-ZoomIn/lib/python3.6/site-packages/django/core/handlers/base.py", line 128, in _get_response
    response = self.process_exception_by_middleware(e, request)
  File "/home/V-ZoomIn/lib/python3.6/site-packages/django/core/handlers/base.py", line 126, in _get_response
    response = wrapped_callback(request, *callback_args, **callback_kwargs)
  File "/home/V-ZoomIn/lib/python3.6/site-packages/django/views/decorators/csrf.py", line 54, in wrapped_view
    return view_func(*args, **kwargs)
  File "/home/V-ZoomIn/lib/python3.6/site-packages/django/views/generic/base.py", line 69, in view
    return self.dispatch(request, *args, **kwargs)
  File "/home/V-ZoomIn/lib/python3.6/site-packages/rest_framework/views.py", line 483, in dispatch
    response = self.handle_exception(exc)
  File "/home/V-ZoomIn/lib/python3.6/site-packages/rest_framework/views.py", line 443, in handle_exception
    self.raise_uncaught_exception(exc)
  File "/home/V-ZoomIn/lib/python3.6/site-packages/rest_framework/views.py", line 480, in dispatch
    response = handler(request, *args, **kwargs)
  File "/home/V-ZoomIn/lib/python3.6/site-packages/rest_framework/decorators.py", line 53, in handler
    return func(*args, **kwargs)
  File "/home/ZoomInDev/apps/tasks/views.py", line 418, in sum_analysis
    data_set = DataSet.objects.get(id=request.data['data_set'])
  File "/home/V-ZoomIn/lib/python3.6/site-packages/django/db/models/manager.py", line 82, in manager_method
    return getattr(self.get_queryset(), name)(*args, **kwargs)
  File "/home/V-ZoomIn/lib/python3.6/site-packages/django/db/models/query.py", line 403, in get
    self.model._meta.object_name
tasks.models.DoesNotExist: DataSet matching query does not exist.
"POST /task/chart/sum HTTP/1.1" 500 17166
"GET /chart/ HTTP/1.1" 200 1108
"POST /chart/ HTTP/1.1" 400 49
"POST /task/dataProcessing/showDataSet1 HTTP/1.1" 200 470109
Internal Server Error: /task/chart/sum
Traceback (most recent call last):
  File "/home/V-ZoomIn/lib/python3.6/site-packages/django/core/handlers/exception.py", line 35, in inner
    response = get_response(request)
  File "/home/V-ZoomIn/lib/python3.6/site-packages/django/core/handlers/base.py", line 128, in _get_response
    response = self.process_exception_by_middleware(e, request)
  File "/home/V-ZoomIn/lib/python3.6/site-packages/django/core/handlers/base.py", line 126, in _get_response
    response = wrapped_callback(request, *callback_args, **callback_kwargs)
  File "/home/V-ZoomIn/lib/python3.6/site-packages/django/views/decorators/csrf.py", line 54, in wrapped_view
    return view_func(*args, **kwargs)
  File "/home/V-ZoomIn/lib/python3.6/site-packages/django/views/generic/base.py", line 69, in view
    return self.dispatch(request, *args, **kwargs)
  File "/home/V-ZoomIn/lib/python3.6/site-packages/rest_framework/views.py", line 483, in dispatch
    response = self.handle_exception(exc)
  File "/home/V-ZoomIn/lib/python3.6/site-packages/rest_framework/views.py", line 443, in handle_exception
    self.raise_uncaught_exception(exc)
  File "/home/V-ZoomIn/lib/python3.6/site-packages/rest_framework/views.py", line 480, in dispatch
    response = handler(request, *args, **kwargs)
  File "/home/V-ZoomIn/lib/python3.6/site-packages/rest_framework/decorators.py", line 53, in handler
    return func(*args, **kwargs)
  File "/home/ZoomInDev/apps/tasks/views.py", line 418, in sum_analysis
    data_set = DataSet.objects.get(id=request.data['data_set'])
  File "/home/V-ZoomIn/lib/python3.6/site-packages/django/db/models/manager.py", line 82, in manager_method
    return getattr(self.get_queryset(), name)(*args, **kwargs)
  File "/home/V-ZoomIn/lib/python3.6/site-packages/django/db/models/query.py", line 403, in get
    self.model._meta.object_name
tasks.models.DoesNotExist: DataSet matching query does not exist.
"POST /task/chart/sum HTTP/1.1" 500 17133
"POST /chart/ HTTP/1.1" 400 49
"GET /chart/ HTTP/1.1" 200 1108
"POST /task/dataProcessing/showDataSet1 HTTP/1.1" 200 470109
Internal Server Error: /task/chart/sum
Traceback (most recent call last):
  File "/home/V-ZoomIn/lib/python3.6/site-packages/django/core/handlers/exception.py", line 35, in inner
    response = get_response(request)
  File "/home/V-ZoomIn/lib/python3.6/site-packages/django/core/handlers/base.py", line 128, in _get_response
    response = self.process_exception_by_middleware(e, request)
  File "/home/V-ZoomIn/lib/python3.6/site-packages/django/core/handlers/base.py", line 126, in _get_response
    response = wrapped_callback(request, *callback_args, **callback_kwargs)
  File "/home/V-ZoomIn/lib/python3.6/site-packages/django/views/decorators/csrf.py", line 54, in wrapped_view
    return view_func(*args, **kwargs)
  File "/home/V-ZoomIn/lib/python3.6/site-packages/django/views/generic/base.py", line 69, in view
    return self.dispatch(request, *args, **kwargs)
  File "/home/V-ZoomIn/lib/python3.6/site-packages/rest_framework/views.py", line 483, in dispatch
    response = self.handle_exception(exc)
  File "/home/V-ZoomIn/lib/python3.6/site-packages/rest_framework/views.py", line 443, in handle_exception
    self.raise_uncaught_exception(exc)
  File "/home/V-ZoomIn/lib/python3.6/site-packages/rest_framework/views.py", line 480, in dispatch
    response = handler(request, *args, **kwargs)
  File "/home/V-ZoomIn/lib/python3.6/site-packages/rest_framework/decorators.py", line 53, in handler
    return func(*args, **kwargs)
  File "/home/ZoomInDev/apps/tasks/views.py", line 418, in sum_analysis
    data_set = DataSet.objects.get(id=request.data['data_set'])
  File "/home/V-ZoomIn/lib/python3.6/site-packages/django/db/models/manager.py", line 82, in manager_method
    return getattr(self.get_queryset(), name)(*args, **kwargs)
  File "/home/V-ZoomIn/lib/python3.6/site-packages/django/db/models/query.py", line 403, in get
    self.model._meta.object_name
tasks.models.DoesNotExist: DataSet matching query does not exist.
"POST /task/chart/sum HTTP/1.1" 500 17133
"POST /chart/ HTTP/1.1" 400 49
"GET /chart/ HTTP/1.1" 200 1108
"POST /task/dataProcessing/showDataSet1 HTTP/1.1" 200 470109
Internal Server Error: /task/chart/sum
Traceback (most recent call last):
  File "/home/V-ZoomIn/lib/python3.6/site-packages/django/core/handlers/exception.py", line 35, in inner
    response = get_response(request)
  File "/home/V-ZoomIn/lib/python3.6/site-packages/django/core/handlers/base.py", line 128, in _get_response
    response = self.process_exception_by_middleware(e, request)
  File "/home/V-ZoomIn/lib/python3.6/site-packages/django/core/handlers/base.py", line 126, in _get_response
    response = wrapped_callback(request, *callback_args, **callback_kwargs)
  File "/home/V-ZoomIn/lib/python3.6/site-packages/django/views/decorators/csrf.py", line 54, in wrapped_view
    return view_func(*args, **kwargs)
  File "/home/V-ZoomIn/lib/python3.6/site-packages/django/views/generic/base.py", line 69, in view
    return self.dispatch(request, *args, **kwargs)
  File "/home/V-ZoomIn/lib/python3.6/site-packages/rest_framework/views.py", line 483, in dispatch
    response = self.handle_exception(exc)
  File "/home/V-ZoomIn/lib/python3.6/site-packages/rest_framework/views.py", line 443, in handle_exception
    self.raise_uncaught_exception(exc)
  File "/home/V-ZoomIn/lib/python3.6/site-packages/rest_framework/views.py", line 480, in dispatch
    response = handler(request, *args, **kwargs)
  File "/home/V-ZoomIn/lib/python3.6/site-packages/rest_framework/decorators.py", line 53, in handler
    return func(*args, **kwargs)
  File "/home/ZoomInDev/apps/tasks/views.py", line 418, in sum_analysis
    data_set = DataSet.objects.get(id=request.data['data_set'])
  File "/home/V-ZoomIn/lib/python3.6/site-packages/django/db/models/manager.py", line 82, in manager_method
    return getattr(self.get_queryset(), name)(*args, **kwargs)
  File "/home/V-ZoomIn/lib/python3.6/site-packages/django/db/models/query.py", line 403, in get
    self.model._meta.object_name
tasks.models.DoesNotExist: DataSet matching query does not exist.
"POST /task/chart/sum HTTP/1.1" 500 17133
"POST /chart/ HTTP/1.1" 400 49
"GET /chart/ HTTP/1.1" 200 1108
"POST /task/dataProcessing/showDataSet1 HTTP/1.1" 200 470109
Internal Server Error: /task/chart/sum
Traceback (most recent call last):
  File "/home/V-ZoomIn/lib/python3.6/site-packages/django/core/handlers/exception.py", line 35, in inner
    response = get_response(request)
  File "/home/V-ZoomIn/lib/python3.6/site-packages/django/core/handlers/base.py", line 128, in _get_response
    response = self.process_exception_by_middleware(e, request)
  File "/home/V-ZoomIn/lib/python3.6/site-packages/django/core/handlers/base.py", line 126, in _get_response
    response = wrapped_callback(request, *callback_args, **callback_kwargs)
  File "/home/V-ZoomIn/lib/python3.6/site-packages/django/views/decorators/csrf.py", line 54, in wrapped_view
    return view_func(*args, **kwargs)
  File "/home/V-ZoomIn/lib/python3.6/site-packages/django/views/generic/base.py", line 69, in view
    return self.dispatch(request, *args, **kwargs)
  File "/home/V-ZoomIn/lib/python3.6/site-packages/rest_framework/views.py", line 483, in dispatch
    response = self.handle_exception(exc)
  File "/home/V-ZoomIn/lib/python3.6/site-packages/rest_framework/views.py", line 443, in handle_exception
    self.raise_uncaught_exception(exc)
  File "/home/V-ZoomIn/lib/python3.6/site-packages/rest_framework/views.py", line 480, in dispatch
    response = handler(request, *args, **kwargs)
  File "/home/V-ZoomIn/lib/python3.6/site-packages/rest_framework/decorators.py", line 53, in handler
    return func(*args, **kwargs)
  File "/home/ZoomInDev/apps/tasks/views.py", line 421, in sum_analysis
    chart_type=request.data['chart_type'], x_axis=request.data['x_axis'], y_axis=request.data['y_axis'])
  File "/home/ZoomInDev/db_tools/dataAnalyze.py", line 26, in chart_sum
    df = df.groupby(x_axis)[y_axis].sum()
  File "/home/V-ZoomIn/lib/python3.6/site-packages/pandas/core/generic.py", line 6659, in groupby
    observed=observed, **kwargs)
  File "/home/V-ZoomIn/lib/python3.6/site-packages/pandas/core/groupby/groupby.py", line 2152, in groupby
    return klass(obj, by, **kwds)
  File "/home/V-ZoomIn/lib/python3.6/site-packages/pandas/core/groupby/groupby.py", line 599, in __init__
    mutated=self.mutated)
  File "/home/V-ZoomIn/lib/python3.6/site-packages/pandas/core/groupby/groupby.py", line 3291, in _get_grouper
    raise KeyError(gpr)
KeyError: '性别_x，考生号'
"POST /task/chart/sum HTTP/1.1" 500 17537
"POST /chart/ HTTP/1.1" 400 49
"GET /chart/ HTTP/1.1" 200 1108
"POST /task/dataProcessing/showDataSet1 HTTP/1.1" 200 470109
"POST /chart/ HTTP/1.1" 400 49
Internal Server Error: /task/chart/sum
Traceback (most recent call last):
  File "/home/V-ZoomIn/lib/python3.6/site-packages/django/core/handlers/exception.py", line 35, in inner
    response = get_response(request)
  File "/home/V-ZoomIn/lib/python3.6/site-packages/django/core/handlers/base.py", line 128, in _get_response
    response = self.process_exception_by_middleware(e, request)
  File "/home/V-ZoomIn/lib/python3.6/site-packages/django/core/handlers/base.py", line 126, in _get_response
    response = wrapped_callback(request, *callback_args, **callback_kwargs)
  File "/home/V-ZoomIn/lib/python3.6/site-packages/django/views/decorators/csrf.py", line 54, in wrapped_view
    return view_func(*args, **kwargs)
  File "/home/V-ZoomIn/lib/python3.6/site-packages/django/views/generic/base.py", line 69, in view
    return self.dispatch(request, *args, **kwargs)
  File "/home/V-ZoomIn/lib/python3.6/site-packages/rest_framework/views.py", line 483, in dispatch
    response = self.handle_exception(exc)
  File "/home/V-ZoomIn/lib/python3.6/site-packages/rest_framework/views.py", line 443, in handle_exception
    self.raise_uncaught_exception(exc)
  File "/home/V-ZoomIn/lib/python3.6/site-packages/rest_framework/views.py", line 480, in dispatch
    response = handler(request, *args, **kwargs)
  File "/home/V-ZoomIn/lib/python3.6/site-packages/rest_framework/decorators.py", line 53, in handler
    return func(*args, **kwargs)
  File "/home/ZoomInDev/apps/tasks/views.py", line 418, in sum_analysis
    data_set = DataSet.objects.get(id=request.data['data_set'])
  File "/home/V-ZoomIn/lib/python3.6/site-packages/django/db/models/manager.py", line 82, in manager_method
    return getattr(self.get_queryset(), name)(*args, **kwargs)
  File "/home/V-ZoomIn/lib/python3.6/site-packages/django/db/models/query.py", line 403, in get
    self.model._meta.object_name
tasks.models.DoesNotExist: DataSet matching query does not exist.
"POST /task/chart/sum HTTP/1.1" 500 17134
"GET /chart/ HTTP/1.1" 200 1108
"POST /task/dataProcessing/showDataSet1 HTTP/1.1" 200 470109
Internal Server Error: /task/chart/sum
Traceback (most recent call last):
  File "/home/V-ZoomIn/lib/python3.6/site-packages/django/core/handlers/exception.py", line 35, in inner
    response = get_response(request)
  File "/home/V-ZoomIn/lib/python3.6/site-packages/django/core/handlers/base.py", line 128, in _get_response
    response = self.process_exception_by_middleware(e, request)
  File "/home/V-ZoomIn/lib/python3.6/site-packages/django/core/handlers/base.py", line 126, in _get_response
    response = wrapped_callback(request, *callback_args, **callback_kwargs)
  File "/home/V-ZoomIn/lib/python3.6/site-packages/django/views/decorators/csrf.py", line 54, in wrapped_view
    return view_func(*args, **kwargs)
  File "/home/V-ZoomIn/lib/python3.6/site-packages/django/views/generic/base.py", line 69, in view
    return self.dispatch(request, *args, **kwargs)
  File "/home/V-ZoomIn/lib/python3.6/site-packages/rest_framework/views.py", line 483, in dispatch
    response = self.handle_exception(exc)
  File "/home/V-ZoomIn/lib/python3.6/site-packages/rest_framework/views.py", line 443, in handle_exception
    self.raise_uncaught_exception(exc)
  File "/home/V-ZoomIn/lib/python3.6/site-packages/rest_framework/views.py", line 480, in dispatch
    response = handler(request, *args, **kwargs)
  File "/home/V-ZoomIn/lib/python3.6/site-packages/rest_framework/decorators.py", line 53, in handler
    return func(*args, **kwargs)
  File "/home/ZoomInDev/apps/tasks/views.py", line 421, in sum_analysis
    chart_type=request.data['chart_type'], x_axis=request.data['x_axis'], y_axis=request.data['y_axis'])
  File "/home/ZoomInDev/db_tools/dataAnalyze.py", line 26, in chart_sum
    df = df.groupby(x_axis)[y_axis].sum()
  File "/home/V-ZoomIn/lib/python3.6/site-packages/pandas/core/generic.py", line 6659, in groupby
    observed=observed, **kwargs)
  File "/home/V-ZoomIn/lib/python3.6/site-packages/pandas/core/groupby/groupby.py", line 2152, in groupby
    return klass(obj, by, **kwds)
  File "/home/V-ZoomIn/lib/python3.6/site-packages/pandas/core/groupby/groupby.py", line 599, in __init__
    mutated=self.mutated)
  File "/home/V-ZoomIn/lib/python3.6/site-packages/pandas/core/groupby/groupby.py", line 3291, in _get_grouper
    raise KeyError(gpr)
KeyError: '性别_x，考生号'
"POST /task/chart/sum HTTP/1.1" 500 17537
"POST /chart/ HTTP/1.1" 400 49
"GET /chart/ HTTP/1.1" 200 1108
"POST /task/dataProcessing/showDataSet1 HTTP/1.1" 200 470109
Internal Server Error: /task/chart/sum
Traceback (most recent call last):
  File "/home/V-ZoomIn/lib/python3.6/site-packages/django/core/handlers/exception.py", line 35, in inner
    response = get_response(request)
  File "/home/V-ZoomIn/lib/python3.6/site-packages/django/core/handlers/base.py", line 128, in _get_response
    response = self.process_exception_by_middleware(e, request)
  File "/home/V-ZoomIn/lib/python3.6/site-packages/django/core/handlers/base.py", line 126, in _get_response
    response = wrapped_callback(request, *callback_args, **callback_kwargs)
  File "/home/V-ZoomIn/lib/python3.6/site-packages/django/views/decorators/csrf.py", line 54, in wrapped_view
    return view_func(*args, **kwargs)
  File "/home/V-ZoomIn/lib/python3.6/site-packages/django/views/generic/base.py", line 69, in view
    return self.dispatch(request, *args, **kwargs)
  File "/home/V-ZoomIn/lib/python3.6/site-packages/rest_framework/views.py", line 483, in dispatch
    response = self.handle_exception(exc)
  File "/home/V-ZoomIn/lib/python3.6/site-packages/rest_framework/views.py", line 443, in handle_exception
    self.raise_uncaught_exception(exc)
  File "/home/V-ZoomIn/lib/python3.6/site-packages/rest_framework/views.py", line 480, in dispatch
    response = handler(request, *args, **kwargs)
  File "/home/V-ZoomIn/lib/python3.6/site-packages/rest_framework/decorators.py", line 53, in handler
    return func(*args, **kwargs)
  File "/home/ZoomInDev/apps/tasks/views.py", line 421, in sum_analysis
    chart_type=request.data['chart_type'], x_axis=request.data['x_axis'], y_axis=request.data['y_axis'])
  File "/home/ZoomInDev/db_tools/dataAnalyze.py", line 26, in chart_sum
    df = df.groupby(x_axis)[y_axis].sum()
  File "/home/V-ZoomIn/lib/python3.6/site-packages/pandas/core/generic.py", line 6659, in groupby
    observed=observed, **kwargs)
  File "/home/V-ZoomIn/lib/python3.6/site-packages/pandas/core/groupby/groupby.py", line 2152, in groupby
    return klass(obj, by, **kwds)
  File "/home/V-ZoomIn/lib/python3.6/site-packages/pandas/core/groupby/groupby.py", line 599, in __init__
    mutated=self.mutated)
  File "/home/V-ZoomIn/lib/python3.6/site-packages/pandas/core/groupby/groupby.py", line 3291, in _get_grouper
    raise KeyError(gpr)
KeyError: '性别_x'
"POST /task/chart/sum HTTP/1.1" 500 17513
"POST /chart/ HTTP/1.1" 400 49
"GET /chart/ HTTP/1.1" 200 1108
"POST /task/dataProcessing/showDataSet1 HTTP/1.1" 200 470109
"OPTIONS /taskinfo/ HTTP/1.1" 200 0
"OPTIONS /taskinfo/ HTTP/1.1" 200 0
"GET /taskinfo/ HTTP/1.1" 200 1447
"GET /taskinfo/ HTTP/1.1" 200 1447
"POST /taskinfo/ HTTP/1.1" 201 101
"OPTIONS /dataSet/ HTTP/1.1" 200 0
Internal Server Error: /dataSet/
Traceback (most recent call last):
  File "/home/V-ZoomIn/lib/python3.6/site-packages/django/core/handlers/exception.py", line 35, in inner
    response = get_response(request)
  File "/home/V-ZoomIn/lib/python3.6/site-packages/django/core/handlers/base.py", line 128, in _get_response
    response = self.process_exception_by_middleware(e, request)
  File "/home/V-ZoomIn/lib/python3.6/site-packages/django/core/handlers/base.py", line 126, in _get_response
    response = wrapped_callback(request, *callback_args, **callback_kwargs)
  File "/home/V-ZoomIn/lib/python3.6/site-packages/django/views/decorators/csrf.py", line 54, in wrapped_view
    return view_func(*args, **kwargs)
  File "/home/V-ZoomIn/lib/python3.6/site-packages/rest_framework/viewsets.py", line 103, in view
    return self.dispatch(request, *args, **kwargs)
  File "/home/V-ZoomIn/lib/python3.6/site-packages/rest_framework/views.py", line 483, in dispatch
    response = self.handle_exception(exc)
  File "/home/V-ZoomIn/lib/python3.6/site-packages/rest_framework/views.py", line 443, in handle_exception
    self.raise_uncaught_exception(exc)
  File "/home/V-ZoomIn/lib/python3.6/site-packages/rest_framework/views.py", line 480, in dispatch
    response = handler(request, *args, **kwargs)
  File "/home/ZoomInDev/apps/tasks/views.py", line 174, in create
    req_data.__setitem__('task', request.data['task'])
KeyError: 'task'
"POST /dataSet/ HTTP/1.1" 500 16566
"POST /login/ HTTP/1.1" 200 173
"OPTIONS /taskinfo/ HTTP/1.1" 200 0
"OPTIONS /taskinfo/ HTTP/1.1" 200 0
"GET /taskinfo/ HTTP/1.1" 200 1575
"GET /taskinfo/ HTTP/1.1" 200 1575
"POST /taskinfo/ HTTP/1.1" 201 102
"OPTIONS /dataSet/ HTTP/1.1" 200 0
Internal Server Error: /dataSet/
Traceback (most recent call last):
  File "/home/V-ZoomIn/lib/python3.6/site-packages/django/core/handlers/exception.py", line 35, in inner
    response = get_response(request)
  File "/home/V-ZoomIn/lib/python3.6/site-packages/django/core/handlers/base.py", line 128, in _get_response
    response = self.process_exception_by_middleware(e, request)
  File "/home/V-ZoomIn/lib/python3.6/site-packages/django/core/handlers/base.py", line 126, in _get_response
    response = wrapped_callback(request, *callback_args, **callback_kwargs)
  File "/home/V-ZoomIn/lib/python3.6/site-packages/django/views/decorators/csrf.py", line 54, in wrapped_view
    return view_func(*args, **kwargs)
  File "/home/V-ZoomIn/lib/python3.6/site-packages/rest_framework/viewsets.py", line 103, in view
    return self.dispatch(request, *args, **kwargs)
  File "/home/V-ZoomIn/lib/python3.6/site-packages/rest_framework/views.py", line 483, in dispatch
    response = self.handle_exception(exc)
  File "/home/V-ZoomIn/lib/python3.6/site-packages/rest_framework/views.py", line 443, in handle_exception
    self.raise_uncaught_exception(exc)
  File "/home/V-ZoomIn/lib/python3.6/site-packages/rest_framework/views.py", line 480, in dispatch
    response = handler(request, *args, **kwargs)
  File "/home/ZoomInDev/apps/tasks/views.py", line 174, in create
    req_data.__setitem__('task', request.data['task'])
KeyError: 'task'
"POST /dataSet/ HTTP/1.1" 500 16563
"POST /login/ HTTP/1.1" 200 175
"OPTIONS /taskinfo/ HTTP/1.1" 200 0
"OPTIONS /taskinfo/ HTTP/1.1" 200 0
"GET /taskinfo/ HTTP/1.1" 200 1355
"GET /taskinfo/ HTTP/1.1" 200 1355
"POST /taskinfo/ HTTP/1.1" 201 116
"OPTIONS /dataSet/ HTTP/1.1" 200 0
"POST /dataSet/ HTTP/1.1" 400 99
"GET /taskinfo/ HTTP/1.1" 200 1498
"GET /taskinfo/ HTTP/1.1" 200 1498
"POST /taskinfo/ HTTP/1.1" 201 101
Internal Server Error: /dataSet/
Traceback (most recent call last):
  File "/home/V-ZoomIn/lib/python3.6/site-packages/django/core/handlers/exception.py", line 35, in inner
    response = get_response(request)
  File "/home/V-ZoomIn/lib/python3.6/site-packages/django/core/handlers/base.py", line 128, in _get_response
    response = self.process_exception_by_middleware(e, request)
  File "/home/V-ZoomIn/lib/python3.6/site-packages/django/core/handlers/base.py", line 126, in _get_response
    response = wrapped_callback(request, *callback_args, **callback_kwargs)
  File "/home/V-ZoomIn/lib/python3.6/site-packages/django/views/decorators/csrf.py", line 54, in wrapped_view
    return view_func(*args, **kwargs)
  File "/home/V-ZoomIn/lib/python3.6/site-packages/rest_framework/viewsets.py", line 103, in view
    return self.dispatch(request, *args, **kwargs)
  File "/home/V-ZoomIn/lib/python3.6/site-packages/rest_framework/views.py", line 483, in dispatch
    response = self.handle_exception(exc)
  File "/home/V-ZoomIn/lib/python3.6/site-packages/rest_framework/views.py", line 443, in handle_exception
    self.raise_uncaught_exception(exc)
  File "/home/V-ZoomIn/lib/python3.6/site-packages/rest_framework/views.py", line 480, in dispatch
    response = handler(request, *args, **kwargs)
  File "/home/ZoomInDev/apps/tasks/views.py", line 174, in create
    req_data.__setitem__('task', request.data['task'])
KeyError: 'task'
"POST /dataSet/ HTTP/1.1" 500 16306
"POST /login/ HTTP/1.1" 200 176
"POST /taskinfo/ HTTP/1.1" 201 123
"POST /dataSet/ HTTP/1.1" 201 300
"POST /taskinfo/ HTTP/1.1" 201 105
Internal Server Error: /dataSet/
Traceback (most recent call last):
  File "/home/V-ZoomIn/lib/python3.6/site-packages/django/core/handlers/exception.py", line 35, in inner
    response = get_response(request)
  File "/home/V-ZoomIn/lib/python3.6/site-packages/django/core/handlers/base.py", line 128, in _get_response
    response = self.process_exception_by_middleware(e, request)
  File "/home/V-ZoomIn/lib/python3.6/site-packages/django/core/handlers/base.py", line 126, in _get_response
    response = wrapped_callback(request, *callback_args, **callback_kwargs)
  File "/home/V-ZoomIn/lib/python3.6/site-packages/django/views/decorators/csrf.py", line 54, in wrapped_view
    return view_func(*args, **kwargs)
  File "/home/V-ZoomIn/lib/python3.6/site-packages/rest_framework/viewsets.py", line 103, in view
    return self.dispatch(request, *args, **kwargs)
  File "/home/V-ZoomIn/lib/python3.6/site-packages/rest_framework/views.py", line 483, in dispatch
    response = self.handle_exception(exc)
  File "/home/V-ZoomIn/lib/python3.6/site-packages/rest_framework/views.py", line 443, in handle_exception
    self.raise_uncaught_exception(exc)
  File "/home/V-ZoomIn/lib/python3.6/site-packages/rest_framework/views.py", line 480, in dispatch
    response = handler(request, *args, **kwargs)
  File "/home/ZoomInDev/apps/tasks/views.py", line 174, in create
    req_data.__setitem__('task', request.data['task'])
KeyError: 'task'
"POST /dataSet/ HTTP/1.1" 500 16306
"OPTIONS /taskinfo/ HTTP/1.1" 200 0
"OPTIONS /taskinfo/ HTTP/1.1" 200 0
"GET /taskinfo/ HTTP/1.1" 200 1704
"GET /taskinfo/ HTTP/1.1" 200 1704
"POST /chart/ HTTP/1.1" 415 77
"POST /taskinfo/ HTTP/1.1" 201 102
"OPTIONS /dataSet/ HTTP/1.1" 200 0
Internal Server Error: /dataSet/
Traceback (most recent call last):
  File "/home/V-ZoomIn/lib/python3.6/site-packages/django/core/handlers/exception.py", line 35, in inner
    response = get_response(request)
  File "/home/V-ZoomIn/lib/python3.6/site-packages/django/core/handlers/base.py", line 128, in _get_response
    response = self.process_exception_by_middleware(e, request)
  File "/home/V-ZoomIn/lib/python3.6/site-packages/django/core/handlers/base.py", line 126, in _get_response
    response = wrapped_callback(request, *callback_args, **callback_kwargs)
  File "/home/V-ZoomIn/lib/python3.6/site-packages/django/views/decorators/csrf.py", line 54, in wrapped_view
    return view_func(*args, **kwargs)
  File "/home/V-ZoomIn/lib/python3.6/site-packages/rest_framework/viewsets.py", line 103, in view
    return self.dispatch(request, *args, **kwargs)
  File "/home/V-ZoomIn/lib/python3.6/site-packages/rest_framework/views.py", line 483, in dispatch
    response = self.handle_exception(exc)
  File "/home/V-ZoomIn/lib/python3.6/site-packages/rest_framework/views.py", line 443, in handle_exception
    self.raise_uncaught_exception(exc)
  File "/home/V-ZoomIn/lib/python3.6/site-packages/rest_framework/views.py", line 480, in dispatch
    response = handler(request, *args, **kwargs)
  File "/home/ZoomInDev/apps/tasks/views.py", line 174, in create
    req_data.__setitem__('task', request.data['task'])
KeyError: 'task'
"POST /dataSet/ HTTP/1.1" 500 16563
"GET /dataSet/ HTTP/1.1" 200 391
"OPTIONS /task/dataProcessing/showDataSet1 HTTP/1.1" 200 0
"POST /task/dataProcessing/showDataSet1 HTTP/1.1" 200 22989
"POST /task/dataProcessing/showDataSet1 HTTP/1.1" 200 22989
"GET /dataSet/ HTTP/1.1" 200 391
"OPTIONS /task/dataProcessing/showDtypes HTTP/1.1" 200 0
"POST /task/dataProcessing/showDtypes HTTP/1.1" 200 238
"POST /chart/ HTTP/1.1" 415 77
"POST /chart/ HTTP/1.1" 415 77
"POST /login/ HTTP/1.1" 200 173
"OPTIONS /taskinfo/ HTTP/1.1" 200 0
"OPTIONS /taskinfo/ HTTP/1.1" 200 0
"GET /taskinfo/ HTTP/1.1" 200 1833
"GET /taskinfo/ HTTP/1.1" 200 1833
"POST /chart/ HTTP/1.1" 400 42
"POST /taskinfo/ HTTP/1.1" 201 98
"OPTIONS /dataSet/ HTTP/1.1" 200 0
Internal Server Error: /dataSet/
Traceback (most recent call last):
  File "/home/V-ZoomIn/lib/python3.6/site-packages/django/core/handlers/exception.py", line 35, in inner
    response = get_response(request)
  File "/home/V-ZoomIn/lib/python3.6/site-packages/django/core/handlers/base.py", line 128, in _get_response
    response = self.process_exception_by_middleware(e, request)
  File "/home/V-ZoomIn/lib/python3.6/site-packages/django/core/handlers/base.py", line 126, in _get_response
    response = wrapped_callback(request, *callback_args, **callback_kwargs)
  File "/home/V-ZoomIn/lib/python3.6/site-packages/django/views/decorators/csrf.py", line 54, in wrapped_view
    return view_func(*args, **kwargs)
  File "/home/V-ZoomIn/lib/python3.6/site-packages/rest_framework/viewsets.py", line 103, in view
    return self.dispatch(request, *args, **kwargs)
  File "/home/V-ZoomIn/lib/python3.6/site-packages/rest_framework/views.py", line 483, in dispatch
    response = self.handle_exception(exc)
  File "/home/V-ZoomIn/lib/python3.6/site-packages/rest_framework/views.py", line 443, in handle_exception
    self.raise_uncaught_exception(exc)
  File "/home/V-ZoomIn/lib/python3.6/site-packages/rest_framework/views.py", line 480, in dispatch
    response = handler(request, *args, **kwargs)
  File "/home/ZoomInDev/apps/tasks/views.py", line 174, in create
    req_data.__setitem__('task', request.data['task'])
KeyError: 'task'
"POST /dataSet/ HTTP/1.1" 500 16298
"POST /chart/ HTTP/1.1" 415 77
"POST /chart/ HTTP/1.1" 400 42
"POST /chart/ HTTP/1.1" 400 49
"POST /chart/ HTTP/1.1" 201 224
"POST /taskinfo/ HTTP/1.1" 400 46
"POST /taskinfo/ HTTP/1.1" 201 99
Internal Server Error: /dataSet/
Traceback (most recent call last):
  File "/home/V-ZoomIn/lib/python3.6/site-packages/django/core/handlers/exception.py", line 35, in inner
    response = get_response(request)
  File "/home/V-ZoomIn/lib/python3.6/site-packages/django/core/handlers/base.py", line 128, in _get_response
    response = self.process_exception_by_middleware(e, request)
  File "/home/V-ZoomIn/lib/python3.6/site-packages/django/core/handlers/base.py", line 126, in _get_response
    response = wrapped_callback(request, *callback_args, **callback_kwargs)
  File "/home/V-ZoomIn/lib/python3.6/site-packages/django/views/decorators/csrf.py", line 54, in wrapped_view
    return view_func(*args, **kwargs)
  File "/home/V-ZoomIn/lib/python3.6/site-packages/rest_framework/viewsets.py", line 103, in view
    return self.dispatch(request, *args, **kwargs)
  File "/home/V-ZoomIn/lib/python3.6/site-packages/rest_framework/views.py", line 483, in dispatch
    response = self.handle_exception(exc)
  File "/home/V-ZoomIn/lib/python3.6/site-packages/rest_framework/views.py", line 443, in handle_exception
    self.raise_uncaught_exception(exc)
  File "/home/V-ZoomIn/lib/python3.6/site-packages/rest_framework/views.py", line 480, in dispatch
    response = handler(request, *args, **kwargs)
  File "/home/ZoomInDev/apps/tasks/views.py", line 174, in create
    req_data.__setitem__('task', request.data['task'])
KeyError: 'task'
"POST /dataSet/ HTTP/1.1" 500 16298
"OPTIONS /task/dataProcessing/showDataSet1 HTTP/1.1" 200 0
"OPTIONS /chart/ HTTP/1.1" 200 0
"OPTIONS /task/chart/sum HTTP/1.1" 200 0
"OPTIONS /chart/ HTTP/1.1" 200 0
"POST /chart/ HTTP/1.1" 400 49
Internal Server Error: /task/chart/sum
Traceback (most recent call last):
  File "/home/V-ZoomIn/lib/python3.6/site-packages/django/core/handlers/exception.py", line 35, in inner
    response = get_response(request)
  File "/home/V-ZoomIn/lib/python3.6/site-packages/django/core/handlers/base.py", line 128, in _get_response
    response = self.process_exception_by_middleware(e, request)
  File "/home/V-ZoomIn/lib/python3.6/site-packages/django/core/handlers/base.py", line 126, in _get_response
    response = wrapped_callback(request, *callback_args, **callback_kwargs)
  File "/home/V-ZoomIn/lib/python3.6/site-packages/django/views/decorators/csrf.py", line 54, in wrapped_view
    return view_func(*args, **kwargs)
  File "/home/V-ZoomIn/lib/python3.6/site-packages/django/views/generic/base.py", line 69, in view
    return self.dispatch(request, *args, **kwargs)
  File "/home/V-ZoomIn/lib/python3.6/site-packages/rest_framework/views.py", line 483, in dispatch
    response = self.handle_exception(exc)
  File "/home/V-ZoomIn/lib/python3.6/site-packages/rest_framework/views.py", line 443, in handle_exception
    self.raise_uncaught_exception(exc)
  File "/home/V-ZoomIn/lib/python3.6/site-packages/rest_framework/views.py", line 480, in dispatch
    response = handler(request, *args, **kwargs)
  File "/home/V-ZoomIn/lib/python3.6/site-packages/rest_framework/decorators.py", line 53, in handler
    return func(*args, **kwargs)
  File "/home/ZoomInDev/apps/tasks/views.py", line 421, in sum_analysis
    chart_type=request.data['chart_type'], x_axis=request.data['x_axis'], y_axis=request.data['y_axis'])
  File "/home/ZoomInDev/db_tools/dataAnalyze.py", line 26, in chart_sum
    df = df.groupby(x_axis)[y_axis].sum()
  File "/home/V-ZoomIn/lib/python3.6/site-packages/pandas/core/generic.py", line 6659, in groupby
    observed=observed, **kwargs)
  File "/home/V-ZoomIn/lib/python3.6/site-packages/pandas/core/groupby/groupby.py", line 2152, in groupby
    return klass(obj, by, **kwds)
  File "/home/V-ZoomIn/lib/python3.6/site-packages/pandas/core/groupby/groupby.py", line 599, in __init__
    mutated=self.mutated)
  File "/home/V-ZoomIn/lib/python3.6/site-packages/pandas/core/groupby/groupby.py", line 3291, in _get_grouper
    raise KeyError(gpr)
KeyError: '性别_x'
"POST /task/chart/sum HTTP/1.1" 500 17514
"GET /chart/ HTTP/1.1" 200 1108
"POST /task/dataProcessing/showDataSet1 HTTP/1.1" 200 470109
Internal Server Error: /task/chart/sum
Traceback (most recent call last):
  File "/home/V-ZoomIn/lib/python3.6/site-packages/django/core/handlers/exception.py", line 35, in inner
    response = get_response(request)
  File "/home/V-ZoomIn/lib/python3.6/site-packages/django/core/handlers/base.py", line 128, in _get_response
    response = self.process_exception_by_middleware(e, request)
  File "/home/V-ZoomIn/lib/python3.6/site-packages/django/core/handlers/base.py", line 126, in _get_response
    response = wrapped_callback(request, *callback_args, **callback_kwargs)
  File "/home/V-ZoomIn/lib/python3.6/site-packages/django/views/decorators/csrf.py", line 54, in wrapped_view
    return view_func(*args, **kwargs)
  File "/home/V-ZoomIn/lib/python3.6/site-packages/django/views/generic/base.py", line 69, in view
    return self.dispatch(request, *args, **kwargs)
  File "/home/V-ZoomIn/lib/python3.6/site-packages/rest_framework/views.py", line 483, in dispatch
    response = self.handle_exception(exc)
  File "/home/V-ZoomIn/lib/python3.6/site-packages/rest_framework/views.py", line 443, in handle_exception
    self.raise_uncaught_exception(exc)
  File "/home/V-ZoomIn/lib/python3.6/site-packages/rest_framework/views.py", line 480, in dispatch
    response = handler(request, *args, **kwargs)
  File "/home/V-ZoomIn/lib/python3.6/site-packages/rest_framework/decorators.py", line 53, in handler
    return func(*args, **kwargs)
  File "/home/ZoomInDev/apps/tasks/views.py", line 421, in sum_analysis
    chart_type=request.data['chart_type'], x_axis=request.data['x_axis'], y_axis=request.data['y_axis'])
  File "/home/ZoomInDev/db_tools/dataAnalyze.py", line 26, in chart_sum
    df = df.groupby(x_axis)[y_axis].sum()
  File "/home/V-ZoomIn/lib/python3.6/site-packages/pandas/core/generic.py", line 6659, in groupby
    observed=observed, **kwargs)
  File "/home/V-ZoomIn/lib/python3.6/site-packages/pandas/core/groupby/groupby.py", line 2152, in groupby
    return klass(obj, by, **kwds)
  File "/home/V-ZoomIn/lib/python3.6/site-packages/pandas/core/groupby/groupby.py", line 599, in __init__
    mutated=self.mutated)
  File "/home/V-ZoomIn/lib/python3.6/site-packages/pandas/core/groupby/groupby.py", line 3291, in _get_grouper
    raise KeyError(gpr)
KeyError: '性别_x'
"POST /task/chart/sum HTTP/1.1" 500 17546
"GET /chart/ HTTP/1.1" 200 1108
"POST /chart/ HTTP/1.1" 400 49
"POST /task/dataProcessing/showDataSet1 HTTP/1.1" 200 470109
"POST /task/chart/sum HTTP/1.1" 200 315
"OPTIONS /taskinfo/ HTTP/1.1" 200 0
"POST /taskinfo/ HTTP/1.1" 201 108
"OPTIONS /dataSet/ HTTP/1.1" 200 0
Internal Server Error: /dataSet/
Traceback (most recent call last):
  File "/home/V-ZoomIn/lib/python3.6/site-packages/django/core/handlers/exception.py", line 35, in inner
    response = get_response(request)
  File "/home/V-ZoomIn/lib/python3.6/site-packages/django/core/handlers/base.py", line 128, in _get_response
    response = self.process_exception_by_middleware(e, request)
  File "/home/V-ZoomIn/lib/python3.6/site-packages/django/core/handlers/base.py", line 126, in _get_response
    response = wrapped_callback(request, *callback_args, **callback_kwargs)
  File "/home/V-ZoomIn/lib/python3.6/site-packages/django/views/decorators/csrf.py", line 54, in wrapped_view
    return view_func(*args, **kwargs)
  File "/home/V-ZoomIn/lib/python3.6/site-packages/rest_framework/viewsets.py", line 103, in view
    return self.dispatch(request, *args, **kwargs)
  File "/home/V-ZoomIn/lib/python3.6/site-packages/rest_framework/views.py", line 483, in dispatch
    response = self.handle_exception(exc)
  File "/home/V-ZoomIn/lib/python3.6/site-packages/rest_framework/views.py", line 443, in handle_exception
    self.raise_uncaught_exception(exc)
  File "/home/V-ZoomIn/lib/python3.6/site-packages/rest_framework/views.py", line 480, in dispatch
    response = handler(request, *args, **kwargs)
  File "/home/ZoomInDev/apps/tasks/views.py", line 174, in create
    req_data.__setitem__('task', request.data['task'])
KeyError: 'task'
"POST /dataSet/ HTTP/1.1" 500 16563
"OPTIONS /taskinfo/ HTTP/1.1" 200 0
"OPTIONS /taskinfo/ HTTP/1.1" 200 0
"GET /taskinfo/ HTTP/1.1" 200 1758
"GET /taskinfo/ HTTP/1.1" 200 1758
"POST /taskinfo/ HTTP/1.1" 201 98
"OPTIONS /dataSet/ HTTP/1.1" 200 0
Internal Server Error: /dataSet/
Traceback (most recent call last):
  File "/home/V-ZoomIn/lib/python3.6/site-packages/django/core/handlers/exception.py", line 35, in inner
    response = get_response(request)
  File "/home/V-ZoomIn/lib/python3.6/site-packages/django/core/handlers/base.py", line 128, in _get_response
    response = self.process_exception_by_middleware(e, request)
  File "/home/V-ZoomIn/lib/python3.6/site-packages/django/core/handlers/base.py", line 126, in _get_response
    response = wrapped_callback(request, *callback_args, **callback_kwargs)
  File "/home/V-ZoomIn/lib/python3.6/site-packages/django/views/decorators/csrf.py", line 54, in wrapped_view
    return view_func(*args, **kwargs)
  File "/home/V-ZoomIn/lib/python3.6/site-packages/rest_framework/viewsets.py", line 103, in view
    return self.dispatch(request, *args, **kwargs)
  File "/home/V-ZoomIn/lib/python3.6/site-packages/rest_framework/views.py", line 483, in dispatch
    response = self.handle_exception(exc)
  File "/home/V-ZoomIn/lib/python3.6/site-packages/rest_framework/views.py", line 443, in handle_exception
    self.raise_uncaught_exception(exc)
  File "/home/V-ZoomIn/lib/python3.6/site-packages/rest_framework/views.py", line 480, in dispatch
    response = handler(request, *args, **kwargs)
  File "/home/ZoomInDev/apps/tasks/views.py", line 174, in create
    req_data.__setitem__('task', request.data['task'])
KeyError: 'task'
"POST /dataSet/ HTTP/1.1" 500 16306
"POST /taskinfo/ HTTP/1.1" 201 124
Internal Server Error: /dataSet/
Traceback (most recent call last):
  File "/home/V-ZoomIn/lib/python3.6/site-packages/django/core/handlers/exception.py", line 35, in inner
    response = get_response(request)
  File "/home/V-ZoomIn/lib/python3.6/site-packages/django/core/handlers/base.py", line 128, in _get_response
    response = self.process_exception_by_middleware(e, request)
  File "/home/V-ZoomIn/lib/python3.6/site-packages/django/core/handlers/base.py", line 126, in _get_response
    response = wrapped_callback(request, *callback_args, **callback_kwargs)
  File "/home/V-ZoomIn/lib/python3.6/site-packages/django/views/decorators/csrf.py", line 54, in wrapped_view
    return view_func(*args, **kwargs)
  File "/home/V-ZoomIn/lib/python3.6/site-packages/rest_framework/viewsets.py", line 103, in view
    return self.dispatch(request, *args, **kwargs)
  File "/home/V-ZoomIn/lib/python3.6/site-packages/rest_framework/views.py", line 483, in dispatch
    response = self.handle_exception(exc)
  File "/home/V-ZoomIn/lib/python3.6/site-packages/rest_framework/views.py", line 443, in handle_exception
    self.raise_uncaught_exception(exc)
  File "/home/V-ZoomIn/lib/python3.6/site-packages/rest_framework/views.py", line 480, in dispatch
    response = handler(request, *args, **kwargs)
  File "/home/ZoomInDev/apps/tasks/views.py", line 174, in create
    req_data.__setitem__('task', request.data['task'])
KeyError: 'task'
"POST /dataSet/ HTTP/1.1" 500 16306
"OPTIONS /taskinfo/ HTTP/1.1" 200 0
"OPTIONS /taskinfo/ HTTP/1.1" 200 0
"GET /taskinfo/ HTTP/1.1" 200 2219
"GET /taskinfo/ HTTP/1.1" 200 2219
"GET /taskinfo/ HTTP/1.1" 200 2219
"GET /taskinfo/ HTTP/1.1" 200 2219
"POST /taskinfo/ HTTP/1.1" 201 109
"OPTIONS /dataSet/ HTTP/1.1" 200 0
Internal Server Error: /dataSet/
Traceback (most recent call last):
  File "/home/V-ZoomIn/lib/python3.6/site-packages/django/core/handlers/exception.py", line 35, in inner
    response = get_response(request)
  File "/home/V-ZoomIn/lib/python3.6/site-packages/django/core/handlers/base.py", line 128, in _get_response
    response = self.process_exception_by_middleware(e, request)
  File "/home/V-ZoomIn/lib/python3.6/site-packages/django/core/handlers/base.py", line 126, in _get_response
    response = wrapped_callback(request, *callback_args, **callback_kwargs)
  File "/home/V-ZoomIn/lib/python3.6/site-packages/django/views/decorators/csrf.py", line 54, in wrapped_view
    return view_func(*args, **kwargs)
  File "/home/V-ZoomIn/lib/python3.6/site-packages/rest_framework/viewsets.py", line 103, in view
    return self.dispatch(request, *args, **kwargs)
  File "/home/V-ZoomIn/lib/python3.6/site-packages/rest_framework/views.py", line 483, in dispatch
    response = self.handle_exception(exc)
  File "/home/V-ZoomIn/lib/python3.6/site-packages/rest_framework/views.py", line 443, in handle_exception
    self.raise_uncaught_exception(exc)
  File "/home/V-ZoomIn/lib/python3.6/site-packages/rest_framework/views.py", line 480, in dispatch
    response = handler(request, *args, **kwargs)
  File "/home/ZoomInDev/apps/tasks/views.py", line 174, in create
    req_data.__setitem__('task', request.data['task'])
KeyError: 'task'
"POST /dataSet/ HTTP/1.1" 500 16563
"GET /taskinfo/ HTTP/1.1" 200 2034
"GET /taskinfo/ HTTP/1.1" 200 2034
"OPTIONS /taskinfo/ HTTP/1.1" 200 0
"POST /taskinfo/ HTTP/1.1" 201 117
"GET /taskinfo/ HTTP/1.1" 200 2355
"GET /taskinfo/ HTTP/1.1" 200 2355
"GET /taskinfo/ HTTP/1.1" 200 2178
"GET /taskinfo/ HTTP/1.1" 200 2178
"POST /taskinfo/ HTTP/1.1" 201 100
"POST /taskinfo/ HTTP/1.1" 201 114
"OPTIONS /dataSet/ HTTP/1.1" 200 0
"POST /dataSet/ HTTP/1.1" 201 294
Internal Server Error: /dataSet/
Traceback (most recent call last):
  File "/home/V-ZoomIn/lib/python3.6/site-packages/django/core/handlers/exception.py", line 35, in inner
    response = get_response(request)
  File "/home/V-ZoomIn/lib/python3.6/site-packages/django/core/handlers/base.py", line 128, in _get_response
    response = self.process_exception_by_middleware(e, request)
  File "/home/V-ZoomIn/lib/python3.6/site-packages/django/core/handlers/base.py", line 126, in _get_response
    response = wrapped_callback(request, *callback_args, **callback_kwargs)
  File "/home/V-ZoomIn/lib/python3.6/site-packages/django/views/decorators/csrf.py", line 54, in wrapped_view
    return view_func(*args, **kwargs)
  File "/home/V-ZoomIn/lib/python3.6/site-packages/rest_framework/viewsets.py", line 103, in view
    return self.dispatch(request, *args, **kwargs)
  File "/home/V-ZoomIn/lib/python3.6/site-packages/rest_framework/views.py", line 483, in dispatch
    response = self.handle_exception(exc)
  File "/home/V-ZoomIn/lib/python3.6/site-packages/rest_framework/views.py", line 443, in handle_exception
    self.raise_uncaught_exception(exc)
  File "/home/V-ZoomIn/lib/python3.6/site-packages/rest_framework/views.py", line 480, in dispatch
    response = handler(request, *args, **kwargs)
  File "/home/ZoomInDev/apps/tasks/views.py", line 174, in create
    req_data.__setitem__('task', request.data['task'])
KeyError: 'task'
"POST /dataSet/ HTTP/1.1" 500 16563
"OPTIONS /task/dataProcessing/showDataSet1 HTTP/1.1" 200 0
"GET /dataSet/ HTTP/1.1" 200 491
"POST /task/dataProcessing/showDataSet1 HTTP/1.1" 200 26174
"OPTIONS /task/dataProcessing/showDtypes HTTP/1.1" 200 0
"POST /task/dataProcessing/showDtypes HTTP/1.1" 200 249
"GET / HTTP/1.1" 200 5740
"GET /docs/ HTTP/1.1" 200 213654
"GET /docs/schema.js HTTP/1.1" 200 17428
"POST /login/ HTTP/1.1" 200 176
Internal Server Error: /taskinfo/
Traceback (most recent call last):
  File "/Users/cribbee/Virtualenv/V-ZoomIn/lib/python3.6/site-packages/django/core/handlers/exception.py", line 35, in inner
    response = get_response(request)
  File "/Users/cribbee/Virtualenv/V-ZoomIn/lib/python3.6/site-packages/django/core/handlers/base.py", line 128, in _get_response
    response = self.process_exception_by_middleware(e, request)
  File "/Users/cribbee/Virtualenv/V-ZoomIn/lib/python3.6/site-packages/django/core/handlers/base.py", line 126, in _get_response
    response = wrapped_callback(request, *callback_args, **callback_kwargs)
  File "/Users/cribbee/Virtualenv/V-ZoomIn/lib/python3.6/site-packages/django/views/decorators/csrf.py", line 54, in wrapped_view
    return view_func(*args, **kwargs)
  File "/Users/cribbee/Virtualenv/V-ZoomIn/lib/python3.6/site-packages/rest_framework/viewsets.py", line 103, in view
    return self.dispatch(request, *args, **kwargs)
  File "/Users/cribbee/Virtualenv/V-ZoomIn/lib/python3.6/site-packages/rest_framework/views.py", line 483, in dispatch
    response = self.handle_exception(exc)
  File "/Users/cribbee/Virtualenv/V-ZoomIn/lib/python3.6/site-packages/rest_framework/views.py", line 443, in handle_exception
    self.raise_uncaught_exception(exc)
  File "/Users/cribbee/Virtualenv/V-ZoomIn/lib/python3.6/site-packages/rest_framework/views.py", line 480, in dispatch
    response = handler(request, *args, **kwargs)
  File "/Users/cribbee/PycharmProjects/ZoomInDev/apps/tasks/views.py", line 124, in create
    dataProcessing.process.mkdir(floder=taskinfo.task_folder)
  File "/Users/cribbee/PycharmProjects/ZoomInDev/db_tools/dataProcessing.py", line 23, in mkdir
    os.mkdir(floder)
FileNotFoundError: [Errno 2] No such file or directory: '/home/ZoomInDataSet/3'
"POST /taskinfo/ HTTP/1.1" 500 16612
Internal Server Error: /taskinfo/
Traceback (most recent call last):
  File "/Users/cribbee/Virtualenv/V-ZoomIn/lib/python3.6/site-packages/django/core/handlers/exception.py", line 35, in inner
    response = get_response(request)
  File "/Users/cribbee/Virtualenv/V-ZoomIn/lib/python3.6/site-packages/django/core/handlers/base.py", line 128, in _get_response
    response = self.process_exception_by_middleware(e, request)
  File "/Users/cribbee/Virtualenv/V-ZoomIn/lib/python3.6/site-packages/django/core/handlers/base.py", line 126, in _get_response
    response = wrapped_callback(request, *callback_args, **callback_kwargs)
  File "/Users/cribbee/Virtualenv/V-ZoomIn/lib/python3.6/site-packages/django/views/decorators/csrf.py", line 54, in wrapped_view
    return view_func(*args, **kwargs)
  File "/Users/cribbee/Virtualenv/V-ZoomIn/lib/python3.6/site-packages/rest_framework/viewsets.py", line 103, in view
    return self.dispatch(request, *args, **kwargs)
  File "/Users/cribbee/Virtualenv/V-ZoomIn/lib/python3.6/site-packages/rest_framework/views.py", line 483, in dispatch
    response = self.handle_exception(exc)
  File "/Users/cribbee/Virtualenv/V-ZoomIn/lib/python3.6/site-packages/rest_framework/views.py", line 443, in handle_exception
    self.raise_uncaught_exception(exc)
  File "/Users/cribbee/Virtualenv/V-ZoomIn/lib/python3.6/site-packages/rest_framework/views.py", line 480, in dispatch
    response = handler(request, *args, **kwargs)
  File "/Users/cribbee/PycharmProjects/ZoomInDev/apps/tasks/views.py", line 124, in create
    dataProcessing.process.mkdir(floder=taskinfo.task_folder)
  File "/Users/cribbee/PycharmProjects/ZoomInDev/db_tools/dataProcessing.py", line 23, in mkdir
    os.mkdir(floder)
FileNotFoundError: [Errno 2] No such file or directory: '/home/ZoomInDataSet/4'
"POST /taskinfo/ HTTP/1.1" 500 16612
"POST /taskinfo/ HTTP/1.1" 400 46
"GET /taskinfo/ HTTP/1.1" 200 567
"GET / HTTP/1.1" 200 5740
"GET /docs/ HTTP/1.1" 200 213654
"GET /docs/schema.js HTTP/1.1" 200 17428
"POST /login/ HTTP/1.1" 200 176
Internal Server Error: /taskinfo/
Traceback (most recent call last):
  File "/Users/cribbee/Virtualenv/V-ZoomIn/lib/python3.6/site-packages/django/core/handlers/exception.py", line 35, in inner
    response = get_response(request)
  File "/Users/cribbee/Virtualenv/V-ZoomIn/lib/python3.6/site-packages/django/core/handlers/base.py", line 128, in _get_response
    response = self.process_exception_by_middleware(e, request)
  File "/Users/cribbee/Virtualenv/V-ZoomIn/lib/python3.6/site-packages/django/core/handlers/base.py", line 126, in _get_response
    response = wrapped_callback(request, *callback_args, **callback_kwargs)
  File "/Users/cribbee/Virtualenv/V-ZoomIn/lib/python3.6/site-packages/django/views/decorators/csrf.py", line 54, in wrapped_view
    return view_func(*args, **kwargs)
  File "/Users/cribbee/Virtualenv/V-ZoomIn/lib/python3.6/site-packages/rest_framework/viewsets.py", line 103, in view
    return self.dispatch(request, *args, **kwargs)
  File "/Users/cribbee/Virtualenv/V-ZoomIn/lib/python3.6/site-packages/rest_framework/views.py", line 483, in dispatch
    response = self.handle_exception(exc)
  File "/Users/cribbee/Virtualenv/V-ZoomIn/lib/python3.6/site-packages/rest_framework/views.py", line 443, in handle_exception
    self.raise_uncaught_exception(exc)
  File "/Users/cribbee/Virtualenv/V-ZoomIn/lib/python3.6/site-packages/rest_framework/views.py", line 480, in dispatch
    response = handler(request, *args, **kwargs)
  File "/Users/cribbee/PycharmProjects/ZoomInDev/apps/tasks/views.py", line 124, in create
    dataProcessing.process.mkdir(floder=taskinfo.task_folder)
  File "/Users/cribbee/PycharmProjects/ZoomInDev/db_tools/dataProcessing.py", line 23, in mkdir
    os.mkdir(floder)
FileNotFoundError: [Errno 2] No such file or directory: '/home/ZoomInDataSet/5'
"POST /taskinfo/ HTTP/1.1" 500 16612
"GET /taskinfo/ HTTP/1.1" 200 707
